Workbook

Sheet Instructions - READ FIRST
A1: HOW THIS SYSTEM WORKS (v8 - same layout as before, one bug fixed)
A3: This is the same Master Leads layout you already have live. Only the F-Code rule changed:
A5: F-CODE IS NOW UNIQUE PER PHONE NUMBER, PERMANENTLY
A6: Before: every new campaign entry generated a brand new F-code, even for a phone number already in the system.
A7: Now: 'Add New Lead' checks column A (Phone Normalized) for this number FIRST. If it's already there under any
A8: earlier row, it REUSES that same F-code. A new F-code is only generated the very first time a number is ever seen.
A10: So the same student messaging in through a different boost later keeps their original F-code, and gets a new
A11: row logging the new campaign/enquiry - not a new identity.
A13: DUPLICATE VS REPEAT (unchanged)
A14: Same phone + same campaign already logged = true duplicate, blocked, no new row.
A15: Same phone + a different/new campaign = new row added, F-code reused, marked 'Repeat Student'.
A17: SETUP STEPS
... A48: 0716030661

Sheet Members
A1: Member Name | B1: Total Leads (auto) | C1: Converted Leads (auto)
A2: maheesha | B2: =COUNTIF('Master Leads'!$D$2:$D$1000,A2) -> 1 | C2: =COUNTIFS('Master Leads'!$D$2:$D$1000,A2,'Master Leads'!$F$2:$F$1000,"Converted") -> 1
A3: menik | B3: =COUNTIF('Master Leads'!$D$2:$D$1000,A3) -> 0 | C3: =COUNTIFS('Master Leads'!$D$2:$D$1000,A3,'Master Leads'!$F$2:$F$1000,"Converted") -> 0
A4: kavinda | B4: =COUNTIF('Master Leads'!$D$2:$D$1000,A4) -> 2 | C4: =COUNTIFS('Master Leads'!$D$2:$D$1000,A4,'Master Leads'!$F$2:$F$1000,"Converted") -> 0
A5: umesh | B5: =COUNTIF('Master Leads'!$D$2:$D$1000,A5) -> 4 | C5: =COUNTIFS('Master Leads'!$D$2:$D$1000,A5,'Master Leads'!$F$2:$F$1000,"Converted") -> 1
A6: Avishka | B6: =COUNTIF('Master Leads'!$D$2:$D$1000,A6) -> 0 | C6: =COUNTIFS('Master Leads'!$D$2:$D$1000,A6,'Master Leads'!$F$2:$F$1000,"Converted") -> 0
A7: Wihanga | B7: =COUNTIF('Master Leads'!$D$2:$D$1000,A7) -> 0 | C7: =COUNTIFS('Master Leads'!$D$2:$D$1000,A7,'Master Leads'!$F$2:$F$1000,"Converted") -> 0
A8: muthumali | B8: =COUNTIF('Master Leads'!$D$2:$D$1000,A8) -> 1 | C8: =COUNTIFS('Master Leads'!$D$2:$D$1000,A8,'Master Leads'!$F$2:$F$1000,"Converted") -> 0
A9: shamali | B9: =COUNTIF('Master Leads'!$D$2:$D$1000,A9) -> 0 | C9: =COUNTIFS('Master Leads'!$D$2:$D$1000,A9,'Master Leads'!$F$2:$F$1000,"Converted") -> 0

Sheet Master Leads
A1: Phone (Normalized) | B1: Raw Phone (as entered) | C1: F-Code | D1: Assigned Member | E1: Date Added | F1: Status | G1: Grade | H1: Comments | I1: Second Call Done | J1: Second Call Notes | K1: Duplicate Check | L1: Campaign / Boost Name | M1: Repeat Student? | N1: Previous F-Code (if repeat) | O1: Paid | P1: Grade
A2: =IFERROR(__xludf.DUMMYFUNCTION("IF(B2="""","""",RIGHT(regexreplace(B2&"""",""[^0-9]"",""""),9))"),"778625101") -> 778625101 | B2: +94 77 862 5101 | C2: F00001 | D2: maheesha | E2: 2026-07-01 | F2: Converted | G2: 6 | I2: No | K2: =IF(COUNTIFS($A$2:A2,A2,$L$2:L2,L2)>1,"DUPLICATE - CHECK","") | L2: B1 | M2: =IF(COUNTIF($A1:A$2,A)>0,"Yes - see Previous F-Code","No") -> No | N2: {=IF(COUNTIF($A1:A$2,A)>0,INDEX($C1:C$2,MATCH(A2,$A1:A$2,0)),"")} | O2: No | P2: 7, 9
A3: =IFERROR(__xludf.DUMMYFUNCTION("IF(B3="""","""",RIGHT(regexreplace(B3&"""",""[^0-9]"",""""),9))"),"766820157") -> 766820157 | B3: 0766820157 | C3: F00002 | D3: umesh | E3: 2026-07-02 | F3: Not Interested | H3: off | I3: No | K3: =IF(COUNTIFS($A$2:A3,A3,$L$2:L3,L3)>1,"DUPLICATE - CHECK","") | L3: B1 | M3: =IF(COUNTIF($A2:A$2,A3)>0,"Yes - see Previous F-Code","No") -> No | N3: =IF(COUNTIF($A2:A$2,A3)>0,INDEX($C2:C$2,MATCH(A3,$A2:A$2,0)),"")
A4: =IFERROR(__xludf.DUMMYFUNCTION("IF(B4="""","""",RIGHT(regexreplace(B4&"""",""[^0-9]"",""""),9))"),"712197438") -> 712197438 | B4: +94 71 219 7438 | C4: F00003 | D4: kavinda | E4: 2026-07-03 | F4: Contacted | G4: 11 | I4: Yes | J4: details ewanna | K4: =IF(COUNTIFS($A$2:A4,A4,$L$2:L4,L4)>1,"DUPLICATE - CHECK","") | M4: =IF(COUNTIF($A3:A$2,A4)>0,"Yes - see Previous F-Code","No") -> No | N4: =IF(COUNTIF($A3:A$2,A4)>0,INDEX($C3:C$2,MATCH(A4,$A3:A$2,0)),"")
A5: =IFERROR(__xludf.DUMMYFUNCTION("IF(B5="""","""",RIGHT(regexreplace(B5&"""",""[^0-9]"",""""),9))"),"716030661") -> 716030661 | B5: 716030661 | C5: F00004 | D5: umesh | E5: 46223.351 | F5: Contacted | G5: 8, 9 | H5: send details | K5: =IF(COUNTIFS($A$2:A5,A5,$L$2:L5,L5)>1,"DUPLICATE - CHECK","") | M5: =IF(COUNTIF($A4:A$2,A5)>0,"Yes - see Previous F-Code","No") -> No | N5: {=IF(COUNTIF($A$2:A4,A)>0,INDEX($C$2:C4,MATCH(A5,$A$2:A4,0)),"")} | P5: 9
A6: =IFERROR(__xludf.DUMMYFUNCTION("IF(B6="""","""",RIGHT(regexreplace(B6&"""",""[^0-9]"",""""),9))"),"781833131") -> 781833131 | B6: 781833131 | C6: F00005 | D6: umesh | E6: 46223.351 | F6: Converted | G6: 9 | K6: =IF(COUNTIFS($A$2:A6,A6,$L$2:L6,L6)>1,"DUPLICATE - CHECK","") | M6: =IF(COUNTIF($A5:A$2,A6)>0,"Yes - see Previous F-Code","No") -> No | N6: =IF(COUNTIF($A$2:A5,A6)>0,INDEX($C$2:C5,MATCH(A6,$A$2:A5,0)),"")
A7: =IFERROR(__xludf.DUMMYFUNCTION("IF(B7="""","""",RIGHT(regexreplace(B7&"""",""[^0-9]"",""""),9))"),"716030661") -> 716030661 | B7: 716030661 | C7: F00004 | E7: 46223.355 | F7: New | G7: 7 | K7: =IF(COUNTIFS($A$2:A7,A7,$L$2:L7,L7)>1,"DUPLICATE - CHECK","") | M7: =IF(COUNTIF($A6:A$2,A7)>0,"Yes - see Previous F-Code","No") -> Yes - see Previous F-Code | N7: =IF(COUNTIF($A$2:A6,A7)>0,INDEX($C$2:C6,MATCH(A7,$A$2:A6,0)),"") -> F00004
A8: =IFERROR(__xludf.DUMMYFUNCTION("IF(B8="""","""",RIGHT(regexreplace(B8&"""",""[^0-9]"",""""),9))"),"752945180") -> 752945180 | B8: 752945180 | C8: F00006 | D8: kavinda | E8: 46223.36 | F8: No Answer | I8: No | K8: =IF(COUNTIFS($A$2:A8,A8,$L$2:L8,L8)>1,"DUPLICATE - CHECK","") | L8: B1 | M8: =IF(COUNTIF($A7:A$2,A8)>0,"Yes - see Previous F-Code","No") -> No | N8: {=IF(COUNTIF($A$2:A7,A)>0,INDEX($C$2:C7,MATCH(A8,$A$2:A7,0)),"")}
A9: =IFERROR(__xludf.DUMMYFUNCTION("IF(B9="""","""",RIGHT(regexreplace(B9&"""",""[^0-9]"",""""),9))"),"752945180") -> 752945180 | B9: 94752945180 | C9: F00006 | D9: muthumali | E9: 46223.36 | F9: Contacted | G9: 8 | K9: =IF(COUNTIFS($A$2:A9,A9,$L$2:L9,L9)>1,"DUPLICATE - CHECK","") -> DUPLICATE - CHECK | L9: B1 | M9: =IF(COUNTIF($A8:A$2,A9)>0,"Yes - see Previous F-Code","No") -> Yes - see Previous F-Code | N9: =IF(COUNTIF($A$2:A8,A9)>0,INDEX($C$2:C8,MATCH(A9,$A$2:A8,0)),"") -> F00006
A10: =IFERROR(__xludf.DUMMYFUNCTION("IF(B10="""","""",RIGHT(regexreplace(B10&"""",""[^0-9]"",""""),9))"),"778625101") -> 778625101 | B10: 778625101 | C10: F00001 | D10: umesh | E10: 46223.361 | F10: Contacted | G10: 10 | K10: =IF(COUNTIFS($A$2:A10,A10,$L$2:L10,L10)>1,"DUPLICATE - CHECK","") | L10: B2 | M10: =IF(COUNTIF($A9:A$2,A10)>0,"Yes - see Previous F-Code","No") -> Yes - see Previous F-Code | N10: =IF(COUNTIF($A$2:A9,A10)>0,INDEX($C$2:C9,MATCH(A10,$A$2:A9,0)),"") -> F00001
A11: =IFERROR(__xludf.DUMMYFUNCTION("IF(B11="""","""",RIGHT(regexreplace(B11&"""",""[^0-9]"",""""),9))"),"789632546") -> 789632546 | B11: 789632546 | C11: F00007 | E11: 46223.364 | K11: =IF(COUNTIFS($A$2:A11,A11,$L$2:L11,L11)>1,"DUPLICATE - CHECK","") | M11: =IF(COUNTIF($A10:A$2,A11)>0,"Yes - see Previous F-Code","No") -> No | N11: {=IF(COUNTIF($A$2:A10,A)>0,INDEX($C$2:C10,MATCH(A11,$A$2:A10,0)),"")}
A12: =IFERROR(__xludf.DUMMYFUNCTION("IF(B12="""","""",RIGHT(regexreplace(B12&"""",""[^0-9]"",""""),9))"),"") | K12: =IF(COUNTIFS($A$2:A12,A12,$L$2:L12,L12)>1,"DUPLICATE - CHECK","") | M12: =IF(COUNTIF($A11:A$2,A12)>0,"Yes - see Previous F-Code","No") -> No | N12: =IF(COUNTIF($A$2:A11,A12)>0,INDEX($C$2:C11,MATCH(A12,$A$2:A11,0)),"")
A13: =IFERROR(__xludf.DUMMYFUNCTION("IF(B13="""","""",RIGHT(regexreplace(B13&"""",""[^0-9]"",""""),9))"),"") | K13: =IF(COUNTIFS($A$2:A13,A13,$L$2:L13,L13)>1,"DUPLICATE - CHECK","") | M13: =IF(COUNTIF($A12:A$2,A13)>0,"Yes - see Previous F-Code","No") -> Yes - see Previous F-Code | N13: =IF(COUNTIF($A$2:A12,A13)>0,INDEX($C$2:C12,MATCH(A13,$A$2:A12,0)),"")
A14: =IFERROR(__xludf.DUMMYFUNCTION("IF(B14="""","""",RIGHT(regexreplace(B14&"""",""[^0-9]"",""""),9))"),"") | K14: =IF(COUNTIFS($A$2:A14,A14,$L$2:L14,L14)>1,"DUPLICATE - CHECK","") | M14: =IF(COUNTIF($A13:A$2,A14)>0,"Yes - see Previous F-Code","No") -> Yes - see Previous F-Code | N14: {=IF(COUNTIF($A$2:A13,A)>0,INDEX($C$2:C13,MATCH(A14,$A$2:A13,0)),"")}
A15: =IFERROR(__xludf.DUMMYFUNCTION("IF(B15="""","""",RIGHT(regexreplace(B15&"""",""[^0-9]"",""""),9))"),"") | K15: =IF(COUNTIFS($A$2:A15,A15,$L$2:L15,L15)>1,"DUPLICATE - CHECK","") | M15: =IF(COUNTIF($A14:A$2,A15)>0,"Yes - see Previous F-Code","No") -> Yes - see Previous F-Code | N15: =IF(COUNTIF($A$2:A14,A15)>0,INDEX($C$2:C14,MATCH(A15,$A$2:A14,0)),"")
A16: =IFERROR(__xludf.DUMMYFUNCTION("IF(B16="""","""",RIGHT(regexreplace(B16&"""",""[^0-9]"",""""),9))"),"") | K16: =IF(COUNTIFS($A$2:A16,A16,$L$2:L16,L16)>1,"DUPLICATE - CHECK","") | M16: =IF(COUNTIF($A15:A$2,A16)>0,"Yes - see Previous F-Code","No") -> Yes - see Previous F-Code | N16: =IF(COUNTIF($A$2:A15,A16)>0,INDEX($C$2:C15,MATCH(A16,$A$2:A15,0)),"")
A17: =IFERROR(__xludf.DUMMYFUNCTION("IF(B17="""","""",RIGHT(regexreplace(B17&"""",""[^0-9]"",""""),9))"),"") | K17: =IF(COUNTIFS($A$2:A17,A17,$L$2:L17,L17)>1,"DUPLICATE - CHECK","") | M17: =IF(COUNTIF($A16:A$2,A17)>0,"Yes - see Previous F-Code","No") -> Yes - see Previous F-Code | N17: {=IF(COUNTIF($A$2:A16,A)>0,INDEX($C$2:C16,MATCH(A17,$A$2:A16,0)),"")}
A18: =IFERROR(__xludf.DUMMYFUNCTION("IF(B18="""","""",RIGHT(regexreplace(B18&"""",""[^0-9]"",""""),9))"),"") | K18: =IF(COUNTIFS($A$2:A18,A18,$L$2:L18,L18)>1,"DUPLICATE - CHECK","") | M18: =IF(COUNTIF($A17:A$2,A18)>0,"Yes - see Previous F-Code","No") -> Yes - see Previous F-Code | N18: =IF(COUNTIF($A$2:A17,A18)>0,INDEX($C$2:C17,MATCH(A18,$A$2:A17,0)),"")
A19: =IFERROR(__xludf.DUMMYFUNCTION("IF(B19="""","""",RIGHT(regexreplace(B19&"""",""[^0-9]"",""""),9))"),"") | K19: =IF(COUNTIFS($A$2:A19,A19,$L$2:L19,L19)>1,"DUPLICATE - CHECK","") | M19: =IF(COUNTIF($A18:A$2,A19)>0,"Yes - see Previous F-Code","No") -> Yes - see Previous F-Code | N19: =IF(COUNTIF($A$2:A18,A19)>0,INDEX($C$2:C18,MATCH(A19,$A$2:A18,0)),"")
A20: =IFERROR(__xludf.DUMMYFUNCTION("IF(B20="""","""",RIGHT(regexreplace(B20&"""",""[^0-9]"",""""),9))"),"") | K20: =IF(COUNTIFS($A$2:A20,A20,$L$2:L20,L20)>1,"DUPLICATE - CHECK","") | M20: =IF(COUNTIF($A19:A$2,A20)>0,"Yes - see Previous F-Code","No") -> Yes - see Previous F-Code | N20: {=IF(COUNTIF($A$2:A19,A)>0,INDEX($C$2:C19,MATCH(A20,$A$2:A19,0)),"")}
A21: =IFERROR(__xludf.DUMMYFUNCTION("IF(B21="""","""",RIGHT(regexreplace(B21&"""",""[^0-9]"",""""),9))"),"") | K21: =IF(COUNTIFS($A$2:A21,A21,$L$2:L21,L21)>1,"DUPLICATE - CHECK","") | M21: =IF(COUNTIF($A20:A$2,A21)>0,"Yes - see Previous F-Code","No") -> Yes - see Previous F-Code | N21: =IF(COUNTIF($A$2:A20,A21)>0,INDEX($C$2:C20,MATCH(A21,$A$2:A20,0)),"")
A22: =IFERROR(__xludf.DUMMYFUNCTION("IF(B22="""","""",RIGHT(regexreplace(B22&"""",""[^0-9]"",""""),9))"),"") | K22: =IF(COUNTIFS($A$2:A22,A22,$L$2:L22,L22)>1,"DUPLICATE - CHECK","") | M22: =IF(COUNTIF($A21:A$2,A22)>0,"Yes - see Previous F-Code","No") -> Yes - see Previous F-Code | N22: =IF(COUNTIF($A$2:A21,A22)>0,INDEX($C$2:C21,MATCH(A22,$A$2:A21,0)),"")
A23: =IFERROR(__xludf.DUMMYFUNCTION("IF(B23="""","""",RIGHT(regexreplace(B23&"""",""[^0-9]"",""""),9))"),"") | K23: =IF(COUNTIFS($A$2:A23,A23,$L$2:L23,L23)>1,"DUPLICATE - CHECK","") | N23: {=IF(COUNTIF($A$2:A22,A)>0,INDEX($C$2:C22,MATCH(A23,$A$2:A22,0)),"")}
A24: =IFERROR(__xludf.DUMMYFUNCTION("IF(B24="""","""",RIGHT(regexreplace(B24&"""",""[^0-9]"",""""),9))"),"") | K24: =IF(COUNTIFS($A$2:A24,A24,$L$2:L24,L24)>1,"DUPLICATE - CHECK","") | N24: =IF(COUNTIF($A$2:A23,A24)>0,INDEX($C$2:C23,MATCH(A24,$A$2:A23,0)),"")
A25: =IFERROR(__xludf.DUMMYFUNCTION("IF(B25="""","""",RIGHT(regexreplace(B25&"""",""[^0-9]"",""""),9))"),"") | K25: =IF(COUNTIFS($A$2:A25,A25,$L$2:L25,L25)>1,"DUPLICATE - CHECK","") | N25: =IF(COUNTIF($A$2:A24,A25)>0,INDEX($C$2:C24,MATCH(A25,$A$2:A24,0)),"")
A26: =IFERROR(__xludf.DUMMYFUNCTION("IF(B26="""","""",RIGHT(regexreplace(B26&"""",""[^0-9]"",""""),9))"),"") | K26: =IF(COUNTIFS($A$2:A26,A26,$L$2:L26,L26)>1,"DUPLICATE - CHECK","") | N26: {=IF(COUNTIF($A$2:A25,A)>0,INDEX($C$2:C25,MATCH(A26,$A$2:A25,0)),"")}
A27: =IFERROR(__xludf.DUMMYFUNCTION("IF(B27="""","""",RIGHT(regexreplace(B27&"""",""[^0-9]"",""""),9))"),"") | K27: =IF(COUNTIFS($A$2:A27,A27,$L$2:L27,L27)>1,"DUPLICATE - CHECK","") | N27: =IF(COUNTIF($A$2:A26,A27)>0,INDEX($C$2:C26,MATCH(A27,$A$2:A26,0)),"")
A28: =IFERROR(__xludf.DUMMYFUNCTION("IF(B28="""","""",RIGHT(regexreplace(B28&"""",""[^0-9]"",""""),9))"),"") | K28: =IF(COUNTIFS($A$2:A28,A28,$L$2:L28,L28)>1,"DUPLICATE - CHECK","") | N28: =IF(COUNTIF($A$2:A27,A28)>0,INDEX($C$2:C27,MATCH(A28,$A$2:A27,0)),"")
A29: =IFERROR(__xludf.DUMMYFUNCTION("IF(B29="""","""",RIGHT(regexreplace(B29&"""",""[^0-9]"",""""),9))"),"") | K29: =IF(COUNTIFS($A$2:A29,A29,$L$2:L29,L29)>1,"DUPLICATE - CHECK","") | N29: {=IF(COUNTIF($A$2:A28,A)>0,INDEX($C$2:C28,MATCH(A29,$A$2:A28,0)),"")}
A30: =IFERROR(__xludf.DUMMYFUNCTION("IF(B30="""","""",RIGHT(regexreplace(B30&"""",""[^0-9]"",""""),9))"),"") | K30: =IF(COUNTIFS($A$2:A30,A30,$L$2:L30,L30)>1,"DUPLICATE - CHECK","") | N30: =IF(COUNTIF($A$2:A29,A30)>0,INDEX($C$2:C29,MATCH(A30,$A$2:A29,0)),"")
A31: =IFERROR(__xludf.DUMMYFUNCTION("IF(B31="""","""",RIGHT(regexreplace(B31&"""",""[^0-9]"",""""),9))"),"") | K31: =IF(COUNTIFS($A$2:A31,A31,$L$2:L31,L31)>1,"DUPLICATE - CHECK","") | N31: =IF(COUNTIF($A$2:A30,A31)>0,INDEX($C$2:C30,MATCH(A31,$A$2:A30,0)),"")
A32: =IFERROR(__xludf.DUMMYFUNCTION("IF(B32="""","""",RIGHT(regexreplace(B32&"""",""[^0-9]"",""""),9))"),"") | K32: =IF(COUNTIFS($A$2:A32,A32,$L$2:L32,L32)>1,"DUPLICATE - CHECK","") | N32: {=IF(COUNTIF($A$2:A31,A)>0,INDEX($C$2:C31,MATCH(A32,$A$2:A31,0)),"")}
A33: =IFERROR(__xludf.DUMMYFUNCTION("IF(B33="""","""",RIGHT(regexreplace(B33&"""",""[^0-9]"",""""),9))"),"") | K33: =IF(COUNTIFS($A$2:A33,A33,$L$2:L33,L33)>1,"DUPLICATE - CHECK","") | N33: =IF(COUNTIF($A$2:A32,A33)>0,INDEX($C$2:C32,MATCH(A33,$A$2:A32,0)),"")
A34: =IFERROR(__xludf.DUMMYFUNCTION("IF(B34="""","""",RIGHT(regexreplace(B34&"""",""[^0-9]"",""""),9))"),"") | K34: =IF(COUNTIFS($A$2:A34,A34,$L$2:L34,L34)>1,"DUPLICATE - CHECK","") | N34: =IF(COUNTIF($A$2:A33,A34)>0,INDEX($C$2:C33,MATCH(A34,$A$2:A33,0)),"")
A35: =IFERROR(__xludf.DUMMYFUNCTION("IF(B35="""","""",RIGHT(regexreplace(B35&"""",""[^0-9]"",""""),9))"),"") | K35: =IF(COUNTIFS($A$2:A35,A35,$L$2:L35,L35)>1,"DUPLICATE - CHECK","") | N35: {=IF(COUNTIF($A$2:A34,A)>0,INDEX($C$2:C34,MATCH(A35,$A$2:A34,0)),"")}
A36: =IFERROR(__xludf.DUMMYFUNCTION("IF(B36="""","""",RIGHT(regexreplace(B36&"""",""[^0-9]"",""""),9))"),"") | K36: =IF(COUNTIFS($A$2:A36,A36,$L$2:L36,L36)>1,"DUPLICATE - CHECK","") | N36: =IF(COUNTIF($A$2:A35,A36)>0,INDEX($C$2:C35,MATCH(A36,$A$2:A35,0)),"")
A37: =IFERROR(__xludf.DUMMYFUNCTION("IF(B37="""","""",RIGHT(regexreplace(B37&"""",""[^0-9]"",""""),9))"),"") | K37: =IF(COUNTIFS($A$2:A37,A37,$L$2:L37,L37)>1,"DUPLICATE - CHECK","") | N37: =IF(COUNTIF($A$2:A36,A37)>0,INDEX($C$2:C36,MATCH(A37,$A$2:A36,0)),"")
A38: =IFERROR(__xludf.DUMMYFUNCTION("IF(B38="""","""",RIGHT(regexreplace(B38&"""",""[^0-9]"",""""),9))"),"") | K38: =IF(COUNTIFS($A$2:A38,A38,$L$2:L38,L38)>1,"DUPLICATE - CHECK","") | N38: {=IF(COUNTIF($A$2:A37,A)>0,INDEX($C$2:C37,MATCH(A38,$A$2:A37,0)),"")}
A39: =IFERROR(__xludf.DUMMYFUNCTION("IF(B39="""","""",RIGHT(regexreplace(B39&"""",""[^0-9]"",""""),9))"),"") | K39: =IF(COUNTIFS($A$2:A39,A39,$L$2:L39,L39)>1,"DUPLICATE - CHECK","") | N39: =IF(COUNTIF($A$2:A38,A39)>0,INDEX($C$2:C38,MATCH(A39,$A$2:A38,0)),"")
A40: =IFERROR(__xludf.DUMMYFUNCTION("IF(B40="""","""",RIGHT(regexreplace(B40&"""",""[^0-9]"",""""),9))"),"") | K40: =IF(COUNTIFS($A$2:A40,A40,$L$2:L40,L40)>1,"DUPLICATE - CHECK","") | N40: =IF(COUNTIF($A$2:A39,A40)>0,INDEX($C$2:C39,MATCH(A40,$A$2:A39,0)),"")
...

Sheet Leads Summary
A1: Member | B1: Total Leads Handled | C1: Converted Leads | D1: Conversion Rate
A2: =Members!A2 -> maheesha | B2: =COUNTIF('Master Leads'!$D$2:$D$1000,A2) -> 1 | C2: =COUNTIFS('Master Leads'!$D$2:$D$1000,A2,'Master Leads'!$F$2:$F$1000,"Converted") -> 1 | D2: =IF(B2=0,"-",C2/B2) -> 1
A3: =Members!A3 -> menik | B3: =COUNTIF('Master Leads'!$D$2:$D$1000,A3) -> 0 | C3: =COUNTIFS('Master Leads'!$D$2:$D$1000,A3,'Master Leads'!$F$2:$F$1000,"Converted") -> 0 | D3: =IF(B3=0,"-",C3/B3) -> -
A4: =Members!A4 -> kavinda | B4: =COUNTIF('Master Leads'!$D$2:$D$1000,A4) -> 2 | C4: =COUNTIFS('Master Leads'!$D$2:$D$1000,A4,'Master Leads'!$F$2:$F$1000,"Converted") -> 0 | D4: =IF(B4=0,"-",C4/B4) -> 0
A5: =Members!A5 -> umesh | B5: =COUNTIF('Master Leads'!$D$2:$D$1000,A5) -> 4 | C5: =COUNTIFS('Master Leads'!$D$2:$D$1000,A5,'Master Leads'!$F$2:$F$1000,"Converted") -> 1 | D5: =IF(B5=0,"-",C5/B5) -> 0.25
A6: =Members!A6 -> Avishka | B6: =COUNTIF('Master Leads'!$D$2:$D$1000,A6) -> 0 | C6: =COUNTIFS('Master Leads'!$D$2:$D$1000,A6,'Master Leads'!$F$2:$F$1000,"Converted") -> 0 | D6: =IF(B6=0,"-",C6/B6) -> -
A7: =Members!A7 -> Wihanga | B7: =COUNTIF('Master Leads'!$D$2:$D$1000,A7) -> 0 | C7: =COUNTIFS('Master Leads'!$D$2:$D$1000,A7,'Master Leads'!$F$2:$F$1000,"Converted") -> 0 | D7: =IF(B7=0,"-",C7/B7) -> -
A8: =Members!A8 -> muthumali | B8: =COUNTIF('Master Leads'!$D$2:$D$1000,A8) -> 1 | C8: =COUNTIFS('Master Leads'!$D$2:$D$1000,A8,'Master Leads'!$F$2:$F$1000,"Converted") -> 0 | D8: =IF(B8=0,"-",C8/B8) -> 0
A9: =Members!A9 -> shamali | B9: =COUNTIF('Master Leads'!$D$2:$D$1000,A9) -> 0 | C9: =COUNTIFS('Master Leads'!$D$2:$D$1000,A9,'Master Leads'!$F$2:$F$1000,"Converted") -> 0 | D9: =IF(B9=0,"-",C9/B9) -> -
A10: TOTAL | B10: =SUM(B2:B9) -> 8 | C10: =SUM(C2:C9) -> 2 | D10: =IF(B10=0,"-",C10/B10) -> 0.25
