Workbook

Sheet Executive Dashboard
B2: LEAD MANAGEMENT SYSTEM | EXECUTIVE DASHBOARD
B3: Live data from Master Leads · Auto-refreshes with new entries · Professional CRM Analytics
B5: TOTAL LEADS | G5: PAID STUDENTS | L5: CONVERSION RATE | Q5: REPEAT STUDENTS | V5: ACTIVE LEADS
B6: =COUNTA('Master Leads'!B:B)-1 -> 10 | G6: =COUNTIF('Master Leads'!O:O,"Yes") -> 2 | L6: =IFERROR(COUNTIF('Master Leads'!F:F,"Converted")/(COUNTA('Master Leads'!B:B)-1),0) -> 0.2 | Q6: =COUNTIF('Master Leads'!M:M,"Yes*") -> 13 | V6: =COUNTIF('Master Leads'!F:F,"New")+COUNTIF('Master Leads'!F:F,"Contacted") -> 5
B7: All entries in Master Leads | G7: Confirmed fee paid (col O = Yes) | L7: Converted leads ÷ Total leads | Q7: Same student, multiple campaigns | V7: Status = New or Contacted
B9: NO ANSWER | G9: CONVERTED | L9: INTERESTED | Q9: TODAY'S LEADS | V9: THIS MONTH
B10: =COUNTIF('Master Leads'!F:F,"No Answer") -> 1 | G10: =COUNTIF('Master Leads'!F:F,"Converted") -> 2 | L10: =COUNTIF('Master Leads'!F:F,"Interested") -> 0 | Q10: =COUNTIF('Master Leads'!E:E,TODAY()) -> 0 | V10: =COUNTIFS('Master Leads'!E:E,">="&DATE(YEAR(TODAY()),MONTH(TODAY()),1),'Master Leads'!E:E,"<="&EOMONTH(TODAY(),0)) -> 7
B11: Calls not picked up | G11: Successfully converted | L11: Interested but not yet paid | Q11: New leads added today | V11: Leads added this month
B13: PERFORMANCE ANALYTICS — Charts auto-update from Master Leads
B57: NOTE: Campaign chart uses B1-B10 by default. Update campaign names in _DB1_Data sheet (col A, rows 31-40) to match your actual campaigns.

Sheet Grade Interest
B2: GRADE INTEREST DASHBOARD | Leads by Grade (6 - 11)
B3: Shows how many leads enquired for each grade · Auto-updates with new data
B5: GRADE BREAKDOWN — Leads, Paid Students & Percentage per Grade
B7: Grade | E7: Total Leads | I7: Paid Students | M7: Lead % | P7: Paid % | S7: Interested → Paid Conv.
B8: Grade 6 | E8: =COUNTIF('Master Leads'!G:G,6) -> 1 | I8: =COUNTIFS('Master Leads'!G:G,6,'Master Leads'!O:O,"Yes") -> 0 | M8: =IFERROR(COUNTIF('Master Leads'!G:G,6)/(COUNTA('Master Leads'!B:B)-1),0) -> 0.1 | P8: =IFERROR(COUNTIFS('Master Leads'!G:G,6,'Master Leads'!O:O,"Yes")/COUNTIF('Master Leads'!G:G,6),0) -> 0 | S8: =IFERROR(COUNTIFS('Master Leads'!G:G,6,'Master Leads'!O:O,"Yes")/(COUNTIFS('Master Leads'!G:G,6,'Master Leads'!F:F,"Interested")+COUNTIFS('Master Leads'!G:G,6,'Master Leads'!O:O,"Yes")),0) -> 0
B9: Grade 7 | E9: =COUNTIF('Master Leads'!G:G,7) -> 1 | I9: =COUNTIFS('Master Leads'!G:G,7,'Master Leads'!O:O,"Yes") -> 1 | M9: =IFERROR(COUNTIF('Master Leads'!G:G,7)/(COUNTA('Master Leads'!B:B)-1),0) -> 0.1 | P9: =IFERROR(COUNTIFS('Master Leads'!G:G,7,'Master Leads'!O:O,"Yes")/COUNTIF('Master Leads'!G:G,7),0) -> 1 | S9: =IFERROR(COUNTIFS('Master Leads'!G:G,7,'Master Leads'!O:O,"Yes")/(COUNTIFS('Master Leads'!G:G,7,'Master Leads'!F:F,"Interested")+COUNTIFS('Master Leads'!G:G,7,'Master Leads'!O:O,"Yes")),0) -> 1
B10: Grade 8 | E10: =COUNTIF('Master Leads'!G:G,8) -> 1 | I10: =COUNTIFS('Master Leads'!G:G,8,'Master Leads'!O:O,"Yes") -> 0 | M10: =IFERROR(COUNTIF('Master Leads'!G:G,8)/(COUNTA('Master Leads'!B:B)-1),0) -> 0.1 | P10: =IFERROR(COUNTIFS('Master Leads'!G:G,8,'Master Leads'!O:O,"Yes")/COUNTIF('Master Leads'!G:G,8),0) -> 0 | S10: =IFERROR(COUNTIFS('Master Leads'!G:G,8,'Master Leads'!O:O,"Yes")/(COUNTIFS('Master Leads'!G:G,8,'Master Leads'!F:F,"Interested")+COUNTIFS('Master Leads'!G:G,8,'Master Leads'!O:O,"Yes")),0) -> 0
B11: Grade 9 | E11: =COUNTIF('Master Leads'!G:G,9) -> 1 | I11: =COUNTIFS('Master Leads'!G:G,9,'Master Leads'!O:O,"Yes") -> 0 | M11: =IFERROR(COUNTIF('Master Leads'!G:G,9)/(COUNTA('Master Leads'!B:B)-1),0) -> 0.1 | P11: =IFERROR(COUNTIFS('Master Leads'!G:G,9,'Master Leads'!O:O,"Yes")/COUNTIF('Master Leads'!G:G,9),0) -> 0 | S11: =IFERROR(COUNTIFS('Master Leads'!G:G,9,'Master Leads'!O:O,"Yes")/(COUNTIFS('Master Leads'!G:G,9,'Master Leads'!F:F,"Interested")+COUNTIFS('Master Leads'!G:G,9,'Master Leads'!O:O,"Yes")),0) -> 0
B12: Grade 10 | E12: =COUNTIF('Master Leads'!G:G,10) -> 1 | I12: =COUNTIFS('Master Leads'!G:G,10,'Master Leads'!O:O,"Yes") -> 0 | M12: =IFERROR(COUNTIF('Master Leads'!G:G,10)/(COUNTA('Master Leads'!B:B)-1),0) -> 0.1 | P12: =IFERROR(COUNTIFS('Master Leads'!G:G,10,'Master Leads'!O:O,"Yes")/COUNTIF('Master Leads'!G:G,10),0) -> 0 | S12: =IFERROR(COUNTIFS('Master Leads'!G:G,10,'Master Leads'!O:O,"Yes")/(COUNTIFS('Master Leads'!G:G,10,'Master Leads'!F:F,"Interested")+COUNTIFS('Master Leads'!G:G,10,'Master Leads'!O:O,"Yes")),0) -> 0
B13: Grade 11 | E13: =COUNTIF('Master Leads'!G:G,11) -> 1 | I13: =COUNTIFS('Master Leads'!G:G,11,'Master Leads'!O:O,"Yes") -> 1 | M13: =IFERROR(COUNTIF('Master Leads'!G:G,11)/(COUNTA('Master Leads'!B:B)-1),0) -> 0.1 | P13: =IFERROR(COUNTIFS('Master Leads'!G:G,11,'Master Leads'!O:O,"Yes")/COUNTIF('Master Leads'!G:G,11),0) -> 1 | S13: =IFERROR(COUNTIFS('Master Leads'!G:G,11,'Master Leads'!O:O,"Yes")/(COUNTIFS('Master Leads'!G:G,11,'Master Leads'!F:F,"Interested")+COUNTIFS('Master Leads'!G:G,11,'Master Leads'!O:O,"Yes")),0) -> 1
B14: TOTAL | E14: =COUNTA('Master Leads'!B:B)-1 -> 10 | I14: =COUNTIF('Master Leads'!O:O,"Yes") -> 2 | M14: 100%

Sheet Paid Dashboard
B2: PAID STUDENT DASHBOARD | Fee-Confirmed Enrollments
B3: Shows all students who have confirmed payment · Grade-wise breakdown · Conversion rates
B5: TOTAL PAID | H5: TOTAL LEADS | N5: OVERALL PAID % | T5: INTERESTED → PAID
B6: =COUNTIF('Master Leads'!O:O,"Yes") -> 2 | H6: =COUNTA('Master Leads'!B:B)-1 -> 10 | N6: =IFERROR(COUNTIF('Master Leads'!O:O,"Yes")/(COUNTA('Master Leads'!B:B)-1),0) -> 0.2 | T6: =IFERROR(COUNTIF('Master Leads'!O:O,"Yes")/(COUNTIF('Master Leads'!F:F,"Interested")+COUNTIF('Master Leads'!O:O,"Yes")),0) -> 1
B7: All confirmed paid students | H7: All leads in system | N7: Paid ÷ Total Leads | T7: Of interested leads, how many paid
B9: GRADE 6 PAID | G9: GRADE 7 PAID | L9: GRADE 8 PAID | Q9: GRADE 9 PAID
B10: =COUNTIFS('Master Leads'!G:G,6,'Master Leads'!O:O,"Yes") -> 0 | G10: =COUNTIFS('Master Leads'!G:G,7,'Master Leads'!O:O,"Yes") -> 1 | L10: =COUNTIFS('Master Leads'!G:G,8,'Master Leads'!O:O,"Yes") -> 0 | Q10: =COUNTIFS('Master Leads'!G:G,9,'Master Leads'!O:O,"Yes") -> 0
B11: Paid in Grade 6 | G11: Paid in Grade 7 | L11: Paid in Grade 8 | Q11: Paid in Grade 9
B13: GRADE 10 PAID | G13: GRADE 11 PAID
B14: =COUNTIFS('Master Leads'!G:G,10,'Master Leads'!O:O,"Yes") -> 0 | G14: =COUNTIFS('Master Leads'!G:G,11,'Master Leads'!O:O,"Yes") -> 1
B15: Paid in Grade 10 | G15: Paid in Grade 11
B17: GRADE-WISE PAID BREAKDOWN — Detailed conversion per grade
B18: Grade | E18: Total Leads | I18: Paid | M18: Not Paid | Q18: Paid % | T18: Interested→Paid
B19: Grade 6 | E19: =COUNTIF('Master Leads'!G:G,6) -> 1 | I19: =COUNTIFS('Master Leads'!G:G,6,'Master Leads'!O:O,"Yes") -> 0 | M19: =COUNTIF('Master Leads'!G:G,6)-COUNTIFS('Master Leads'!G:G,6,'Master Leads'!O:O,"Yes") -> 1 | Q19: =IFERROR(COUNTIFS('Master Leads'!G:G,6,'Master Leads'!O:O,"Yes")/COUNTIF('Master Leads'!G:G,6),0) -> 0 | T19: =IFERROR(COUNTIFS('Master Leads'!G:G,6,'Master Leads'!O:O,"Yes")/(COUNTIFS('Master Leads'!G:G,6,'Master Leads'!F:F,"Interested")+COUNTIFS('Master Leads'!G:G,6,'Master Leads'!O:O,"Yes")),0) -> 0
B20: Grade 7 | E20: =COUNTIF('Master Leads'!G:G,7) -> 1 | I20: =COUNTIFS('Master Leads'!G:G,7,'Master Leads'!O:O,"Yes") -> 1 | M20: =COUNTIF('Master Leads'!G:G,7)-COUNTIFS('Master Leads'!G:G,7,'Master Leads'!O:O,"Yes") -> 0 | Q20: =IFERROR(COUNTIFS('Master Leads'!G:G,7,'Master Leads'!O:O,"Yes")/COUNTIF('Master Leads'!G:G,7),0) -> 1 | T20: =IFERROR(COUNTIFS('Master Leads'!G:G,7,'Master Leads'!O:O,"Yes")/(COUNTIFS('Master Leads'!G:G,7,'Master Leads'!F:F,"Interested")+COUNTIFS('Master Leads'!G:G,7,'Master Leads'!O:O,"Yes")),0) -> 1
B21: Grade 8 | E21: =COUNTIF('Master Leads'!G:G,8) -> 1 | I21: =COUNTIFS('Master Leads'!G:G,8,'Master Leads'!O:O,"Yes") -> 0 | M21: =COUNTIF('Master Leads'!G:G,8)-COUNTIFS('Master Leads'!G:G,8,'Master Leads'!O:O,"Yes") -> 1 | Q21: =IFERROR(COUNTIFS('Master Leads'!G:G,8,'Master Leads'!O:O,"Yes")/COUNTIF('Master Leads'!G:G,8),0) -> 0 | T21: =IFERROR(COUNTIFS('Master Leads'!G:G,8,'Master Leads'!O:O,"Yes")/(COUNTIFS('Master Leads'!G:G,8,'Master Leads'!F:F,"Interested")+COUNTIFS('Master Leads'!G:G,8,'Master Leads'!O:O,"Yes")),0) -> 0
B22: Grade 9 | E22: =COUNTIF('Master Leads'!G:G,9) -> 1 | I22: =COUNTIFS('Master Leads'!G:G,9,'Master Leads'!O:O,"Yes") -> 0 | M22: =COUNTIF('Master Leads'!G:G,9)-COUNTIFS('Master Leads'!G:G,9,'Master Leads'!O:O,"Yes") -> 1 | Q22: =IFERROR(COUNTIFS('Master Leads'!G:G,9,'Master Leads'!O:O,"Yes")/COUNTIF('Master Leads'!G:G,9),0) -> 0 | T22: =IFERROR(COUNTIFS('Master Leads'!G:G,9,'Master Leads'!O:O,"Yes")/(COUNTIFS('Master Leads'!G:G,9,'Master Leads'!F:F,"Interested")+COUNTIFS('Master Leads'!G:G,9,'Master Leads'!O:O,"Yes")),0) -> 0
B23: Grade 10 | E23: =COUNTIF('Master Leads'!G:G,10) -> 1 | I23: =COUNTIFS('Master Leads'!G:G,10,'Master Leads'!O:O,"Yes") -> 0 | M23: =COUNTIF('Master Leads'!G:G,10)-COUNTIFS('Master Leads'!G:G,10,'Master Leads'!O:O,"Yes") -> 1 | Q23: =IFERROR(COUNTIFS('Master Leads'!G:G,10,'Master Leads'!O:O,"Yes")/COUNTIF('Master Leads'!G:G,10),0) -> 0 | T23: =IFERROR(COUNTIFS('Master Leads'!G:G,10,'Master Leads'!O:O,"Yes")/(COUNTIFS('Master Leads'!G:G,10,'Master Leads'!F:F,"Interested")+COUNTIFS('Master Leads'!G:G,10,'Master Leads'!O:O,"Yes")),0) -> 0
B24: Grade 11 | E24: =COUNTIF('Master Leads'!G:G,11) -> 1 | I24: =COUNTIFS('Master Leads'!G:G,11,'Master Leads'!O:O,"Yes") -> 1 | M24: =COUNTIF('Master Leads'!G:G,11)-COUNTIFS('Master Leads'!G:G,11,'Master Leads'!O:O,"Yes") -> 0 | Q24: =IFERROR(COUNTIFS('Master Leads'!G:G,11,'Master Leads'!O:O,"Yes")/COUNTIF('Master Leads'!G:G,11),0) -> 1 | T24: =IFERROR(COUNTIFS('Master Leads'!G:G,11,'Master Leads'!O:O,"Yes")/(COUNTIFS('Master Leads'!G:G,11,'Master Leads'!F:F,"Interested")+COUNTIFS('Master Leads'!G:G,11,'Master Leads'!O:O,"Yes")),0) -> 1
B25: TOTAL | E25: =COUNTA('Master Leads'!B:B)-1 -> 10 | I25: =COUNTIF('Master Leads'!O:O,"Yes") -> 2
B26: PAID CHARTS — Visual breakdown of payments by grade

Sheet Member Performance
B2: MEMBER PERFORMANCE DASHBOARD | Staff Leads, Conversions & Rankings
B3: See which team member handles the most leads and converts best · Auto-updates
B5: MEMBER-WISE LEAD & CONVERSION PERFORMANCE
B6: Member | G6: Total Leads | K6: Paid | O6: Converted | S6: No Answer | W6: Conv. % | AA6: Paid % | AE6: Rank
B7: maheesha | G7: =COUNTIF('Master Leads'!D:D,"maheesha") -> 1 | K7: =COUNTIFS('Master Leads'!D:D,"maheesha",'Master Leads'!O:O,"Yes") -> 0 | O7: =COUNTIFS('Master Leads'!D:D,"maheesha",'Master Leads'!F:F,"Converted") -> 1 | S7: =COUNTIFS('Master Leads'!D:D,"maheesha",'Master Leads'!F:F,"No Answer") -> 0 | W7: =IFERROR(COUNTIFS('Master Leads'!D:D,"maheesha",'Master Leads'!F:F,"Converted")/COUNTIF('Master Leads'!D:D,"maheesha"),0) -> 1 | AA7: =IFERROR(COUNTIFS('Master Leads'!D:D,"maheesha",'Master Leads'!O:O,"Yes")/COUNTIF('Master Leads'!D:D,"maheesha"),0) -> 0
B8: menik | G8: =COUNTIF('Master Leads'!D:D,"menik") -> 0 | K8: =COUNTIFS('Master Leads'!D:D,"menik",'Master Leads'!O:O,"Yes") -> 0 | O8: =COUNTIFS('Master Leads'!D:D,"menik",'Master Leads'!F:F,"Converted") -> 0 | S8: =COUNTIFS('Master Leads'!D:D,"menik",'Master Leads'!F:F,"No Answer") -> 0 | W8: =IFERROR(COUNTIFS('Master Leads'!D:D,"menik",'Master Leads'!F:F,"Converted")/COUNTIF('Master Leads'!D:D,"menik"),0) -> 0 | AA8: =IFERROR(COUNTIFS('Master Leads'!D:D,"menik",'Master Leads'!O:O,"Yes")/COUNTIF('Master Leads'!D:D,"menik"),0) -> 0
B9: kavinda | G9: =COUNTIF('Master Leads'!D:D,"kavinda") -> 2 | K9: =COUNTIFS('Master Leads'!D:D,"kavinda",'Master Leads'!O:O,"Yes") -> 1 | O9: =COUNTIFS('Master Leads'!D:D,"kavinda",'Master Leads'!F:F,"Converted") -> 0 | S9: =COUNTIFS('Master Leads'!D:D,"kavinda",'Master Leads'!F:F,"No Answer") -> 1 | W9: =IFERROR(COUNTIFS('Master Leads'!D:D,"kavinda",'Master Leads'!F:F,"Converted")/COUNTIF('Master Leads'!D:D,"kavinda"),0) -> 0 | AA9: =IFERROR(COUNTIFS('Master Leads'!D:D,"kavinda",'Master Leads'!O:O,"Yes")/COUNTIF('Master Leads'!D:D,"kavinda"),0) -> 0.5
B10: umesh | G10: =COUNTIF('Master Leads'!D:D,"umesh") -> 4 | K10: =COUNTIFS('Master Leads'!D:D,"umesh",'Master Leads'!O:O,"Yes") -> 0 | O10: =COUNTIFS('Master Leads'!D:D,"umesh",'Master Leads'!F:F,"Converted") -> 1 | S10: =COUNTIFS('Master Leads'!D:D,"umesh",'Master Leads'!F:F,"No Answer") -> 0 | W10: =IFERROR(COUNTIFS('Master Leads'!D:D,"umesh",'Master Leads'!F:F,"Converted")/COUNTIF('Master Leads'!D:D,"umesh"),0) -> 0.25 | AA10: =IFERROR(COUNTIFS('Master Leads'!D:D,"umesh",'Master Leads'!O:O,"Yes")/COUNTIF('Master Leads'!D:D,"umesh"),0) -> 0
B11: Avishka | G11: =COUNTIF('Master Leads'!D:D,"Avishka") -> 0 | K11: =COUNTIFS('Master Leads'!D:D,"Avishka",'Master Leads'!O:O,"Yes") -> 0 | O11: =COUNTIFS('Master Leads'!D:D,"Avishka",'Master Leads'!F:F,"Converted") -> 0 | S11: =COUNTIFS('Master Leads'!D:D,"Avishka",'Master Leads'!F:F,"No Answer") -> 0 | W11: =IFERROR(COUNTIFS('Master Leads'!D:D,"Avishka",'Master Leads'!F:F,"Converted")/COUNTIF('Master Leads'!D:D,"Avishka"),0) -> 0 | AA11: =IFERROR(COUNTIFS('Master Leads'!D:D,"Avishka",'Master Leads'!O:O,"Yes")/COUNTIF('Master Leads'!D:D,"Avishka"),0) -> 0
B12: Wihanga | G12: =COUNTIF('Master Leads'!D:D,"Wihanga") -> 0 | K12: =COUNTIFS('Master Leads'!D:D,"Wihanga",'Master Leads'!O:O,"Yes") -> 0 | O12: =COUNTIFS('Master Leads'!D:D,"Wihanga",'Master Leads'!F:F,"Converted") -> 0 | S12: =COUNTIFS('Master Leads'!D:D,"Wihanga",'Master Leads'!F:F,"No Answer") -> 0 | W12: =IFERROR(COUNTIFS('Master Leads'!D:D,"Wihanga",'Master Leads'!F:F,"Converted")/COUNTIF('Master Leads'!D:D,"Wihanga"),0) -> 0 | AA12: =IFERROR(COUNTIFS('Master Leads'!D:D,"Wihanga",'Master Leads'!O:O,"Yes")/COUNTIF('Master Leads'!D:D,"Wihanga"),0) -> 0
B13: muthumali | G13: =COUNTIF('Master Leads'!D:D,"muthumali") -> 1 | K13: =COUNTIFS('Master Leads'!D:D,"muthumali",'Master Leads'!O:O,"Yes") -> 0 | O13: =COUNTIFS('Master Leads'!D:D,"muthumali",'Master Leads'!F:F,"Converted") -> 0 | S13: =COUNTIFS('Master Leads'!D:D,"muthumali",'Master Leads'!F:F,"No Answer") -> 0 | W13: =IFERROR(COUNTIFS('Master Leads'!D:D,"muthumali",'Master Leads'!F:F,"Converted")/COUNTIF('Master Leads'!D:D,"muthumali"),0) -> 0 | AA13: =IFERROR(COUNTIFS('Master Leads'!D:D,"muthumali",'Master Leads'!O:O,"Yes")/COUNTIF('Master Leads'!D:D,"muthumali"),0) -> 0
B14: shamali | G14: =COUNTIF('Master Leads'!D:D,"shamali") -> 0 | K14: =COUNTIFS('Master Leads'!D:D,"shamali",'Master Leads'!O:O,"Yes") -> 0 | O14: =COUNTIFS('Master Leads'!D:D,"shamali",'Master Leads'!F:F,"Converted") -> 0 | S14: =COUNTIFS('Master Leads'!D:D,"shamali",'Master Leads'!F:F,"No Answer") -> 0 | W14: =IFERROR(COUNTIFS('Master Leads'!D:D,"shamali",'Master Leads'!F:F,"Converted")/COUNTIF('Master Leads'!D:D,"shamali"),0) -> 0 | AA14: =IFERROR(COUNTIFS('Master Leads'!D:D,"shamali",'Master Leads'!O:O,"Yes")/COUNTIF('Master Leads'!D:D,"shamali"),0) -> 0
B15: TOTAL | G15: =COUNTA('Master Leads'!B:B)-1 -> 10 | K15: =COUNTIF('Master Leads'!O:O,"Yes") -> 2
B17: GRADE BREAKDOWN BY MEMBER — Which member handles which grade
B18: Member | G18: Grade 6 | J18: Grade 7 | M18: Grade 8 | P18: Grade 9 | S18: Grade 10 | V18: Grade 11 | Y18: Total
B19: maheesha | G19: =COUNTIFS('Master Leads'!D:D,"maheesha",'Master Leads'!G:G,6) -> 1 | J19: =COUNTIFS('Master Leads'!D:D,"maheesha",'Master Leads'!G:G,7) -> 0 | M19: =COUNTIFS('Master Leads'!D:D,"maheesha",'Master Leads'!G:G,8) -> 0 | P19: =COUNTIFS('Master Leads'!D:D,"maheesha",'Master Leads'!G:G,9) -> 0 | S19: =COUNTIFS('Master Leads'!D:D,"maheesha",'Master Leads'!G:G,10) -> 0 | V19: =COUNTIFS('Master Leads'!D:D,"maheesha",'Master Leads'!G:G,11) -> 0 | Y19: =COUNTIF('Master Leads'!D:D,"maheesha") -> 1
B20: menik | G20: =COUNTIFS('Master Leads'!D:D,"menik",'Master Leads'!G:G,6) -> 0 | J20: =COUNTIFS('Master Leads'!D:D,"menik",'Master Leads'!G:G,7) -> 0 | M20: =COUNTIFS('Master Leads'!D:D,"menik",'Master Leads'!G:G,8) -> 0 | P20: =COUNTIFS('Master Leads'!D:D,"menik",'Master Leads'!G:G,9) -> 0 | S20: =COUNTIFS('Master Leads'!D:D,"menik",'Master Leads'!G:G,10) -> 0 | V20: =COUNTIFS('Master Leads'!D:D,"menik",'Master Leads'!G:G,11) -> 0 | Y20: =COUNTIF('Master Leads'!D:D,"menik") -> 0
B21: kavinda | G21: =COUNTIFS('Master Leads'!D:D,"kavinda",'Master Leads'!G:G,6) -> 0 | J21: =COUNTIFS('Master Leads'!D:D,"kavinda",'Master Leads'!G:G,7) -> 0 | M21: =COUNTIFS('Master Leads'!D:D,"kavinda",'Master Leads'!G:G,8) -> 0 | P21: =COUNTIFS('Master Leads'!D:D,"kavinda",'Master Leads'!G:G,9) -> 0 | S21: =COUNTIFS('Master Leads'!D:D,"kavinda",'Master Leads'!G:G,10) -> 0 | V21: =COUNTIFS('Master Leads'!D:D,"kavinda",'Master Leads'!G:G,11) -> 1 | Y21: =COUNTIF('Master Leads'!D:D,"kavinda") -> 2
B22: umesh | G22: =COUNTIFS('Master Leads'!D:D,"umesh",'Master Leads'!G:G,6) -> 0 | J22: =COUNTIFS('Master Leads'!D:D,"umesh",'Master Leads'!G:G,7) -> 0 | M22: =COUNTIFS('Master Leads'!D:D,"umesh",'Master Leads'!G:G,8) -> 0 | P22: =COUNTIFS('Master Leads'!D:D,"umesh",'Master Leads'!G:G,9) -> 1 | S22: =COUNTIFS('Master Leads'!D:D,"umesh",'Master Leads'!G:G,10) -> 1 | V22: =COUNTIFS('Master Leads'!D:D,"umesh",'Master Leads'!G:G,11) -> 0 | Y22: =COUNTIF('Master Leads'!D:D,"umesh") -> 4
B23: Avishka | G23: =COUNTIFS('Master Leads'!D:D,"Avishka",'Master Leads'!G:G,6) -> 0 | J23: =COUNTIFS('Master Leads'!D:D,"Avishka",'Master Leads'!G:G,7) -> 0 | M23: =COUNTIFS('Master Leads'!D:D,"Avishka",'Master Leads'!G:G,8) -> 0 | P23: =COUNTIFS('Master Leads'!D:D,"Avishka",'Master Leads'!G:G,9) -> 0 | S23: =COUNTIFS('Master Leads'!D:D,"Avishka",'Master Leads'!G:G,10) -> 0 | V23: =COUNTIFS('Master Leads'!D:D,"Avishka",'Master Leads'!G:G,11) -> 0 | Y23: =COUNTIF('Master Leads'!D:D,"Avishka") -> 0
B24: Wihanga | G24: =COUNTIFS('Master Leads'!D:D,"Wihanga",'Master Leads'!G:G,6) -> 0 | J24: =COUNTIFS('Master Leads'!D:D,"Wihanga",'Master Leads'!G:G,7) -> 0 | M24: =COUNTIFS('Master Leads'!D:D,"Wihanga",'Master Leads'!G:G,8) -> 0 | P24: =COUNTIFS('Master Leads'!D:D,"Wihanga",'Master Leads'!G:G,9) -> 0 | S24: =COUNTIFS('Master Leads'!D:D,"Wihanga",'Master Leads'!G:G,10) -> 0 | V24: =COUNTIFS('Master Leads'!D:D,"Wihanga",'Master Leads'!G:G,11) -> 0 | Y24: =COUNTIF('Master Leads'!D:D,"Wihanga") -> 0
B25: muthumali | G25: =COUNTIFS('Master Leads'!D:D,"muthumali",'Master Leads'!G:G,6) -> 0 | J25: =COUNTIFS('Master Leads'!D:D,"muthumali",'Master Leads'!G:G,7) -> 0 | M25: =COUNTIFS('Master Leads'!D:D,"muthumali",'Master Leads'!G:G,8) -> 1 | P25: =COUNTIFS('Master Leads'!D:D,"muthumali",'Master Leads'!G:G,9) -> 0 | S25: =COUNTIFS('Master Leads'!D:D,"muthumali",'Master Leads'!G:G,10) -> 0 | V25: =COUNTIFS('Master Leads'!D:D,"muthumali",'Master Leads'!G:G,11) -> 0 | Y25: =COUNTIF('Master Leads'!D:D,"muthumali") -> 1
B26: shamali | G26: =COUNTIFS('Master Leads'!D:D,"shamali",'Master Leads'!G:G,6) -> 0 | J26: =COUNTIFS('Master Leads'!D:D,"shamali",'Master Leads'!G:G,7) -> 0 | M26: =COUNTIFS('Master Leads'!D:D,"shamali",'Master Leads'!G:G,8) -> 0 | P26: =COUNTIFS('Master Leads'!D:D,"shamali",'Master Leads'!G:G,9) -> 0 | S26: =COUNTIFS('Master Leads'!D:D,"shamali",'Master Leads'!G:G,10) -> 0 | V26: =COUNTIFS('Master Leads'!D:D,"shamali",'Master Leads'!G:G,11) -> 0 | Y26: =COUNTIF('Master Leads'!D:D,"shamali") -> 0
B29: MEMBER CHARTS — Visual performance comparison

Sheet Member Paid
B2: MEMBER PAID DASHBOARD | Paid Students by Member & Grade
B3: Drill down into which member generated paid students in each grade · Auto-updates
B5: PAID BY MEMBER × GRADE — Detailed grade-wise paid breakdown per member
B6: Member | G6: Grade 6 | J6: Grade 7 | M6: Grade 8 | P6: Grade 9 | S6: Grade 10 | V6: Grade 11 | Y6: Total Paid
B7: maheesha | G7: =COUNTIFS('Master Leads'!D:D,"maheesha",'Master Leads'!G:G,6,'Master Leads'!O:O,"Yes") -> 0 | J7: =COUNTIFS('Master Leads'!D:D,"maheesha",'Master Leads'!G:G,7,'Master Leads'!O:O,"Yes") -> 0 | M7: =COUNTIFS('Master Leads'!D:D,"maheesha",'Master Leads'!G:G,8,'Master Leads'!O:O,"Yes") -> 0 | P7: =COUNTIFS('Master Leads'!D:D,"maheesha",'Master Leads'!G:G,9,'Master Leads'!O:O,"Yes") -> 0 | S7: =COUNTIFS('Master Leads'!D:D,"maheesha",'Master Leads'!G:G,10,'Master Leads'!O:O,"Yes") -> 0 | V7: =COUNTIFS('Master Leads'!D:D,"maheesha",'Master Leads'!G:G,11,'Master Leads'!O:O,"Yes") -> 0 | Y7: =COUNTIFS('Master Leads'!D:D,"maheesha",'Master Leads'!O:O,"Yes") -> 0
B8: menik | G8: =COUNTIFS('Master Leads'!D:D,"menik",'Master Leads'!G:G,6,'Master Leads'!O:O,"Yes") -> 0 | J8: =COUNTIFS('Master Leads'!D:D,"menik",'Master Leads'!G:G,7,'Master Leads'!O:O,"Yes") -> 0 | M8: =COUNTIFS('Master Leads'!D:D,"menik",'Master Leads'!G:G,8,'Master Leads'!O:O,"Yes") -> 0 | P8: =COUNTIFS('Master Leads'!D:D,"menik",'Master Leads'!G:G,9,'Master Leads'!O:O,"Yes") -> 0 | S8: =COUNTIFS('Master Leads'!D:D,"menik",'Master Leads'!G:G,10,'Master Leads'!O:O,"Yes") -> 0 | V8: =COUNTIFS('Master Leads'!D:D,"menik",'Master Leads'!G:G,11,'Master Leads'!O:O,"Yes") -> 0 | Y8: =COUNTIFS('Master Leads'!D:D,"menik",'Master Leads'!O:O,"Yes") -> 0
B9: kavinda | G9: =COUNTIFS('Master Leads'!D:D,"kavinda",'Master Leads'!G:G,6,'Master Leads'!O:O,"Yes") -> 0 | J9: =COUNTIFS('Master Leads'!D:D,"kavinda",'Master Leads'!G:G,7,'Master Leads'!O:O,"Yes") -> 0 | M9: =COUNTIFS('Master Leads'!D:D,"kavinda",'Master Leads'!G:G,8,'Master Leads'!O:O,"Yes") -> 0 | P9: =COUNTIFS('Master Leads'!D:D,"kavinda",'Master Leads'!G:G,9,'Master Leads'!O:O,"Yes") -> 0 | S9: =COUNTIFS('Master Leads'!D:D,"kavinda",'Master Leads'!G:G,10,'Master Leads'!O:O,"Yes") -> 0 | V9: =COUNTIFS('Master Leads'!D:D,"kavinda",'Master Leads'!G:G,11,'Master Leads'!O:O,"Yes") -> 1 | Y9: =COUNTIFS('Master Leads'!D:D,"kavinda",'Master Leads'!O:O,"Yes") -> 1
B10: umesh | G10: =COUNTIFS('Master Leads'!D:D,"umesh",'Master Leads'!G:G,6,'Master Leads'!O:O,"Yes") -> 0 | J10: =COUNTIFS('Master Leads'!D:D,"umesh",'Master Leads'!G:G,7,'Master Leads'!O:O,"Yes") -> 0 | M10: =COUNTIFS('Master Leads'!D:D,"umesh",'Master Leads'!G:G,8,'Master Leads'!O:O,"Yes") -> 0 | P10: =COUNTIFS('Master Leads'!D:D,"umesh",'Master Leads'!G:G,9,'Master Leads'!O:O,"Yes") -> 0 | S10: =COUNTIFS('Master Leads'!D:D,"umesh",'Master Leads'!G:G,10,'Master Leads'!O:O,"Yes") -> 0 | V10: =COUNTIFS('Master Leads'!D:D,"umesh",'Master Leads'!G:G,11,'Master Leads'!O:O,"Yes") -> 0 | Y10: =COUNTIFS('Master Leads'!D:D,"umesh",'Master Leads'!O:O,"Yes") -> 0
B11: Avishka | G11: =COUNTIFS('Master Leads'!D:D,"Avishka",'Master Leads'!G:G,6,'Master Leads'!O:O,"Yes") -> 0 | J11: =COUNTIFS('Master Leads'!D:D,"Avishka",'Master Leads'!G:G,7,'Master Leads'!O:O,"Yes") -> 0 | M11: =COUNTIFS('Master Leads'!D:D,"Avishka",'Master Leads'!G:G,8,'Master Leads'!O:O,"Yes") -> 0 | P11: =COUNTIFS('Master Leads'!D:D,"Avishka",'Master Leads'!G:G,9,'Master Leads'!O:O,"Yes") -> 0 | S11: =COUNTIFS('Master Leads'!D:D,"Avishka",'Master Leads'!G:G,10,'Master Leads'!O:O,"Yes") -> 0 | V11: =COUNTIFS('Master Leads'!D:D,"Avishka",'Master Leads'!G:G,11,'Master Leads'!O:O,"Yes") -> 0 | Y11: =COUNTIFS('Master Leads'!D:D,"Avishka",'Master Leads'!O:O,"Yes") -> 0
B12: Wihanga | G12: =COUNTIFS('Master Leads'!D:D,"Wihanga",'Master Leads'!G:G,6,'Master Leads'!O:O,"Yes") -> 0 | J12: =COUNTIFS('Master Leads'!D:D,"Wihanga",'Master Leads'!G:G,7,'Master Leads'!O:O,"Yes") -> 0 | M12: =COUNTIFS('Master Leads'!D:D,"Wihanga",'Master Leads'!G:G,8,'Master Leads'!O:O,"Yes") -> 0 | P12: =COUNTIFS('Master Leads'!D:D,"Wihanga",'Master Leads'!G:G,9,'Master Leads'!O:O,"Yes") -> 0 | S12: =COUNTIFS('Master Leads'!D:D,"Wihanga",'Master Leads'!G:G,10,'Master Leads'!O:O,"Yes") -> 0 | V12: =COUNTIFS('Master Leads'!D:D,"Wihanga",'Master Leads'!G:G,11,'Master Leads'!O:O,"Yes") -> 0 | Y12: =COUNTIFS('Master Leads'!D:D,"Wihanga",'Master Leads'!O:O,"Yes") -> 0
B13: muthumali | G13: =COUNTIFS('Master Leads'!D:D,"muthumali",'Master Leads'!G:G,6,'Master Leads'!O:O,"Yes") -> 0 | J13: =COUNTIFS('Master Leads'!D:D,"muthumali",'Master Leads'!G:G,7,'Master Leads'!O:O,"Yes") -> 0 | M13: =COUNTIFS('Master Leads'!D:D,"muthumali",'Master Leads'!G:G,8,'Master Leads'!O:O,"Yes") -> 0 | P13: =COUNTIFS('Master Leads'!D:D,"muthumali",'Master Leads'!G:G,9,'Master Leads'!O:O,"Yes") -> 0 | S13: =COUNTIFS('Master Leads'!D:D,"muthumali",'Master Leads'!G:G,10,'Master Leads'!O:O,"Yes") -> 0 | V13: =COUNTIFS('Master Leads'!D:D,"muthumali",'Master Leads'!G:G,11,'Master Leads'!O:O,"Yes") -> 0 | Y13: =COUNTIFS('Master Leads'!D:D,"muthumali",'Master Leads'!O:O,"Yes") -> 0
B14: shamali | G14: =COUNTIFS('Master Leads'!D:D,"shamali",'Master Leads'!G:G,6,'Master Leads'!O:O,"Yes") -> 0 | J14: =COUNTIFS('Master Leads'!D:D,"shamali",'Master Leads'!G:G,7,'Master Leads'!O:O,"Yes") -> 0 | M14: =COUNTIFS('Master Leads'!D:D,"shamali",'Master Leads'!G:G,8,'Master Leads'!O:O,"Yes") -> 0 | P14: =COUNTIFS('Master Leads'!D:D,"shamali",'Master Leads'!G:G,9,'Master Leads'!O:O,"Yes") -> 0 | S14: =COUNTIFS('Master Leads'!D:D,"shamali",'Master Leads'!G:G,10,'Master Leads'!O:O,"Yes") -> 0 | V14: =COUNTIFS('Master Leads'!D:D,"shamali",'Master Leads'!G:G,11,'Master Leads'!O:O,"Yes") -> 0 | Y14: =COUNTIFS('Master Leads'!D:D,"shamali",'Master Leads'!O:O,"Yes") -> 0
B15: TOTAL | G15: =COUNTIFS('Master Leads'!G:G,6,'Master Leads'!O:O,"Yes") -> 0 | J15: =COUNTIFS('Master Leads'!G:G,7,'Master Leads'!O:O,"Yes") -> 1 | M15: =COUNTIFS('Master Leads'!G:G,8,'Master Leads'!O:O,"Yes") -> 0 | P15: =COUNTIFS('Master Leads'!G:G,9,'Master Leads'!O:O,"Yes") -> 0 | S15: =COUNTIFS('Master Leads'!G:G,10,'Master Leads'!O:O,"Yes") -> 0 | V15: =COUNTIFS('Master Leads'!G:G,11,'Master Leads'!O:O,"Yes") -> 1 | Y15: =COUNTIF('Master Leads'!O:O,"Yes") -> 2
B17: PAID CHARTS — Paid breakdown by member and grade

Sheet Daily Dashboard
B2: DAILY DASHBOARD | Today, Yesterday, Last 7 Days, This Week, This Month
B3: Quick snapshot of lead activity over different time periods · Auto-refreshes daily
B5: TIME-PERIOD LEAD COUNTS — Auto-refreshes on every open
B6: TODAY | G6: YESTERDAY | L6: LAST 7 DAYS | Q6: THIS WEEK | V6: THIS MONTH
B7: =COUNTIF('Master Leads'!E:E,TODAY()) -> 0 | G7: =COUNTIF('Master Leads'!E:E,TODAY()-1) -> 0 | L7: =COUNTIFS('Master Leads'!E:E,">="&TODAY()-6,'Master Leads'!E:E,"<="&TODAY()) -> 0 | Q7: =COUNTIFS('Master Leads'!E:E,">="&TODAY()-WEEKDAY(TODAY(),2)+1,'Master Leads'!E:E,"<="&TODAY()) -> 0 | V7: =COUNTIFS('Master Leads'!E:E,">="&DATE(YEAR(TODAY()),MONTH(TODAY()),1),'Master Leads'!E:E,"<="&TODAY()) -> 0
B8: Leads added today | G8: Leads added yesterday | L8: Leads in the last 7 days | Q8: Mon to today this week | V8: First of month to today
B10: LAST MONTH | G10: THIS WEEK PAID | L10: THIS MONTH PAID | Q10: TODAY CONVERTED | V10: TOTAL LEADS
B11: =COUNTIFS('Master Leads'!E:E,">="&DATE(YEAR(TODAY()),MONTH(TODAY())-1,1),'Master Leads'!E:E,"<="&EOMONTH(TODAY(),-1)) -> 0 | G11: =COUNTIFS('Master Leads'!E:E,">="&TODAY()-WEEKDAY(TODAY(),2)+1,'Master Leads'!E:E,"<="&TODAY(),'Master Leads'!O:O,"Yes") -> 0 | L11: =COUNTIFS('Master Leads'!E:E,">="&DATE(YEAR(TODAY()),MONTH(TODAY()),1),'Master Leads'!E:E,"<="&TODAY(),'Master Leads'!O:O,"Yes") -> 0 | Q11: =COUNTIFS('Master Leads'!E:E,TODAY(),'Master Leads'!F:F,"Converted") -> 0 | V11: =COUNTA('Master Leads'!B:B)-1 -> 10
B12: All of last month | G12: Paid this week | L12: Paid this month | Q12: Converted today | V12: All leads ever
B14: TREND CHARTS — Daily, Weekly, and Monthly patterns

Sheet Repeat Students
B2: REPEAT STUDENT DASHBOARD | Students who Enquired Multiple Times
B3: Track returning students across different campaigns · Uses col M (Repeat Student?)
B5: REPEAT STUDENT KPIs
B6: REPEAT STUDENTS | G6: NEW STUDENTS | L6: REPEAT RATE | Q6: REPEAT & PAID | V6: REPEAT & CONVERTED
B7: =COUNTIF('Master Leads'!M:M,"Yes*") -> 13 | G7: =COUNTIF('Master Leads'!M:M,"No") -> 8 | L7: =IFERROR(COUNTIF('Master Leads'!M:M,"Yes*")/(COUNTA('Master Leads'!B:B)-1),0) -> 1.3 | Q7: =COUNTIFS('Master Leads'!M:M,"Yes*",'Master Leads'!O:O,"Yes") -> 1 | V7: =COUNTIFS('Master Leads'!M:M,"Yes*",'Master Leads'!F:F,"Converted") -> 0
B8: Enquired before (col M = Yes) | G8: First-time enquiries | L8: Repeat / Total leads | Q8: Repeat students who also paid | V8: Repeat students converted
B10: REPEAT BY CAMPAIGN & MEMBER
B11: Campaign | F11: Total Leads | J11: Repeat | N11: Repeat %
B12: B1 | F12: =COUNTIF('Master Leads'!L:L,"B1") -> 4 | J12: =COUNTIFS('Master Leads'!L:L,"B1",'Master Leads'!M:M,"Yes*") -> 1 | N12: =IFERROR(COUNTIFS('Master Leads'!L:L,"B1",'Master Leads'!M:M,"Yes*")/COUNTIF('Master Leads'!L:L,"B1"),0) -> 0.25
B13: B2 | F13: =COUNTIF('Master Leads'!L:L,"B2") -> 1 | J13: =COUNTIFS('Master Leads'!L:L,"B2",'Master Leads'!M:M,"Yes*") -> 1 | N13: =IFERROR(COUNTIFS('Master Leads'!L:L,"B2",'Master Leads'!M:M,"Yes*")/COUNTIF('Master Leads'!L:L,"B2"),0) -> 1
B14: B3 | F14: =COUNTIF('Master Leads'!L:L,"B3") -> 0 | J14: =COUNTIFS('Master Leads'!L:L,"B3",'Master Leads'!M:M,"Yes*") -> 0 | N14: =IFERROR(COUNTIFS('Master Leads'!L:L,"B3",'Master Leads'!M:M,"Yes*")/COUNTIF('Master Leads'!L:L,"B3"),0) -> 0
B15: B4 | F15: =COUNTIF('Master Leads'!L:L,"B4") -> 0 | J15: =COUNTIFS('Master Leads'!L:L,"B4",'Master Leads'!M:M,"Yes*") -> 0 | N15: =IFERROR(COUNTIFS('Master Leads'!L:L,"B4",'Master Leads'!M:M,"Yes*")/COUNTIF('Master Leads'!L:L,"B4"),0) -> 0
B16: B5 | F16: =COUNTIF('Master Leads'!L:L,"B5") -> 0 | J16: =COUNTIFS('Master Leads'!L:L,"B5",'Master Leads'!M:M,"Yes*") -> 0 | N16: =IFERROR(COUNTIFS('Master Leads'!L:L,"B5",'Master Leads'!M:M,"Yes*")/COUNTIF('Master Leads'!L:L,"B5"),0) -> 0
B17: B6 | F17: =COUNTIF('Master Leads'!L:L,"B6") -> 0 | J17: =COUNTIFS('Master Leads'!L:L,"B6",'Master Leads'!M:M,"Yes*") -> 0 | N17: =IFERROR(COUNTIFS('Master Leads'!L:L,"B6",'Master Leads'!M:M,"Yes*")/COUNTIF('Master Leads'!L:L,"B6"),0) -> 0
B18: B7 | F18: =COUNTIF('Master Leads'!L:L,"B7") -> 0 | J18: =COUNTIFS('Master Leads'!L:L,"B7",'Master Leads'!M:M,"Yes*") -> 0 | N18: =IFERROR(COUNTIFS('Master Leads'!L:L,"B7",'Master Leads'!M:M,"Yes*")/COUNTIF('Master Leads'!L:L,"B7"),0) -> 0
B19: B8 | F19: =COUNTIF('Master Leads'!L:L,"B8") -> 0 | J19: =COUNTIFS('Master Leads'!L:L,"B8",'Master Leads'!M:M,"Yes*") -> 0 | N19: =IFERROR(COUNTIFS('Master Leads'!L:L,"B8",'Master Leads'!M:M,"Yes*")/COUNTIF('Master Leads'!L:L,"B8"),0) -> 0

Sheet Follow-up Dashboard
B2: FOLLOW-UP DASHBOARD | Second Calls, Pending Follow-ups & Rates
B3: Track which leads need a second call and who completed it · Based on col I (Second Call Done)
B5: FOLLOW-UP KPIs — Based on Second Call Done column (col I)
B6: SECOND CALL DONE | G6: SECOND CALL PENDING | L6: NOT SET | Q6: FOLLOW-UP RATE | V6: TOTAL LEADS
B7: =COUNTIF('Master Leads'!I:I,"Yes") -> 1 | G7: =COUNTIF('Master Leads'!I:I,"No") -> 3 | L7: =COUNTBLANK('Master Leads'!I2:I10000) -> 9995 | Q7: =IFERROR(COUNTIF('Master Leads'!I:I,"Yes")/(COUNTIF('Master Leads'!I:I,"Yes")+COUNTIF('Master Leads'!I:I,"No")),0) -> 0.25 | V7: =COUNTA('Master Leads'!B:B)-1 -> 10
B8: Completed second calls | G8: Need second call | L8: Second call not recorded | Q8: Done / (Done + Pending) | V8: All leads in system
AI9: 1
B10: 2ND CALL + CONVERTED | G10: 2ND CALL + PAID | L10: PENDING + INTERESTED | Q10: PENDING + NO ANSWER
B11: =COUNTIFS('Master Leads'!I:I,"Yes",'Master Leads'!F:F,"Converted") -> 0 | G11: =COUNTIFS('Master Leads'!I:I,"Yes",'Master Leads'!O:O,"Yes") -> 1 | L11: =COUNTIFS('Master Leads'!I:I,"No",'Master Leads'!F:F,"Interested") -> 0 | Q11: =COUNTIFS('Master Leads'!I:I,"No",'Master Leads'!F:F,"No Answer") -> 1
B12: Second call done & converted | G12: Second call done & paid | L12: Follow-up needed + interested | Q12: Pending call, no answer last time
B14: FOLLOW-UP BY MEMBER — Who has pending second calls?
B15: Member | G15: 2nd Done | K15: 2nd Pending | O15: Not Set | S15: Done %
B16: maheesha | G16: =COUNTIFS('Master Leads'!D:D,"maheesha",'Master Leads'!I:I,"Yes") -> 0 | K16: =COUNTIFS('Master Leads'!D:D,"maheesha",'Master Leads'!I:I,"No") -> 1 | O16: =COUNTIFS('Master Leads'!D:D,"maheesha",'Master Leads'!I:I,"") -> 0 | S16: =IFERROR(COUNTIFS('Master Leads'!D:D,"maheesha",'Master Leads'!I:I,"Yes")/(COUNTIFS('Master Leads'!D:D,"maheesha",'Master Leads'!I:I,"Yes")+COUNTIFS('Master Leads'!D:D,"maheesha",'Master Leads'!I:I,"No")),0) -> 0
B17: menik | G17: =COUNTIFS('Master Leads'!D:D,"menik",'Master Leads'!I:I,"Yes") -> 0 | K17: =COUNTIFS('Master Leads'!D:D,"menik",'Master Leads'!I:I,"No") -> 0 | O17: =COUNTIFS('Master Leads'!D:D,"menik",'Master Leads'!I:I,"") -> 0 | S17: =IFERROR(COUNTIFS('Master Leads'!D:D,"menik",'Master Leads'!I:I,"Yes")/(COUNTIFS('Master Leads'!D:D,"menik",'Master Leads'!I:I,"Yes")+COUNTIFS('Master Leads'!D:D,"menik",'Master Leads'!I:I,"No")),0) -> 0
B18: kavinda | G18: =COUNTIFS('Master Leads'!D:D,"kavinda",'Master Leads'!I:I,"Yes") -> 1 | K18: =COUNTIFS('Master Leads'!D:D,"kavinda",'Master Leads'!I:I,"No") -> 1 | O18: =COUNTIFS('Master Leads'!D:D,"kavinda",'Master Leads'!I:I,"") -> 0 | S18: =IFERROR(COUNTIFS('Master Leads'!D:D,"kavinda",'Master Leads'!I:I,"Yes")/(COUNTIFS('Master Leads'!D:D,"kavinda",'Master Leads'!I:I,"Yes")+COUNTIFS('Master Leads'!D:D,"kavinda",'Master Leads'!I:I,"No")),0) -> 0.5
B19: umesh | G19: =COUNTIFS('Master Leads'!D:D,"umesh",'Master Leads'!I:I,"Yes") -> 0 | K19: =COUNTIFS('Master Leads'!D:D,"umesh",'Master Leads'!I:I,"No") -> 1 | O19: =COUNTIFS('Master Leads'!D:D,"umesh",'Master Leads'!I:I,"") -> 3 | S19: =IFERROR(COUNTIFS('Master Leads'!D:D,"umesh",'Master Leads'!I:I,"Yes")/(COUNTIFS('Master Leads'!D:D,"umesh",'Master Leads'!I:I,"Yes")+COUNTIFS('Master Leads'!D:D,"umesh",'Master Leads'!I:I,"No")),0) -> 0
B20: Avishka | G20: =COUNTIFS('Master Leads'!D:D,"Avishka",'Master Leads'!I:I,"Yes") -> 0 | K20: =COUNTIFS('Master Leads'!D:D,"Avishka",'Master Leads'!I:I,"No") -> 0 | O20: =COUNTIFS('Master Leads'!D:D,"Avishka",'Master Leads'!I:I,"") -> 0 | S20: =IFERROR(COUNTIFS('Master Leads'!D:D,"Avishka",'Master Leads'!I:I,"Yes")/(COUNTIFS('Master Leads'!D:D,"Avishka",'Master Leads'!I:I,"Yes")+COUNTIFS('Master Leads'!D:D,"Avishka",'Master Leads'!I:I,"No")),0) -> 0
B21: Wihanga | G21: =COUNTIFS('Master Leads'!D:D,"Wihanga",'Master Leads'!I:I,"Yes") -> 0 | K21: =COUNTIFS('Master Leads'!D:D,"Wihanga",'Master Leads'!I:I,"No") -> 0 | O21: =COUNTIFS('Master Leads'!D:D,"Wihanga",'Master Leads'!I:I,"") -> 0 | S21: =IFERROR(COUNTIFS('Master Leads'!D:D,"Wihanga",'Master Leads'!I:I,"Yes")/(COUNTIFS('Master Leads'!D:D,"Wihanga",'Master Leads'!I:I,"Yes")+COUNTIFS('Master Leads'!D:D,"Wihanga",'Master Leads'!I:I,"No")),0) -> 0
B22: muthumali | G22: =COUNTIFS('Master Leads'!D:D,"muthumali",'Master Leads'!I:I,"Yes") -> 0 | K22: =COUNTIFS('Master Leads'!D:D,"muthumali",'Master Leads'!I:I,"No") -> 0 | O22: =COUNTIFS('Master Leads'!D:D,"muthumali",'Master Leads'!I:I,"") -> 1 | S22: =IFERROR(COUNTIFS('Master Leads'!D:D,"muthumali",'Master Leads'!I:I,"Yes")/(COUNTIFS('Master Leads'!D:D,"muthumali",'Master Leads'!I:I,"Yes")+COUNTIFS('Master Leads'!D:D,"muthumali",'Master Leads'!I:I,"No")),0) -> 0
B23: shamali | G23: =COUNTIFS('Master Leads'!D:D,"shamali",'Master Leads'!I:I,"Yes") -> 0 | K23: =COUNTIFS('Master Leads'!D:D,"shamali",'Master Leads'!I:I,"No") -> 0 | O23: =COUNTIFS('Master Leads'!D:D,"shamali",'Master Leads'!I:I,"") -> 0 | S23: =IFERROR(COUNTIFS('Master Leads'!D:D,"shamali",'Master Leads'!I:I,"Yes")/(COUNTIFS('Master Leads'!D:D,"shamali",'Master Leads'!I:I,"Yes")+COUNTIFS('Master Leads'!D:D,"shamali",'Master Leads'!I:I,"No")),0) -> 0

Sheet Instructions - READ FIRST
A1: HOW THIS SYSTEM WORKS (v8 - same layout as before, one bug fixed)
A3: This is the same Master Leads layout you already have live. Only the F-Code rule changed:
A5: F-CODE IS NOW UNIQUE PER PHONE NUMBER, PERMANENTLY
A6: Before: every new campaign entry generated a brand new F-code, even for a phone number already in the system.
A7: Now: 'Add New Lead' checks column A (Phone Normalized) for this number FIRST. If it's already there under any
A8: earlier row, it REUSES that same F-code. A new F-code is only generated the very first time a number is ever seen.
A10: So the same student messaging in through a different boost later keeps their original F-code, and gets a new
A11: row logging the new campaign/enquiry - not a new identity.
A13: DUPLICATE VS REPEAT (unchanged)
A14: Same phone + same campaign already logged = true duplicate, blocked, no new row.
A15: Same phone + a different/new campaign = new row added, F-code reused, marked 'Repeat Student'.
A17: SETUP STEPS
... A48: 0716030661

Sheet Members
A1: Member Name | B1: Total Leads (auto) | C1: Converted Leads (auto)
A2: maheesha | B2: =COUNTIF('Master Leads'!$D$2:$D$1000,A2) -> 1 | C2: =COUNTIFS('Master Leads'!$D$2:$D$1000,A2,'Master Leads'!$F$2:$F$1000,"Converted") -> 1
A3: menik | B3: =COUNTIF('Master Leads'!$D$2:$D$1000,A3) -> 0 | C3: =COUNTIFS('Master Leads'!$D$2:$D$1000,A3,'Master Leads'!$F$2:$F$1000,"Converted") -> 0
A4: kavinda | B4: =COUNTIF('Master Leads'!$D$2:$D$1000,A4) -> 2 | C4: =COUNTIFS('Master Leads'!$D$2:$D$1000,A4,'Master Leads'!$F$2:$F$1000,"Converted") -> 0
A5: umesh | B5: =COUNTIF('Master Leads'!$D$2:$D$1000,A5) -> 4 | C5: =COUNTIFS('Master Leads'!$D$2:$D$1000,A5,'Master Leads'!$F$2:$F$1000,"Converted") -> 1
A6: Avishka | B6: =COUNTIF('Master Leads'!$D$2:$D$1000,A6) -> 0 | C6: =COUNTIFS('Master Leads'!$D$2:$D$1000,A6,'Master Leads'!$F$2:$F$1000,"Converted") -> 0
A7: Wihanga | B7: =COUNTIF('Master Leads'!$D$2:$D$1000,A7) -> 0 | C7: =COUNTIFS('Master Leads'!$D$2:$D$1000,A7,'Master Leads'!$F$2:$F$1000,"Converted") -> 0
A8: muthumali | B8: =COUNTIF('Master Leads'!$D$2:$D$1000,A8) -> 1 | C8: =COUNTIFS('Master Leads'!$D$2:$D$1000,A8,'Master Leads'!$F$2:$F$1000,"Converted") -> 0
A9: shamali | B9: =COUNTIF('Master Leads'!$D$2:$D$1000,A9) -> 0 | C9: =COUNTIFS('Master Leads'!$D$2:$D$1000,A9,'Master Leads'!$F$2:$F$1000,"Converted") -> 0

Sheet Master Leads
A1: Phone (Normalized) | B1: Raw Phone (as entered) | C1: F-Code | D1: Assigned Member | E1: Date Added | F1: Status | G1: Grade | H1: Comments | I1: Second Call Done | J1: Second Call Notes | K1: Duplicate Check | L1: Campaign / Boost Name | M1: Repeat Student? | N1: Previous F-Code (if repeat) | O1: Paid | P1: Grade
A2: =IFERROR(__xludf.DUMMYFUNCTION("IF(B2="""","""",RIGHT(regexreplace(B2&"""",""[^0-9]"",""""),9))"),"778625101") -> 778625101 | B2: +94 77 862 5101 | C2: F00001 | D2: maheesha | E2: 2026-07-01 | F2: Converted | G2: 6 | I2: No | K2: =IF(COUNTIFS($A$2:A2,A2,$L$2:L2,L2)>1,"DUPLICATE - CHECK","") | L2: B1 | M2: =IF(COUNTIF($A1:A$2,A)>0,"Yes - see Previous F-Code","No") -> No | N2: {=IF(COUNTIF($A1:A$2,A)>0,INDEX($C1:C$2,MATCH(A2,$A1:A$2,0)),"")} | O2: No | P2: 7, 9
A3: =IFERROR(__xludf.DUMMYFUNCTION("IF(B3="""","""",RIGHT(regexreplace(B3&"""",""[^0-9]"",""""),9))"),"766820157") -> 766820157 | B3: 0766820157 | C3: F00002 | D3: umesh | E3: 2026-07-02 | F3: Not Interested | H3: off | I3: No | K3: =IF(COUNTIFS($A$2:A3,A3,$L$2:L3,L3)>1,"DUPLICATE - CHECK","") | L3: B1 | M3: =IF(COUNTIF($A2:A$2,A3)>0,"Yes - see Previous F-Code","No") -> No | N3: =IF(COUNTIF($A2:A$2,A3)>0,INDEX($C2:C$2,MATCH(A3,$A2:A$2,0)),"")
A4: =IFERROR(__xludf.DUMMYFUNCTION("IF(B4="""","""",RIGHT(regexreplace(B4&"""",""[^0-9]"",""""),9))"),"712197438") -> 712197438 | B4: +94 71 219 7438 | C4: F00003 | D4: kavinda | E4: 2026-07-03 | F4: Contacted | G4: 11 | I4: Yes | J4: details ewanna | K4: =IF(COUNTIFS($A$2:A4,A4,$L$2:L4,L4)>1,"DUPLICATE - CHECK","") | M4: =IF(COUNTIF($A$2:A3,A4)>0,"Yes - see Previous F-Code","No") -> No | N4: =IF(COUNTIF($A$2:A3,A4)>0,INDEX($C$2:C3,MATCH(A4,$A$2:A3,0)),"") | O4: Yes | P4: 11
A5: =IFERROR(__xludf.DUMMYFUNCTION("IF(B5="""","""",RIGHT(regexreplace(B5&"""",""[^0-9]"",""""),9))"),"716030661") -> 716030661 | B5: 716030661 | C5: F00004 | D5: umesh | E5: 46223.351 | F5: Contacted | G5: 8, 9 | H5: send details | K5: =IF(COUNTIFS($A$2:A5,A5,$L$2:L5,L5)>1,"DUPLICATE - CHECK","") | M5: =IF(COUNTIF($A$2:A4,A5)>0,"Yes - see Previous F-Code","No") -> No | N5: {=IF(COUNTIF($A$2:A4,A)>0,INDEX($C$2:C4,MATCH(A5,$A$2:A4,0)),"")} | P5: 9
A6: =IFERROR(__xludf.DUMMYFUNCTION("IF(B6="""","""",RIGHT(regexreplace(B6&"""",""[^0-9]"",""""),9))"),"781833131") -> 781833131 | B6: 781833131 | C6: F00005 | D6: umesh | E6: 46223.351 | F6: Converted | G6: 9 | K6: =IF(COUNTIFS($A$2:A6,A6,$L$2:L6,L6)>1,"DUPLICATE - CHECK","") | M6: =IF(COUNTIF($A$2:A5,A6)>0,"Yes - see Previous F-Code","No") -> No | N6: =IF(COUNTIF($A$2:A5,A6)>0,INDEX($C$2:C5,MATCH(A6,$A$2:A5,0)),"")
A7: =IFERROR(__xludf.DUMMYFUNCTION("IF(B7="""","""",RIGHT(regexreplace(B7&"""",""[^0-9]"",""""),9))"),"716030661") -> 716030661 | B7: 716030661 | C7: F00004 | E7: 46223.355 | F7: New | G7: 7 | K7: =IF(COUNTIFS($A$2:A7,A7,$L$2:L7,L7)>1,"DUPLICATE - CHECK","") | M7: =IF(COUNTIF($A$2:A6,A7)>0,"Yes - see Previous F-Code","No") -> Yes - see Previous F-Code | N7: =IF(COUNTIF($A$2:A6,A7)>0,INDEX($C$2:C6,MATCH(A7,$A$2:A6,0)),"") -> F00004 | O7: Yes | P7: 7
A8: =IFERROR(__xludf.DUMMYFUNCTION("IF(B8="""","""",RIGHT(regexreplace(B8&"""",""[^0-9]"",""""),9))"),"752945180") -> 752945180 | B8: 752945180 | C8: F00006 | D8: kavinda | E8: 46223.36 | F8: No Answer | I8: No | K8: =IF(COUNTIFS($A$2:A8,A8,$L$2:L8,L8)>1,"DUPLICATE - CHECK","") | L8: B1 | M8: =IF(COUNTIF($A$2:A7,A8)>0,"Yes - see Previous F-Code","No") -> No | N8: {=IF(COUNTIF($A$2:A7,A)>0,INDEX($C$2:C7,MATCH(A8,$A$2:A7,0)),"")}
A9: =IFERROR(__xludf.DUMMYFUNCTION("IF(B9="""","""",RIGHT(regexreplace(B9&"""",""[^0-9]"",""""),9))"),"752945180") -> 752945180 | B9: 94752945180 | C9: F00006 | D9: muthumali | E9: 46223.36 | F9: Contacted | G9: 8 | K9: =IF(COUNTIFS($A$2:A9,A9,$L$2:L9,L9)>1,"DUPLICATE - CHECK","") -> DUPLICATE - CHECK | L9: B1 | M9: =IF(COUNTIF($A$2:A8,A9)>0,"Yes - see Previous F-Code","No") -> Yes - see Previous F-Code | N9: =IF(COUNTIF($A$2:A8,A9)>0,INDEX($C$2:C8,MATCH(A9,$A$2:A8,0)),"") -> F00006
A10: =IFERROR(__xludf.DUMMYFUNCTION("IF(B10="""","""",RIGHT(regexreplace(B10&"""",""[^0-9]"",""""),9))"),"778625101") -> 778625101 | B10: 778625101 | C10: F00001 | D10: umesh | E10: 46223.361 | F10: Contacted | G10: 10 | K10: =IF(COUNTIFS($A$2:A10,A10,$L$2:L10,L10)>1,"DUPLICATE - CHECK","") | L10: B2 | M10: =IF(COUNTIF($A$2:A9,A10)>0,"Yes - see Previous F-Code","No") -> Yes - see Previous F-Code | N10: =IF(COUNTIF($A$2:A9,A10)>0,INDEX($C$2:C9,MATCH(A10,$A$2:A9,0)),"") -> F00001
A11: =IFERROR(__xludf.DUMMYFUNCTION("IF(B11="""","""",RIGHT(regexreplace(B11&"""",""[^0-9]"",""""),9))"),"789632546") -> 789632546 | B11: 789632546 | C11: F00007 | E11: 46223.364 | K11: =IF(COUNTIFS($A$2:A11,A11,$L$2:L11,L11)>1,"DUPLICATE - CHECK","") | M11: =IF(COUNTIF($A$2:A10,A11)>0,"Yes - see Previous F-Code","No") -> No | N11: {=IF(COUNTIF($A$2:A10,A)>0,INDEX($C$2:C10,MATCH(A11,$A$2:A10,0)),"")}
A12: =IFERROR(__xludf.DUMMYFUNCTION("IF(B12="""","""",RIGHT(regexreplace(B12&"""",""[^0-9]"",""""),9))"),"") | K12: =IF(COUNTIFS($A$2:A12,A12,$L$2:L12,L12)>1,"DUPLICATE - CHECK","") | M12: =IF(COUNTIF($A$2:A11,A12)>0,"Yes - see Previous F-Code","No") -> No | N12: =IF(COUNTIF($A$2:A11,A12)>0,INDEX($C$2:C11,MATCH(A12,$A$2:A11,0)),"")
A13: =IFERROR(__xludf.DUMMYFUNCTION("IF(B13="""","""",RIGHT(regexreplace(B13&"""",""[^0-9]"",""""),9))"),"") | K13: =IF(COUNTIFS($A$2:A13,A13,$L$2:L13,L13)>1,"DUPLICATE - CHECK","") | M13: =IF(COUNTIF($A$2:A12,A13)>0,"Yes - see Previous F-Code","No") -> Yes - see Previous F-Code | N13: =IF(COUNTIF($A$2:A12,A13)>0,INDEX($C$2:C12,MATCH(A13,$A$2:A12,0)),"") -> 0
A14: =IFERROR(__xludf.DUMMYFUNCTION("IF(B14="""","""",RIGHT(regexreplace(B14&"""",""[^0-9]"",""""),9))"),"") | K14: =IF(COUNTIFS($A$2:A14,A14,$L$2:L14,L14)>1,"DUPLICATE - CHECK","") | M14: =IF(COUNTIF($A$2:A13,A14)>0,"Yes - see Previous F-Code","No") -> Yes - see Previous F-Code | N14: {=IF(COUNTIF($A$2:A13,A)>0,INDEX($C$2:C13,MATCH(A14,$A$2:A13,0)),"")}
A15: =IFERROR(__xludf.DUMMYFUNCTION("IF(B15="""","""",RIGHT(regexreplace(B15&"""",""[^0-9]"",""""),9))"),"") | K15: =IF(COUNTIFS($A$2:A15,A15,$L$2:L15,L15)>1,"DUPLICATE - CHECK","") | M15: =IF(COUNTIF($A$2:A14,A15)>0,"Yes - see Previous F-Code","No") -> Yes - see Previous F-Code | N15: =IF(COUNTIF($A$2:A14,A15)>0,INDEX($C$2:C14,MATCH(A15,$A$2:A14,0)),"") -> 0
A16: =IFERROR(__xludf.DUMMYFUNCTION("IF(B16="""","""",RIGHT(regexreplace(B16&"""",""[^0-9]"",""""),9))"),"") | K16: =IF(COUNTIFS($A$2:A16,A16,$L$2:L16,L16)>1,"DUPLICATE - CHECK","") | M16: =IF(COUNTIF($A$2:A15,A16)>0,"Yes - see Previous F-Code","No") -> Yes - see Previous F-Code | N16: =IF(COUNTIF($A$2:A15,A16)>0,INDEX($C$2:C15,MATCH(A16,$A$2:A15,0)),"") -> 0
A17: =IFERROR(__xludf.DUMMYFUNCTION("IF(B17="""","""",RIGHT(regexreplace(B17&"""",""[^0-9]"",""""),9))"),"") | K17: =IF(COUNTIFS($A$2:A17,A17,$L$2:L17,L17)>1,"DUPLICATE - CHECK","") | M17: =IF(COUNTIF($A$2:A16,A17)>0,"Yes - see Previous F-Code","No") -> Yes - see Previous F-Code | N17: {=IF(COUNTIF($A$2:A16,A)>0,INDEX($C$2:C16,MATCH(A17,$A$2:A16,0)),"")}
A18: =IFERROR(__xludf.DUMMYFUNCTION("IF(B18="""","""",RIGHT(regexreplace(B18&"""",""[^0-9]"",""""),9))"),"") | K18: =IF(COUNTIFS($A$2:A18,A18,$L$2:L18,L18)>1,"DUPLICATE - CHECK","") | M18: =IF(COUNTIF($A$2:A17,A18)>0,"Yes - see Previous F-Code","No") -> Yes - see Previous F-Code | N18: =IF(COUNTIF($A$2:A17,A18)>0,INDEX($C$2:C17,MATCH(A18,$A$2:A17,0)),"") -> 0
A19: =IFERROR(__xludf.DUMMYFUNCTION("IF(B19="""","""",RIGHT(regexreplace(B19&"""",""[^0-9]"",""""),9))"),"") | K19: =IF(COUNTIFS($A$2:A19,A19,$L$2:L19,L19)>1,"DUPLICATE - CHECK","") | M19: =IF(COUNTIF($A$2:A18,A19)>0,"Yes - see Previous F-Code","No") -> Yes - see Previous F-Code | N19: =IF(COUNTIF($A$2:A18,A19)>0,INDEX($C$2:C18,MATCH(A19,$A$2:A18,0)),"") -> 0
A20: =IFERROR(__xludf.DUMMYFUNCTION("IF(B20="""","""",RIGHT(regexreplace(B20&"""",""[^0-9]"",""""),9))"),"") | K20: =IF(COUNTIFS($A$2:A20,A20,$L$2:L20,L20)>1,"DUPLICATE - CHECK","") | M20: =IF(COUNTIF($A$2:A19,A20)>0,"Yes - see Previous F-Code","No") -> Yes - see Previous F-Code | N20: {=IF(COUNTIF($A$2:A19,A)>0,INDEX($C$2:C19,MATCH(A20,$A$2:A19,0)),"")}
A21: =IFERROR(__xludf.DUMMYFUNCTION("IF(B21="""","""",RIGHT(regexreplace(B21&"""",""[^0-9]"",""""),9))"),"") | K21: =IF(COUNTIFS($A$2:A21,A21,$L$2:L21,L21)>1,"DUPLICATE - CHECK","") | M21: =IF(COUNTIF($A$2:A20,A21)>0,"Yes - see Previous F-Code","No") -> Yes - see Previous F-Code | N21: =IF(COUNTIF($A$2:A20,A21)>0,INDEX($C$2:C20,MATCH(A21,$A$2:A20,0)),"") -> 0
A22: =IFERROR(__xludf.DUMMYFUNCTION("IF(B22="""","""",RIGHT(regexreplace(B22&"""",""[^0-9]"",""""),9))"),"") | K22: =IF(COUNTIFS($A$2:A22,A22,$L$2:L22,L22)>1,"DUPLICATE - CHECK","") | M22: =IF(COUNTIF($A$2:A21,A22)>0,"Yes - see Previous F-Code","No") -> Yes - see Previous F-Code | N22: =IF(COUNTIF($A$2:A21,A22)>0,INDEX($C$2:C21,MATCH(A22,$A$2:A21,0)),"") -> 0
A23: =IFERROR(__xludf.DUMMYFUNCTION("IF(B23="""","""",RIGHT(regexreplace(B23&"""",""[^0-9]"",""""),9))"),"") | K23: =IF(COUNTIFS($A$2:A23,A23,$L$2:L23,L23)>1,"DUPLICATE - CHECK","") | N23: {=IF(COUNTIF($A$2:A22,A)>0,INDEX($C$2:C22,MATCH(A23,$A$2:A22,0)),"")}
A24: =IFERROR(__xludf.DUMMYFUNCTION("IF(B24="""","""",RIGHT(regexreplace(B24&"""",""[^0-9]"",""""),9))"),"") | K24: =IF(COUNTIFS($A$2:A24,A24,$L$2:L24,L24)>1,"DUPLICATE - CHECK","") | N24: =IF(COUNTIF($A$2:A23,A24)>0,INDEX($C$2:C23,MATCH(A24,$A$2:A23,0)),"") -> 0
A25: =IFERROR(__xludf.DUMMYFUNCTION("IF(B25="""","""",RIGHT(regexreplace(B25&"""",""[^0-9]"",""""),9))"),"") | K25: =IF(COUNTIFS($A$2:A25,A25,$L$2:L25,L25)>1,"DUPLICATE - CHECK","") | N25: =IF(COUNTIF($A$2:A24,A25)>0,INDEX($C$2:C24,MATCH(A25,$A$2:A24,0)),"") -> 0
A26: =IFERROR(__xludf.DUMMYFUNCTION("IF(B26="""","""",RIGHT(regexreplace(B26&"""",""[^0-9]"",""""),9))"),"") | K26: =IF(COUNTIFS($A$2:A26,A26,$L$2:L26,L26)>1,"DUPLICATE - CHECK","") | N26: {=IF(COUNTIF($A$2:A25,A)>0,INDEX($C$2:C25,MATCH(A26,$A$2:A25,0)),"")}
A27: =IFERROR(__xludf.DUMMYFUNCTION("IF(B27="""","""",RIGHT(regexreplace(B27&"""",""[^0-9]"",""""),9))"),"") | K27: =IF(COUNTIFS($A$2:A27,A27,$L$2:L27,L27)>1,"DUPLICATE - CHECK","") | N27: =IF(COUNTIF($A$2:A26,A27)>0,INDEX($C$2:C26,MATCH(A27,$A$2:A26,0)),"") -> 0
A28: =IFERROR(__xludf.DUMMYFUNCTION("IF(B28="""","""",RIGHT(regexreplace(B28&"""",""[^0-9]"",""""),9))"),"") | K28: =IF(COUNTIFS($A$2:A28,A28,$L$2:L28,L28)>1,"DUPLICATE - CHECK","") | N28: =IF(COUNTIF($A$2:A27,A28)>0,INDEX($C$2:C27,MATCH(A28,$A$2:A27,0)),"") -> 0
A29: =IFERROR(__xludf.DUMMYFUNCTION("IF(B29="""","""",RIGHT(regexreplace(B29&"""",""[^0-9]"",""""),9))"),"") | K29: =IF(COUNTIFS($A$2:A29,A29,$L$2:L29,L29)>1,"DUPLICATE - CHECK","") | N29: {=IF(COUNTIF($A$2:A28,A)>0,INDEX($C$2:C28,MATCH(A29,$A$2:A28,0)),"")}
A30: =IFERROR(__xludf.DUMMYFUNCTION("IF(B30="""","""",RIGHT(regexreplace(B30&"""",""[^0-9]"",""""),9))"),"") | K30: =IF(COUNTIFS($A$2:A30,A30,$L$2:L30,L30)>1,"DUPLICATE - CHECK","") | N30: =IF(COUNTIF($A$2:A29,A30)>0,INDEX($C$2:C29,MATCH(A30,$A$2:A29,0)),"") -> 0
A31: =IFERROR(__xludf.DUMMYFUNCTION("IF(B31="""","""",RIGHT(regexreplace(B31&"""",""[^0-9]"",""""),9))"),"") | K31: =IF(COUNTIFS($A$2:A31,A31,$L$2:L31,L31)>1,"DUPLICATE - CHECK","") | N31: =IF(COUNTIF($A$2:A30,A31)>0,INDEX($C$2:C30,MATCH(A31,$A$2:A30,0)),"") -> 0
A32: =IFERROR(__xludf.DUMMYFUNCTION("IF(B32="""","""",RIGHT(regexreplace(B32&"""",""[^0-9]"",""""),9))"),"") | K32: =IF(COUNTIFS($A$2:A32,A32,$L$2:L32,L32)>1,"DUPLICATE - CHECK","") | N32: {=IF(COUNTIF($A$2:A31,A)>0,INDEX($C$2:C31,MATCH(A32,$A$2:A31,0)),"")}
A33: =IFERROR(__xludf.DUMMYFUNCTION("IF(B33="""","""",RIGHT(regexreplace(B33&"""",""[^0-9]"",""""),9))"),"") | K33: =IF(COUNTIFS($A$2:A33,A33,$L$2:L33,L33)>1,"DUPLICATE - CHECK","") | N33: =IF(COUNTIF($A$2:A32,A33)>0,INDEX($C$2:C32,MATCH(A33,$A$2:A32,0)),"") -> 0
A34: =IFERROR(__xludf.DUMMYFUNCTION("IF(B34="""","""",RIGHT(regexreplace(B34&"""",""[^0-9]"",""""),9))"),"") | K34: =IF(COUNTIFS($A$2:A34,A34,$L$2:L34,L34)>1,"DUPLICATE - CHECK","") | N34: =IF(COUNTIF($A$2:A33,A34)>0,INDEX($C$2:C33,MATCH(A34,$A$2:A33,0)),"") -> 0
A35: =IFERROR(__xludf.DUMMYFUNCTION("IF(B35="""","""",RIGHT(regexreplace(B35&"""",""[^0-9]"",""""),9))"),"") | K35: =IF(COUNTIFS($A$2:A35,A35,$L$2:L35,L35)>1,"DUPLICATE - CHECK","") | N35: {=IF(COUNTIF($A$2:A34,A)>0,INDEX($C$2:C34,MATCH(A35,$A$2:A34,0)),"")}
A36: =IFERROR(__xludf.DUMMYFUNCTION("IF(B36="""","""",RIGHT(regexreplace(B36&"""",""[^0-9]"",""""),9))"),"") | K36: =IF(COUNTIFS($A$2:A36,A36,$L$2:L36,L36)>1,"DUPLICATE - CHECK","") | N36: =IF(COUNTIF($A$2:A35,A36)>0,INDEX($C$2:C35,MATCH(A36,$A$2:A35,0)),"") -> 0
A37: =IFERROR(__xludf.DUMMYFUNCTION("IF(B37="""","""",RIGHT(regexreplace(B37&"""",""[^0-9]"",""""),9))"),"") | K37: =IF(COUNTIFS($A$2:A37,A37,$L$2:L37,L37)>1,"DUPLICATE - CHECK","") | N37: =IF(COUNTIF($A$2:A36,A37)>0,INDEX($C$2:C36,MATCH(A37,$A$2:A36,0)),"") -> 0
A38: =IFERROR(__xludf.DUMMYFUNCTION("IF(B38="""","""",RIGHT(regexreplace(B38&"""",""[^0-9]"",""""),9))"),"") | K38: =IF(COUNTIFS($A$2:A38,A38,$L$2:L38,L38)>1,"DUPLICATE - CHECK","") | N38: {=IF(COUNTIF($A$2:A37,A)>0,INDEX($C$2:C37,MATCH(A38,$A$2:A37,0)),"")}
A39: =IFERROR(__xludf.DUMMYFUNCTION("IF(B39="""","""",RIGHT(regexreplace(B39&"""",""[^0-9]"",""""),9))"),"") | K39: =IF(COUNTIFS($A$2:A39,A39,$L$2:L39,L39)>1,"DUPLICATE - CHECK","") | N39: =IF(COUNTIF($A$2:A38,A39)>0,INDEX($C$2:C38,MATCH(A39,$A$2:A38,0)),"") -> 0
A40: =IFERROR(__xludf.DUMMYFUNCTION("IF(B40="""","""",RIGHT(regexreplace(B40&"""",""[^0-9]"",""""),9))"),"") | K40: =IF(COUNTIFS($A$2:A40,A40,$L$2:L40,L40)>1,"DUPLICATE - CHECK","") | N40: =IF(COUNTIF($A$2:A39,A40)>0,INDEX($C$2:C39,MATCH(A40,$A$2:A39,0)),"") -> 0
...

Sheet Leads Summary
A1: Member | B1: Total Leads Handled | C1: Converted Leads | D1: Conversion Rate
A2: =Members!A2 -> maheesha | B2: =COUNTIF('Master Leads'!$D$2:$D$1000,A2) -> 1 | C2: =COUNTIFS('Master Leads'!$D$2:$D$1000,A2,'Master Leads'!$F$2:$F$1000,"Converted") -> 1 | D2: =IF(B2=0,"-",C2/B2) -> 1
A3: =Members!A3 -> menik | B3: =COUNTIF('Master Leads'!$D$2:$D$1000,A3) -> 0 | C3: =COUNTIFS('Master Leads'!$D$2:$D$1000,A3,'Master Leads'!$F$2:$F$1000,"Converted") -> 0 | D3: =IF(B3=0,"-",C3/B3) -> -
A4: =Members!A4 -> kavinda | B4: =COUNTIF('Master Leads'!$D$2:$D$1000,A4) -> 2 | C4: =COUNTIFS('Master Leads'!$D$2:$D$1000,A4,'Master Leads'!$F$2:$F$1000,"Converted") -> 0 | D4: =IF(B4=0,"-",C4/B4) -> 0
A5: =Members!A5 -> umesh | B5: =COUNTIF('Master Leads'!$D$2:$D$1000,A5) -> 4 | C5: =COUNTIFS('Master Leads'!$D$2:$D$1000,A5,'Master Leads'!$F$2:$F$1000,"Converted") -> 1 | D5: =IF(B5=0,"-",C5/B5) -> 0.25
A6: =Members!A6 -> Avishka | B6: =COUNTIF('Master Leads'!$D$2:$D$1000,A6) -> 0 | C6: =COUNTIFS('Master Leads'!$D$2:$D$1000,A6,'Master Leads'!$F$2:$F$1000,"Converted") -> 0 | D6: =IF(B6=0,"-",C6/B6) -> -
A7: =Members!A7 -> Wihanga | B7: =COUNTIF('Master Leads'!$D$2:$D$1000,A7) -> 0 | C7: =COUNTIFS('Master Leads'!$D$2:$D$1000,A7,'Master Leads'!$F$2:$F$1000,"Converted") -> 0 | D7: =IF(B7=0,"-",C7/B7) -> -
A8: =Members!A8 -> muthumali | B8: =COUNTIF('Master Leads'!$D$2:$D$1000,A8) -> 1 | C8: =COUNTIFS('Master Leads'!$D$2:$D$1000,A8,'Master Leads'!$F$2:$F$1000,"Converted") -> 0 | D8: =IF(B8=0,"-",C8/B8) -> 0
A9: =Members!A9 -> shamali | B9: =COUNTIF('Master Leads'!$D$2:$D$1000,A9) -> 0 | C9: =COUNTIFS('Master Leads'!$D$2:$D$1000,A9,'Master Leads'!$F$2:$F$1000,"Converted") -> 0 | D9: =IF(B9=0,"-",C9/B9) -> -
A10: TOTAL | B10: =SUM(B2:B9) -> 8 | C10: =SUM(C2:C9) -> 2 | D10: =IF(B10=0,"-",C10/B10) -> 0.25

Sheet _DB1_Data
A1: Month | B1: Leads
A2: Jan | B2: =COUNTIFS('Master Leads'!E:E,">="&DATE(YEAR(TODAY()),1,1),'Master Leads'!E:E,"<="&EOMONTH(DATE(YEAR(TODAY()),1,1),0)) -> 0
A3: Feb | B3: =COUNTIFS('Master Leads'!E:E,">="&DATE(YEAR(TODAY()),2,1),'Master Leads'!E:E,"<="&EOMONTH(DATE(YEAR(TODAY()),2,1),0)) -> 0
A4: Mar | B4: =COUNTIFS('Master Leads'!E:E,">="&DATE(YEAR(TODAY()),3,1),'Master Leads'!E:E,"<="&EOMONTH(DATE(YEAR(TODAY()),3,1),0)) -> 0
A5: Apr | B5: =COUNTIFS('Master Leads'!E:E,">="&DATE(YEAR(TODAY()),4,1),'Master Leads'!E:E,"<="&EOMONTH(DATE(YEAR(TODAY()),4,1),0)) -> 0
A6: May | B6: =COUNTIFS('Master Leads'!E:E,">="&DATE(YEAR(TODAY()),5,1),'Master Leads'!E:E,"<="&EOMONTH(DATE(YEAR(TODAY()),5,1),0)) -> 0
A7: Jun | B7: =COUNTIFS('Master Leads'!E:E,">="&DATE(YEAR(TODAY()),6,1),'Master Leads'!E:E,"<="&EOMONTH(DATE(YEAR(TODAY()),6,1),0)) -> 0
A8: Jul | B8: =COUNTIFS('Master Leads'!E:E,">="&DATE(YEAR(TODAY()),7,1),'Master Leads'!E:E,"<="&EOMONTH(DATE(YEAR(TODAY()),7,1),0)) -> 7
A9: Aug | B9: =COUNTIFS('Master Leads'!E:E,">="&DATE(YEAR(TODAY()),8,1),'Master Leads'!E:E,"<="&EOMONTH(DATE(YEAR(TODAY()),8,1),0)) -> 0
A10: Sep | B10: =COUNTIFS('Master Leads'!E:E,">="&DATE(YEAR(TODAY()),9,1),'Master Leads'!E:E,"<="&EOMONTH(DATE(YEAR(TODAY()),9,1),0)) -> 0
A11: Oct | B11: =COUNTIFS('Master Leads'!E:E,">="&DATE(YEAR(TODAY()),10,1),'Master Leads'!E:E,"<="&EOMONTH(DATE(YEAR(TODAY()),10,1),0)) -> 0
A12: Nov | B12: =COUNTIFS('Master Leads'!E:E,">="&DATE(YEAR(TODAY()),11,1),'Master Leads'!E:E,"<="&EOMONTH(DATE(YEAR(TODAY()),11,1),0)) -> 0
A13: Dec | B13: =COUNTIFS('Master Leads'!E:E,">="&DATE(YEAR(TODAY()),12,1),'Master Leads'!E:E,"<="&EOMONTH(DATE(YEAR(TODAY()),12,1),0)) -> 0
A15: Status | B15: Count
A16: New | B16: =COUNTIF('Master Leads'!F:F,"New") -> 1
A17: Contacted | B17: =COUNTIF('Master Leads'!F:F,"Contacted") -> 4
A18: Converted | B18: =COUNTIF('Master Leads'!F:F,"Converted") -> 2
A19: Not Interested | B19: =COUNTIF('Master Leads'!F:F,"Not Interested") -> 1
A20: No Answer | B20: =COUNTIF('Master Leads'!F:F,"No Answer") -> 1
A21: Interested | B21: =COUNTIF('Master Leads'!F:F,"Interested") -> 0
A22: Follow-up | B22: =COUNTIF('Master Leads'!F:F,"Follow-up") -> 0
A23: Second Call Done | B23: =COUNTIF('Master Leads'!F:F,"Second Call Done") -> 0
A24: Not Picked Up | B24: =COUNTIF('Master Leads'!F:F,"Not Picked Up") -> 0
A26: Payment | B26: Count
A27: Paid | B27: =COUNTIF('Master Leads'!O:O,"Yes") -> 2
A28: Unpaid | B28: =MAX(0,COUNTA('Master Leads'!B:B)-1-COUNTIF('Master Leads'!O:O,"Yes")) -> 8
A30: Campaign | B30: Leads | C30: Paid
A31: B1 | B31: =COUNTIF('Master Leads'!L:L,"B1") -> 4 | C31: =COUNTIFS('Master Leads'!L:L,"B1",'Master Leads'!O:O,"Yes") -> 0
A32: B2 | B32: =COUNTIF('Master Leads'!L:L,"B2") -> 1 | C32: =COUNTIFS('Master Leads'!L:L,"B2",'Master Leads'!O:O,"Yes") -> 0
A33: B3 | B33: =COUNTIF('Master Leads'!L:L,"B3") -> 0 | C33: =COUNTIFS('Master Leads'!L:L,"B3",'Master Leads'!O:O,"Yes") -> 0
A34: B4 | B34: =COUNTIF('Master Leads'!L:L,"B4") -> 0 | C34: =COUNTIFS('Master Leads'!L:L,"B4",'Master Leads'!O:O,"Yes") -> 0
A35: B5 | B35: =COUNTIF('Master Leads'!L:L,"B5") -> 0 | C35: =COUNTIFS('Master Leads'!L:L,"B5",'Master Leads'!O:O,"Yes") -> 0
A36: B6 | B36: =COUNTIF('Master Leads'!L:L,"B6") -> 0 | C36: =COUNTIFS('Master Leads'!L:L,"B6",'Master Leads'!O:O,"Yes") -> 0
A37: B7 | B37: =COUNTIF('Master Leads'!L:L,"B7") -> 0 | C37: =COUNTIFS('Master Leads'!L:L,"B7",'Master Leads'!O:O,"Yes") -> 0
A38: B8 | B38: =COUNTIF('Master Leads'!L:L,"B8") -> 0 | C38: =COUNTIFS('Master Leads'!L:L,"B8",'Master Leads'!O:O,"Yes") -> 0
A39: B9 | B39: =COUNTIF('Master Leads'!L:L,"B9") -> 0 | C39: =COUNTIFS('Master Leads'!L:L,"B9",'Master Leads'!O:O,"Yes") -> 0
A40: B10 | B40: =COUNTIF('Master Leads'!L:L,"B10") -> 0 | C40: =COUNTIFS('Master Leads'!L:L,"B10",'Master Leads'!O:O,"Yes") -> 0
A42: Date | B42: Leads
A43: =TODAY()-6 -> 46217 | B43: =COUNTIF('Master Leads'!E:E,TODAY()-6) -> 0
A44: =TODAY()-5 -> 46218 | B44: =COUNTIF('Master Leads'!E:E,TODAY()-5) -> 0
...

Sheet _DB2_Data
A1: Grade | B1: Leads | C1: Paid
A2: Grade 6 | B2: =COUNTIF('Master Leads'!G:G,6) -> 1 | C2: =COUNTIFS('Master Leads'!G:G,6,'Master Leads'!O:O,"Yes") -> 0
A3: Grade 7 | B3: =COUNTIF('Master Leads'!G:G,7) -> 1 | C3: =COUNTIFS('Master Leads'!G:G,7,'Master Leads'!O:O,"Yes") -> 1
A4: Grade 8 | B4: =COUNTIF('Master Leads'!G:G,8) -> 1 | C4: =COUNTIFS('Master Leads'!G:G,8,'Master Leads'!O:O,"Yes") -> 0
A5: Grade 9 | B5: =COUNTIF('Master Leads'!G:G,9) -> 1 | C5: =COUNTIFS('Master Leads'!G:G,9,'Master Leads'!O:O,"Yes") -> 0
A6: Grade 10 | B6: =COUNTIF('Master Leads'!G:G,10) -> 1 | C6: =COUNTIFS('Master Leads'!G:G,10,'Master Leads'!O:O,"Yes") -> 0
A7: Grade 11 | B7: =COUNTIF('Master Leads'!G:G,11) -> 1 | C7: =COUNTIFS('Master Leads'!G:G,11,'Master Leads'!O:O,"Yes") -> 1
A10: Month | B10: Grade 6 | C10: Grade 7 | D10: Grade 8 | E10: Grade 9 | F10: Grade 10 | G10: Grade 11
A11: Jan | B11: =COUNTIFS('Master Leads'!G:G,6,'Master Leads'!E:E,">="&DATE(YEAR(TODAY()),1,1),'Master Leads'!E:E,"<="&EOMONTH(DATE(YEAR(TODAY()),1,1),0)) -> 0 | C11: =COUNTIFS('Master Leads'!G:G,7,'Master Leads'!E:E,">="&DATE(YEAR(TODAY()),1,1),'Master Leads'!E:E,"<="&EOMONTH(DATE(YEAR(TODAY()),1,1),0)) -> 0 | D11: =COUNTIFS('Master Leads'!G:G,8,'Master Leads'!E:E,">="&DATE(YEAR(TODAY()),1,1),'Master Leads'!E:E,"<="&EOMONTH(DATE(YEAR(TODAY()),1,1),0)) -> 0 | E11: =COUNTIFS('Master Leads'!G:G,9,'Master Leads'!E:E,">="&DATE(YEAR(TODAY()),1,1),'Master Leads'!E:E,"<="&EOMONTH(DATE(YEAR(TODAY()),1,1),0)) -> 0 | F11: =COUNTIFS('Master Leads'!G:G,10,'Master Leads'!E:E,">="&DATE(YEAR(TODAY()),1,1),'Master Leads'!E:E,"<="&EOMONTH(DATE(YEAR(TODAY()),1,1),0)) -> 0 | G11: =COUNTIFS('Master Leads'!G:G,11,'Master Leads'!E:E,">="&DATE(YEAR(TODAY()),1,1),'Master Leads'!E:E,"<="&EOMONTH(DATE(YEAR(TODAY()),1,1),0)) -> 0
A12: Feb | B12: =COUNTIFS('Master Leads'!G:G,6,'Master Leads'!E:E,">="&DATE(YEAR(TODAY()),2,1),'Master Leads'!E:E,"<="&EOMONTH(DATE(YEAR(TODAY()),2,1),0)) -> 0 | C12: =COUNTIFS('Master Leads'!G:G,7,'Master Leads'!E:E,">="&DATE(YEAR(TODAY()),2,1),'Master Leads'!E:E,"<="&EOMONTH(DATE(YEAR(TODAY()),2,1),0)) -> 0 | D12: =COUNTIFS('Master Leads'!G:G,8,'Master Leads'!E:E,">="&DATE(YEAR(TODAY()),2,1),'Master Leads'!E:E,"<="&EOMONTH(DATE(YEAR(TODAY()),2,1),0)) -> 0 | E12: =COUNTIFS('Master Leads'!G:G,9,'Master Leads'!E:E,">="&DATE(YEAR(TODAY()),2,1),'Master Leads'!E:E,"<="&EOMONTH(DATE(YEAR(TODAY()),2,1),0)) -> 0 | F12: =COUNTIFS('Master Leads'!G:G,10,'Master Leads'!E:E,">="&DATE(YEAR(TODAY()),2,1),'Master Leads'!E:E,"<="&EOMONTH(DATE(YEAR(TODAY()),2,1),0)) -> 0 | G12: =COUNTIFS('Master Leads'!G:G,11,'Master Leads'!E:E,">="&DATE(YEAR(TODAY()),2,1),'Master Leads'!E:E,"<="&EOMONTH(DATE(YEAR(TODAY()),2,1),0)) -> 0
