Workbook

Sheet Master Leads
B1: Raw Phone (as entered) | C1: F-Code | D1: Assigned Member | E1: Date Added | F1: Status | G1: Grade | H1: Comments | I1: Campaign / Boost Name | J1: Repeat Student? | K1: Duplicate Check | L1: Previous F-Code (if repeat) | M1: Second Call Done | N1: Second Call Notes | O1: Paid | P1: 0
A2: =IFERROR(__xludf.DUMMYFUNCTION("IF(B2="""","""",RIGHT(REGEXREPLACE(B2&"""",""[^0-9]"",""""),9))"),"714423443") -> 714423443 | B2: 714423443 | C2: F70000 | D2: umesh | E2: 46226 | F2: No Answer | I2: S26 | J2: No | K2: =IF(COUNTIFS($A$2:A2,A2,$I$2:I2,I2)>1,"DUPLICATE - CHECK","")
A3: =IFERROR(__xludf.DUMMYFUNCTION("IF(B3="""","""",RIGHT(REGEXREPLACE(B3&"""",""[^0-9]"",""""),9))"),"778959239") -> 778959239 | B3: 778959239 | C3: F70001 | D3: kavinda | E3: 46226 | F3: Contacted | G3: 11 | I3: S26 | J3: =IF(COUNTIF($A$2:A2,A3)>0,"Yes - see Previous F-Code","No") -> No | K3: =IF(COUNTIFS($A$2:A3,A3,$I$2:I3,I3)>1,"DUPLICATE - CHECK","") | L3: =IF(COUNTIF($A$2:A2,A3)>0,INDEX($C$2:C2,MATCH(A3,$A$2:A2,0)),"") | M3: No | N3: busy
A4: =IFERROR(__xludf.DUMMYFUNCTION("IF(B4="""","""",RIGHT(REGEXREPLACE(B4&"""",""[^0-9]"",""""),9))"),"769195778") -> 769195778 | B4: 769195778 | C4: F70002 | D4: muthumali | E4: 46226 | F4: Contacted | G4: 11 | I4: S26 | J4: =IF(COUNTIF($A$2:A3,A4)>0,"Yes - see Previous F-Code","No") -> No | K4: =IF(COUNTIFS($A$2:A4,A4,$I$2:I4,I4)>1,"DUPLICATE - CHECK","") | L4: =IF(COUNTIF($A$2:A3,A4)>0,INDEX($C$2:C3,MATCH(A4,$A$2:A3,0)),"") | M4: Yes | N4: class walata join una
A5: =IFERROR(__xludf.DUMMYFUNCTION("IF(B5="""","""",RIGHT(REGEXREPLACE(B5&"""",""[^0-9]"",""""),9))"),"765471585") -> 765471585 | B5: 765471585 | C5: F70003 | D5: kavinda | E5: 46226 | F5: No Answer | I5: S26 | J5: =IF(COUNTIF($A$2:A4,A5)>0,"Yes - see Previous F-Code","No") -> No | K5: =IF(COUNTIFS($A$2:A5,A5,$I$2:I5,I5)>1,"DUPLICATE - CHECK","") | L5: =IF(COUNTIF($A$2:A4,A5)>0,INDEX($C$2:C4,MATCH(A5,$A$2:A4,0)),"") | M5: No | N5: off
A6: =IFERROR(__xludf.DUMMYFUNCTION("IF(B6="""","""",RIGHT(REGEXREPLACE(B6&"""",""[^0-9]"",""""),9))"),"779810385") -> 779810385 | B6: 779810385 | C6: F70004 | D6: shamali | E6: 46226 | F6: Contacted | G6: 11 | I6: S26 | J6: =IF(COUNTIF($A$2:A5,A6)>0,"Yes - see Previous F-Code","No") -> No | K6: =IF(COUNTIFS($A$2:A6,A6,$I$2:I6,I6)>1,"DUPLICATE - CHECK","") | L6: =IF(COUNTIF($A$2:A5,A6)>0,INDEX($C$2:C5,MATCH(A6,$A$2:A5,0)),"") | M6: Yes | N6: blala kiynnm
A7: =IFERROR(__xludf.DUMMYFUNCTION("IF(B7="""","""",RIGHT(REGEXREPLACE(B7&"""",""[^0-9]"",""""),9))"),"741738779") -> 741738779 | B7: 741738779 | C7: F70005 | D7: muthumali | E7: 46226 | F7: Contacted | G7: 11 | I7: S26 | J7: =IF(COUNTIF($A$2:A6,A7)>0,"Yes - see Previous F-Code","No") -> No | K7: =IF(COUNTIFS($A$2:A7,A7,$I$2:I7,I7)>1,"DUPLICATE - CHECK","") | L7: =IF(COUNTIF($A$2:A6,A7)>0,INDEX($C$2:C6,MATCH(A7,$A$2:A6,0)),"") | M7: Yes | N7: join vela ne
A8: =IFERROR(__xludf.DUMMYFUNCTION("IF(B8="""","""",RIGHT(REGEXREPLACE(B8&"""",""[^0-9]"",""""),9))"),"762721575") -> 762721575 | B8: 762721575 | C8: F70006 | D8: shamali | E8: 46226 | F8: No Answer | I8: S26 | J8: =IF(COUNTIF($A$2:A7,A8)>0,"Yes - see Previous F-Code","No") -> No | K8: =IF(COUNTIFS($A$2:A8,A8,$I$2:I8,I8)>1,"DUPLICATE - CHECK","") | L8: =IF(COUNTIF($A$2:A7,A8)>0,INDEX($C$2:C7,MATCH(A8,$A$2:A7,0)),"") | M8: No | N8: no a
A9: =IFERROR(__xludf.DUMMYFUNCTION("IF(B9="""","""",RIGHT(REGEXREPLACE(B9&"""",""[^0-9]"",""""),9))"),"760581038") -> 760581038 | B9: 760581038 | C9: F70007 | D9: kavinda | E9: 46226 | F9: Contacted | I9: S26 | J9: =IF(COUNTIF($A$2:A8,A9)>0,"Yes - see Previous F-Code","No") -> No | K9: =IF(COUNTIFS($A$2:A9,A9,$I$2:I9,I9)>1,"DUPLICATE - CHECK","") | L9: =IF(COUNTIF($A$2:A8,A9)>0,INDEX($C$2:C8,MATCH(A9,$A$2:A8,0)),"") | M9: No | N9: no a
A10: =IFERROR(__xludf.DUMMYFUNCTION("IF(B10="""","""",RIGHT(REGEXREPLACE(B10&"""",""[^0-9]"",""""),9))"),"712370010") -> 712370010 | B10: 712370010 | C10: F70008 | D10: kushalya | E10: 46226 | F10: No Answer | I10: S26 | J10: =IF(COUNTIF($A$2:A9,A10)>0,"Yes - see Previous F-Code","No") -> No | K10: =IF(COUNTIFS($A$2:A10,A10,$I$2:I10,I10)>1,"DUPLICATE - CHECK","") | L10: =IF(COUNTIF($A$2:A9,A10)>0,INDEX($C$2:C9,MATCH(A10,$A$2:A9,0)),"") | M10: No | N10: no a
A11: =IFERROR(__xludf.DUMMYFUNCTION("IF(B11="""","""",RIGHT(REGEXREPLACE(B11&"""",""[^0-9]"",""""),9))"),"712694935") -> 712694935 | B11: 712694935 | C11: F70009 | D11: shamali | E11: 46226 | F11: Contacted | G11: 10 | I11: S26 | J11: =IF(COUNTIF($A$2:A10,A11)>0,"Yes - see Previous F-Code","No") -> No | K11: =IF(COUNTIFS($A$2:A11,A11,$I$2:I11,I11)>1,"DUPLICATE - CHECK","") | L11: =IF(COUNTIF($A$2:A10,A11)>0,INDEX($C$2:C10,MATCH(A11,$A$2:A10,0)),"") | M11: No | N11: no a
A12: =IFERROR(__xludf.DUMMYFUNCTION("IF(B12="""","""",RIGHT(REGEXREPLACE(B12&"""",""[^0-9]"",""""),9))"),"717444140") -> 717444140 | B12: 717444140 | C12: F70010 | D12: kavinda | E12: 46226 | F12: No Answer | I12: S26 | J12: =IF(COUNTIF($A$2:A11,A12)>0,"Yes - see Previous F-Code","No") -> No | K12: =IF(COUNTIFS($A$2:A12,A12,$I$2:I12,I12)>1,"DUPLICATE - CHECK","") | L12: =IF(COUNTIF($A$2:A11,A12)>0,INDEX($C$2:C11,MATCH(A12,$A$2:A11,0)),"") | M12: No | N12: off
A13: =IFERROR(__xludf.DUMMYFUNCTION("IF(B13="""","""",RIGHT(REGEXREPLACE(B13&"""",""[^0-9]"",""""),9))"),"768299308") -> 768299308 | B13: 768299308 | C13: F70010 | D13: kavinda | E13: 46226 | F13: No Answer | I13: S26 | J13: =IF(COUNTIF($A$2:A12,A13)>0,"Yes - see Previous F-Code","No") -> No | K13: =IF(COUNTIFS($A$2:A13,A13,$I$2:I13,I13)>1,"DUPLICATE - CHECK","") | L13: =IF(COUNTIF($A$2:A12,A13)>0,INDEX($C$2:C12,MATCH(A13,$A$2:A12,0)),"") | M13: No | N13: no a
A15: =IFERROR(__xludf.DUMMYFUNCTION("IF(B15="""","""",RIGHT(REGEXREPLACE(B15&"""",""[^0-9]"",""""),9))"),"711821851") -> 711821851 | B15: 711821851 | C15: F70012 | D15: muthumali | E15: 46226 | F15: No Answer | I15: S26 | J15: =IF(COUNTIF($A$2:A14,A15)>0,"Yes - see Previous F-Code","No") -> No | K15: =IF(COUNTIFS($A$2:A15,A15,$I$2:I15,I15)>1,"DUPLICATE - CHECK","") | L15: =IF(COUNTIF($A$2:A14,A15)>0,INDEX($C$2:C14,MATCH(A15,$A$2:A14,0)),"") | M15: Yes | N15: class ok
A16: =IFERROR(__xludf.DUMMYFUNCTION("IF(B16="""","""",RIGHT(REGEXREPLACE(B16&"""",""[^0-9]"",""""),9))"),"719322000") -> 719322000 | B16: 719322000 | C16: F70013 | D16: shamali | E16: 46226 | F16: No Answer | I16: S26 | J16: =IF(COUNTIF($A$2:A15,A16)>0,"Yes - see Previous F-Code","No") -> No | K16: =IF(COUNTIFS($A$2:A16,A16,$I$2:I16,I16)>1,"DUPLICATE - CHECK","") | L16: =IF(COUNTIF($A$2:A15,A16)>0,INDEX($C$2:C15,MATCH(A16,$A$2:A15,0)),"") | M16: No | N16: no a
A17: =IFERROR(__xludf.DUMMYFUNCTION("IF(B17="""","""",RIGHT(REGEXREPLACE(B17&"""",""[^0-9]"",""""),9))"),"777471118") -> 777471118 | B17: 777471118 | C17: F70014 | D17: muthumali | E17: 46226 | F17: No Answer | G17: 11 | J17: =IF(COUNTIF($A$2:A16,A17)>0,"Yes - see Previous F-Code","No") -> No | K17: =IF(COUNTIFS($A$2:A17,A17,$I$2:I17,I17)>1,"DUPLICATE - CHECK","") | L17: =IF(COUNTIF($A$2:A16,A17)>0,INDEX($C$2:C16,MATCH(A17,$A$2:A16,0)),"") | M17: No | N17: no a
A18: =IFERROR(__xludf.DUMMYFUNCTION("IF(B18="""","""",RIGHT(REGEXREPLACE(B18&"""",""[^0-9]"",""""),9))"),"705238969") -> 705238969 | B18: 705238969 | C18: F70015 | D18: muthumali | E18: 46226 | F18: Contacted | G18: 11 | J18: =IF(COUNTIF($A$2:A17,A18)>0,"Yes - see Previous F-Code","No") -> No | K18: =IF(COUNTIFS($A$2:A18,A18,$I$2:I18,I18)>1,"DUPLICATE - CHECK","") | L18: =IF(COUNTIF($A$2:A17,A18)>0,INDEX($C$2:C17,MATCH(A18,$A$2:A17,0)),"") | M18: Yes | N18: join vela ne
A19: =IFERROR(__xludf.DUMMYFUNCTION("IF(B19="""","""",RIGHT(REGEXREPLACE(B19&"""",""[^0-9]"",""""),9))"),"773981644") -> 773981644 | B19: 773981644 | C19: F70016 | D19: kavinda | E19: 46226 | F19: Contacted | G19: 11 | I19: S26 | J19: =IF(COUNTIF($A$2:A18,A19)>0,"Yes - see Previous F-Code","No") -> No | K19: =IF(COUNTIFS($A$2:A19,A19,$I$2:I19,I19)>1,"DUPLICATE - CHECK","") | L19: =IF(COUNTIF($A$2:A18,A19)>0,INDEX($C$2:C18,MATCH(A19,$A$2:A18,0)),"") | M19: Yes | N19: pay krl
A20: =IFERROR(__xludf.DUMMYFUNCTION("IF(B20="""","""",RIGHT(REGEXREPLACE(B20&"""",""[^0-9]"",""""),9))"),"716747001") -> 716747001 | B20: 716747001 | C20: F70017 | D20: shamali | E20: 46226 | I20: S26 | J20: =IF(COUNTIF($A$2:A19,A20)>0,"Yes - see Previous F-Code","No") -> No | K20: =IF(COUNTIFS($A$2:A20,A20,$I$2:I20,I20)>1,"DUPLICATE - CHECK","") | L20: =IF(COUNTIF($A$2:A19,A20)>0,INDEX($C$2:C19,MATCH(A20,$A$2:A19,0)),"") | M20: Yes | N20: passe gnnm
A21: =IFERROR(__xludf.DUMMYFUNCTION("IF(B21="""","""",RIGHT(REGEXREPLACE(B21&"""",""[^0-9]"",""""),9))"),"763945570") -> 763945570 | B21: 763945570 | C21: F70018 | D21: kavinda | E21: 46226 | F21: Contacted | G21: 11 | I21: S26 | J21: =IF(COUNTIF($A$2:A20,A21)>0,"Yes - see Previous F-Code","No") -> No | K21: =IF(COUNTIFS($A$2:A21,A21,$I$2:I21,I21)>1,"DUPLICATE - CHECK","") | L21: =IF(COUNTIF($A$2:A20,A21)>0,INDEX($C$2:C20,MATCH(A21,$A$2:A20,0)),"") | M21: Yes | N21: physical clss ambalanthota
A22: =IFERROR(__xludf.DUMMYFUNCTION("IF(B22="""","""",RIGHT(REGEXREPLACE(B22&"""",""[^0-9]"",""""),9))"),"703936681") -> 703936681 | B22: 703936681 | C22: F70019 | D22: muthumali | E22: 46226 | F22: Contacted | G22: 11 | J22: =IF(COUNTIF($A$2:A21,A22)>0,"Yes - see Previous F-Code","No") -> No | K22: =IF(COUNTIFS($A$2:A22,A22,$I$2:I22,I22)>1,"DUPLICATE - CHECK","") | L22: =IF(COUNTIF($A$2:A21,A22)>0,INDEX($C$2:C21,MATCH(A22,$A$2:A21,0)),"") | M22: Yes | N22: class ok
A23: =IFERROR(__xludf.DUMMYFUNCTION("IF(B23="""","""",RIGHT(REGEXREPLACE(B23&"""",""[^0-9]"",""""),9))"),"784501127") -> 784501127 | B23: 784501127 | C23: F70020 | D23: kavinda | E23: 46226 | F23: Not Interested | I23: S26 | J23: =IF(COUNTIF($A$2:A22,A23)>0,"Yes - see Previous F-Code","No") -> No | K23: =IF(COUNTIFS($A$2:A23,A23,$I$2:I23,I23)>1,"DUPLICATE - CHECK","") | L23: =IF(COUNTIF($A$2:A22,A23)>0,INDEX($C$2:C22,MATCH(A23,$A$2:A22,0)),"")
A24: =IFERROR(__xludf.DUMMYFUNCTION("IF(B24="""","""",RIGHT(REGEXREPLACE(B24&"""",""[^0-9]"",""""),9))"),"766323831") -> 766323831 | B24: 766323831 | C24: F70021 | D24: kavinda | E24: 46226 | F24: No Answer | G24: 10 | I24: S26 | J24: =IF(COUNTIF($A$2:A23,A24)>0,"Yes - see Previous F-Code","No") -> No | K24: =IF(COUNTIFS($A$2:A24,A24,$I$2:I24,I24)>1,"DUPLICATE - CHECK","") | L24: =IF(COUNTIF($A$2:A23,A24)>0,INDEX($C$2:C23,MATCH(A24,$A$2:A23,0)),"") | M24: No | N24: no a
A25: =IFERROR(__xludf.DUMMYFUNCTION("IF(B25="""","""",RIGHT(REGEXREPLACE(B25&"""",""[^0-9]"",""""),9))"),"703577703") -> 703577703 | B25: 703577703 | C25: F70024 | D25: muthumali | E25: 46226 | F25: No Answer | J25: =IF(COUNTIF($A$2:A24,A25)>0,"Yes - see Previous F-Code","No") -> No | K25: =IF(COUNTIFS($A$2:A25,A25,$I$2:I25,I25)>1,"DUPLICATE - CHECK","") | L25: =IF(COUNTIF($A$2:A24,A25)>0,INDEX($C$2:C24,MATCH(A25,$A$2:A24,0)),"") | M25: Yes | N25: class enne
A26: =IFERROR(__xludf.DUMMYFUNCTION("IF(B26="""","""",RIGHT(REGEXREPLACE(B26&"""",""[^0-9]"",""""),9))"),"727009037") -> 727009037 | B26: 727009037 | C26: F70022 | D26: shamali | E26: 46226 | F26: No Answer | I26: S26 | J26: =IF(COUNTIF($A$2:A25,A26)>0,"Yes - see Previous F-Code","No") -> No | K26: =IF(COUNTIFS($A$2:A26,A26,$I$2:I26,I26)>1,"DUPLICATE - CHECK","") | L26: =IF(COUNTIF($A$2:A25,A26)>0,INDEX($C$2:C25,MATCH(A26,$A$2:A25,0)),"") | M26: Yes | N26: m 1 dnnm
A27: =IFERROR(__xludf.DUMMYFUNCTION("IF(B27="""","""",RIGHT(REGEXREPLACE(B27&"""",""[^0-9]"",""""),9))"),"774435357") -> 774435357 | B27: 774435357 | C27: F70023 | D27: kavinda | E27: 46226 | F27: Contacted | G27: 11 | I27: S26 | J27: =IF(COUNTIF($A$2:A26,A27)>0,"Yes - see Previous F-Code","No") -> No | K27: =IF(COUNTIFS($A$2:A27,A27,$I$2:I27,I27)>1,"DUPLICATE - CHECK","") | L27: =IF(COUNTIF($A$2:A26,A27)>0,INDEX($C$2:C26,MATCH(A27,$A$2:A26,0)),"") | M27: No | N27: no a
A28: =IFERROR(__xludf.DUMMYFUNCTION("IF(B28="""","""",RIGHT(REGEXREPLACE(B28&"""",""[^0-9]"",""""),9))"),"718066694") -> 718066694 | B28: 718066694 | C28: F70026 | E28: 46226 | J28: =IF(COUNTIF($A$2:A27,A28)>0,"Yes - see Previous F-Code","No") -> No | K28: =IF(COUNTIFS($A$2:A28,A28,$I$2:I28,I28)>1,"DUPLICATE - CHECK","") | L28: =IF(COUNTIF($A$2:A27,A28)>0,INDEX($C$2:C27,MATCH(A28,$A$2:A27,0)),"")
A29: =IFERROR(__xludf.DUMMYFUNCTION("IF(B29="""","""",RIGHT(REGEXREPLACE(B29&"""",""[^0-9]"",""""),9))"),"710165336") -> 710165336 | B29: 710165336 | C29: F70025 | D29: muthumali | E29: 46226 | F29: No Answer | G29: 11 | J29: =IF(COUNTIF($A$2:A28,A29)>0,"Yes - see Previous F-Code","No") -> No | K29: =IF(COUNTIFS($A$2:A29,A29,$I$2:I29,I29)>1,"DUPLICATE - CHECK","") | L29: =IF(COUNTIF($A$2:A28,A29)>0,INDEX($C$2:C28,MATCH(A29,$A$2:A28,0)),"") | M29: Yes | N29: cut kara
A31: =IFERROR(__xludf.DUMMYFUNCTION("IF(B31="""","""",RIGHT(REGEXREPLACE(B31&"""",""[^0-9]"",""""),9))"),"769365683") -> 769365683 | B31: 769365683 | C31: F70027 | D31: muthumali | E31: 46226 | F31: Contacted | G31: 11 | J31: =IF(COUNTIF($A$2:A30,A31)>0,"Yes - see Previous F-Code","No") -> No | K31: =IF(COUNTIFS($A$2:A31,A31,$I$2:I31,I31)>1,"DUPLICATE - CHECK","") | L31: =IF(COUNTIF($A$2:A30,A31)>0,INDEX($C$2:C30,MATCH(A31,$A$2:A30,0)),"") | M31: Yes | N31: balala kiynnm
A32: =IFERROR(__xludf.DUMMYFUNCTION("IF(B32="""","""",RIGHT(REGEXREPLACE(B32&"""",""[^0-9]"",""""),9))"),"711993176") -> 711993176 | B32: 94711993176 | C32: F70028 | D32: Ama | E32: 46226 | F32: Contacted | G32: 9 | I32: S26 | J32: =IF(COUNTIF($A$2:A31,A32)>0,"Yes - see Previous F-Code","No") -> No | K32: =IF(COUNTIFS($A$2:A32,A32,$I$2:I32,I32)>1,"DUPLICATE - CHECK","") | L32: =IF(COUNTIF($A$2:A31,A32)>0,INDEX($C$2:C31,MATCH(A32,$A$2:A31,0)),"") | M32: Yes | N32: class enna bari una
A33: =IFERROR(__xludf.DUMMYFUNCTION("IF(B33="""","""",RIGHT(REGEXREPLACE(B33&"""",""[^0-9]"",""""),9))"),"") | K33: =IF(COUNTIFS($A$2:A33,A33,$I$2:I33,I33)>1,"DUPLICATE - CHECK","")
A34: =IFERROR(__xludf.DUMMYFUNCTION("IF(B34="""","""",RIGHT(REGEXREPLACE(B34&"""",""[^0-9]"",""""),9))"),"765254282") -> 765254282 | B34: 765254282 | C34: F70029 | D34: shamali | E34: 46226 | F34: Contacted | G34: 11,10 | I34: S26 | J34: =IF(COUNTIF($A$2:A33,A34)>0,"Yes - see Previous F-Code","No") -> No | K34: =IF(COUNTIFS($A$2:A34,A34,$I$2:I34,I34)>1,"DUPLICATE - CHECK","") | L34: {=IF(COUNTIF($A$2:A33,A34)>0,INDEX($C$2:C33,MATCH(A34,$A$2:A33,0)),"")} | M34: Yes | N34: m 1 dnnmm
A36: =IFERROR(__xludf.DUMMYFUNCTION("IF(B36="""","""",RIGHT(REGEXREPLACE(B36&"""",""[^0-9]"",""""),9))"),"701026904") -> 701026904 | B36: 701026904 | C36: F70030 | D36: kavinda | E36: 46226 | F36: No Answer | G36: 8 | I36: S26 | J36: =IF(COUNTIF($A$2:A35,A36)>0,"Yes - see Previous F-Code","No") -> No | K36: =IF(COUNTIFS($A$2:A36,A36,$I$2:I36,I36)>1,"DUPLICATE - CHECK","") | L36: =IF(COUNTIF($A$2:A35,A36)>0,INDEX($C$2:C35,MATCH(A36,$A$2:A35,0)),"") | M36: No | N36: no a
A37: =IFERROR(__xludf.DUMMYFUNCTION("IF(B37="""","""",RIGHT(REGEXREPLACE(B37&"""",""[^0-9]"",""""),9))"),"702580544") -> 702580544 | B37: 702580544 | C37: F70031 | D37: shamali | E37: 46226 | F37: Contacted | G37: 11 | I37: S26 | J37: =IF(COUNTIF($A$2:A36,A37)>0,"Yes - see Previous F-Code","No") -> No | K37: =IF(COUNTIFS($A$2:A37,A37,$I$2:I37,I37)>1,"DUPLICATE - CHECK","") | L37: =IF(COUNTIF($A$2:A36,A37)>0,INDEX($C$2:C36,MATCH(A37,$A$2:A36,0)),"") | M37: Yes | N37: enna blannm
A38: =IFERROR(__xludf.DUMMYFUNCTION("IF(B38="""","""",RIGHT(REGEXREPLACE(B38&"""",""[^0-9]"",""""),9))"),"772732100") -> 772732100 | B38: 772732100 | C38: F70032 | D38: shamali | E38: 46226 | F38: Not Interested | I38: S26 | J38: =IF(COUNTIF($A$2:A37,A38)>0,"Yes - see Previous F-Code","No") -> No | K38: =IF(COUNTIFS($A$2:A38,A38,$I$2:I38,I38)>1,"DUPLICATE - CHECK","") | L38: =IF(COUNTIF($A$2:A37,A38)>0,INDEX($C$2:C37,MATCH(A38,$A$2:A37,0)),"") | M38: No | N38: busy
A39: =IFERROR(__xludf.DUMMYFUNCTION("IF(B39="""","""",RIGHT(REGEXREPLACE(B39&"""",""[^0-9]"",""""),9))"),"777007650") -> 777007650 | B39: 777007650 | C39: F70033 | D39: Ama | E39: 46226 | F39: No Answer | I39: S26 | J39: =IF(COUNTIF($A$2:A38,A39)>0,"Yes - see Previous F-Code","No") -> No | K39: =IF(COUNTIFS($A$2:A39,A39,$I$2:I39,I39)>1,"DUPLICATE - CHECK","") | L39: =IF(COUNTIF($A$2:A38,A39)>0,INDEX($C$2:C38,MATCH(A39,$A$2:A38,0)),"") | M39: No | N39: busy
A40: =IFERROR(__xludf.DUMMYFUNCTION("IF(B40="""","""",RIGHT(REGEXREPLACE(B40&"""",""[^0-9]"",""""),9))"),"764519540") -> 764519540 | B40: 764519540 | C40: F70038 | D40: kavinda | E40: 46226 | F40: Contacted | G40: 11 | I40: S26 | J40: =IF(COUNTIF($A$2:A39,A40)>0,"Yes - see Previous F-Code","No") -> No | K40: =IF(COUNTIFS($A$2:A40,A40,$I$2:I40,I40)>1,"DUPLICATE - CHECK","") | L40: =IF(COUNTIF($A$2:A39,A40)>0,INDEX($C$2:C39,MATCH(A40,$A$2:A39,0)),"") | M40: No | N40: no a
A41: =IFERROR(__xludf.DUMMYFUNCTION("IF(B41="""","""",RIGHT(REGEXREPLACE(B41&"""",""[^0-9]"",""""),9))"),"779890412") -> 779890412 | B41: 779890412 | C41: F70034 | D41: muthumali | E41: 46226 | F41: No Answer | G41: 10 | I41: S26 | J41: =IF(COUNTIF($A$2:A40,A41)>0,"Yes - see Previous F-Code","No") -> No | K41: =IF(COUNTIFS($A$2:A41,A41,$I$2:I41,I41)>1,"DUPLICATE - CHECK","") | L41: =IF(COUNTIF($A$2:A40,A41)>0,INDEX($C$2:C40,MATCH(A41,$A$2:A40,0)),"") | M41: No | N41: no a
A42: =IFERROR(__xludf.DUMMYFUNCTION("IF(B42="""","""",RIGHT(REGEXREPLACE(B42&"""",""[^0-9]"",""""),9))"),"768369790") -> 768369790 | B42: 94768369790 | C42: F70035 | D42: umesh | E42: 46226 | F42: No Answer | I42: S26 | J42: =IF(COUNTIF($A$2:A41,A42)>0,"Yes - see Previous F-Code","No") -> No | K42: =IF(COUNTIFS($A$2:A42,A42,$I$2:I42,I42)>1,"DUPLICATE - CHECK","") | L42: =IF(COUNTIF($A$2:A41,A42)>0,INDEX($C$2:C41,MATCH(A42,$A$2:A41,0)),"")
A43: =IFERROR(__xludf.DUMMYFUNCTION("IF(B43="""","""",RIGHT(REGEXREPLACE(B43&"""",""[^0-9]"",""""),9))"),"767287836") -> 767287836 | B43: 767287836 | C43: F70036 | D43: muthumali | E43: 46226 | F43: Contacted | G43: 11 | I43: S26 | J43: =IF(COUNTIF($A$2:A42,A43)>0,"Yes - see Previous F-Code","No") -> No | K43: =IF(COUNTIFS($A$2:A43,A43,$I$2:I43,I43)>1,"DUPLICATE - CHECK","") | L43: =IF(COUNTIF($A$2:A42,A43)>0,INDEX($C$2:C42,MATCH(A43,$A$2:A42,0)),"") | M43: No | N43: off
...

Sheet Members
A1: Member Name | B1: Total Leads (auto) | C1: Converted Leads (auto) | D1: Paid (auto) | E1: No Answer (auto) | F1: Conversion Rate (auto) | G1: Paid Rate (auto) | H1: Date Joined | I1: Notes / Role
A2: maheesha | B2: =COUNTIF('Master Leads'!D:D,A2) -> 29 | C2: =COUNTIFS('Master Leads'!D:D,A2,'Master Leads'!F:F,"Converted") -> 0 | D2: =COUNTIFS('Master Leads'!D:D,A2,'Master Leads'!O:O,"Yes") -> 1 | E2: =COUNTIFS('Master Leads'!D:D,A2,'Master Leads'!F:F,"No Answer") -> 9 | F2: =IFERROR(C2/B2,"-") -> 0 | G2: =IFERROR(D2/B2,"-") -> 0.034482759
A3: menik | B3: =COUNTIF('Master Leads'!D:D,A3) -> 0 | C3: =COUNTIFS('Master Leads'!D:D,A3,'Master Leads'!F:F,"Converted") -> 0 | D3: =COUNTIFS('Master Leads'!D:D,A3,'Master Leads'!O:O,"Yes") -> 0 | E3: =COUNTIFS('Master Leads'!D:D,A3,'Master Leads'!F:F,"No Answer") -> 0 | F3: =IFERROR(C3/B3,"-") -> - | G3: =IFERROR(D3/B3,"-") -> -
A4: kavinda | B4: =COUNTIF('Master Leads'!D:D,A4) -> 1722 | C4: =COUNTIFS('Master Leads'!D:D,A4,'Master Leads'!F:F,"Converted") -> 12 | D4: =COUNTIFS('Master Leads'!D:D,A4,'Master Leads'!O:O,"Yes") -> 60 | E4: =COUNTIFS('Master Leads'!D:D,A4,'Master Leads'!F:F,"No Answer") -> 438 | F4: =IFERROR(C4/B4,"-") -> 0.0069686411 | G4: =IFERROR(D4/B4,"-") -> 0.034843206
A5: umesh | B5: =COUNTIF('Master Leads'!D:D,A5) -> 657 | C5: =COUNTIFS('Master Leads'!D:D,A5,'Master Leads'!F:F,"Converted") -> 11 | D5: 14 | E5: =COUNTIFS('Master Leads'!D:D,A5,'Master Leads'!F:F,"No Answer") -> 161 | F5: =IFERROR(C5/B5,"-") -> 0.01674277 | G5: =IFERROR(D5/B5,"-") -> 0.02130898
A6: Avishka | B6: =COUNTIF('Master Leads'!D:D,A6) -> 87 | C6: =COUNTIFS('Master Leads'!D:D,A6,'Master Leads'!F:F,"Converted") -> 0 | D6: =COUNTIFS('Master Leads'!D:D,A6,'Master Leads'!O:O,"Yes") -> 2 | E6: =COUNTIFS('Master Leads'!D:D,A6,'Master Leads'!F:F,"No Answer") -> 20 | F6: =IFERROR(C6/B6,"-") -> 0 | G6: =IFERROR(D6/B6,"-") -> 0.022988506
A7: Wihanga | B7: =COUNTIF('Master Leads'!D:D,A7) -> 0 | C7: =COUNTIFS('Master Leads'!D:D,A7,'Master Leads'!F:F,"Converted") -> 0 | D7: =COUNTIFS('Master Leads'!D:D,A7,'Master Leads'!O:O,"Yes") -> 0 | E7: =COUNTIFS('Master Leads'!D:D,A7,'Master Leads'!F:F,"No Answer") -> 0 | F7: =IFERROR(C7/B7,"-") -> - | G7: =IFERROR(D7/B7,"-") -> -
A8: muthumali | B8: =COUNTIF('Master Leads'!D:D,A8) -> 1539 | C8: =COUNTIFS('Master Leads'!D:D,A8,'Master Leads'!F:F,"Converted") -> 0 | D8: =COUNTIFS('Master Leads'!D:D,A8,'Master Leads'!O:O,"Yes") -> 52 | E8: =COUNTIFS('Master Leads'!D:D,A8,'Master Leads'!F:F,"No Answer") -> 333 | F8: =IFERROR(C8/B8,"-") -> 0 | G8: =IFERROR(D8/B8,"-") -> 0.033788174
A9: shamali | B9: =COUNTIF('Master Leads'!D:D,A9) -> 1899 | C9: =COUNTIFS('Master Leads'!D:D,A9,'Master Leads'!F:F,"Converted") -> 20 | D9: =COUNTIFS('Master Leads'!D:D,A9,'Master Leads'!O:O,"Yes") -> 63 | E9: =COUNTIFS('Master Leads'!D:D,A9,'Master Leads'!F:F,"No Answer") -> 447 | F9: =IFERROR(C9/B9,"-") -> 0.010531859 | G9: =IFERROR(D9/B9,"-") -> 0.033175355
A10: Ama | B10: =COUNTIF('Master Leads'!D:D,A10) -> 1568 | C10: =COUNTIFS('Master Leads'!D:D,A10,'Master Leads'!F:F,"Converted") -> 3 | D10: =COUNTIFS('Master Leads'!D:D,A10,'Master Leads'!O:O,"Yes") -> 56 | E10: =COUNTIFS('Master Leads'!D:D,A10,'Master Leads'!F:F,"No Answer") -> 413 | F10: =IFERROR(C10/B10,"-") -> 0.0019132653 | G10: =IFERROR(D10/B10,"-") -> 0.035714286
A11: kushalya | B11: =COUNTIF('Master Leads'!D:D,A11) -> 1736 | C11: =COUNTIFS('Master Leads'!D:D,A11,'Master Leads'!F:F,"Converted") -> 11 | D11: =COUNTIFS('Master Leads'!D:D,A11,'Master Leads'!O:O,"Yes") -> 66 | E11: =COUNTIFS('Master Leads'!D:D,A11,'Master Leads'!F:F,"No Answer") -> 403 | F11: =IFERROR(C11/B11,"-") -> 0.0063364055 | G11: =IFERROR(D11/B11,"-") -> 0.038018433
A12: TOTAL | B12: =COUNTA('Master Leads'!B:B)-1 -> 9236 | C12: =COUNTIF('Master Leads'!F:F,"Converted") -> 57 | D12: =COUNTIF('Master Leads'!O:O,"Yes") -> 314 | E12: =COUNTIF('Master Leads'!F:F,"No Answer") -> 2224

Sheet Leads Summary
A2: CRM LEADS & PERFORMANCE ANALYTICS
A3: Real-time team analytics, grade distribution, conversion metrics, unresolved pipelines, and campaign effectiveness.
A5: Filter Start Date: | C5: End Date: | E5: Leave dates blank to view All-Time data. Format: YYYY-MM-DD (e.g. 2026-07-01)
A7: TABLE 1: ALL LEADS BY MEMBER & GRADE
A8: Assigned Member | B8: Grade 6 | C8: Grade 7 | D8: Grade 8 | E8: Grade 9 | F8: Grade 10 | G8: Grade 11 | H8: Total Leads | I8: Share %
A9: {=IF(INDEX(Members!$A:$A,2)="","",INDEX(Members!$A:$A,2))} -> maheesha | B9: =IF($A9="","",SUMPRODUCT(('Master Leads'!$D:$D=$A9) * (ISNUMBER(SEARCH("6", 'Master Leads'!$G:$G))) * ('Master Leads'!$E:$E>=IF(ISBLANK($B$5),0,$B$5)) * ('Master Leads'!$E:$E<=IF(ISBLANK($D$5),99999,$D$5)))) -> 0 | C9: =IF($A9="","",SUMPRODUCT(('Master Leads'!$D:$D=$A9) * (ISNUMBER(SEARCH("7", 'Master Leads'!$G:$G))) * ('Master Leads'!$E:$E>=IF(ISBLANK($B$5),0,$B$5)) * ('Master Leads'!$E:$E<=IF(ISBLANK($D$5),99999,$D$5)))) -> 0 | D9: =IF($A9="","",SUMPRODUCT(('Master Leads'!$D:$D=$A9) * (ISNUMBER(SEARCH("8", 'Master Leads'!$G:$G))) * ('Master Leads'!$E:$E>=IF(ISBLANK($B$5),0,$B$5)) * ('Master Leads'!$E:$E<=IF(ISBLANK($D$5),99999,$D$5)))) -> 1 | E9: =IF($A9="","",SUMPRODUCT(('Master Leads'!$D:$D=$A9) * (ISNUMBER(SEARCH("9", 'Master Leads'!$G:$G))) * ('Master Leads'!$E:$E>=IF(ISBLANK($B$5),0,$B$5)) * ('Master Leads'!$E:$E<=IF(ISBLANK($D$5),99999,$D$5)))) -> 0 | F9: =IF($A9="","",SUMPRODUCT(('Master Leads'!$D:$D=$A9) * (ISNUMBER(SEARCH("10", 'Master Leads'!$G:$G))) * ('Master Leads'!$E:$E>=IF(ISBLANK($B$5),0,$B$5)) * ('Master Leads'!$E:$E<=IF(ISBLANK($D$5),99999,$D$5)))) -> 1 | G9: =IF($A9="","",SUMPRODUCT(('Master Leads'!$D:$D=$A9) * (ISNUMBER(SEARCH("11", 'Master Leads'!$G:$G))) * ('Master Leads'!$E:$E>=IF(ISBLANK($B$5),0,$B$5)) * ('Master Leads'!$E:$E<=IF(ISBLANK($D$5),99999,$D$5)))) -> 22 | H9: =IF($A9="","",COUNTIFS('Master Leads'!$D:$D,$A9,'Master Leads'!$E:$E,">="&IF(ISBLANK($B$5),0,$B$5),'Master Leads'!$E:$E,"<="&IF(ISBLANK($D$5),99999,$D$5))) -> 29 | I9: =IF(OR($A9="",$H$29=0),"",H9/$H$29) -> 0.0031392076
A10: {=IF(INDEX(Members!$A:$A,3)="","",INDEX(Members!$A:$A,3))} -> menik | B10: =IF($A10="","",SUMPRODUCT(('Master Leads'!$D:$D=$A10) * (ISNUMBER(SEARCH("6", 'Master Leads'!$G:$G))) * ('Master Leads'!$E:$E>=IF(ISBLANK($B$5),0,$B$5)) * ('Master Leads'!$E:$E<=IF(ISBLANK($D$5),99999,$D$5)))) -> 0 | C10: =IF($A10="","",SUMPRODUCT(('Master Leads'!$D:$D=$A10) * (ISNUMBER(SEARCH("7", 'Master Leads'!$G:$G))) * ('Master Leads'!$E:$E>=IF(ISBLANK($B$5),0,$B$5)) * ('Master Leads'!$E:$E<=IF(ISBLANK($D$5),99999,$D$5)))) -> 0 | D10: =IF($A10="","",SUMPRODUCT(('Master Leads'!$D:$D=$A10) * (ISNUMBER(SEARCH("8", 'Master Leads'!$G:$G))) * ('Master Leads'!$E:$E>=IF(ISBLANK($B$5),0,$B$5)) * ('Master Leads'!$E:$E<=IF(ISBLANK($D$5),99999,$D$5)))) -> 0 | E10: =IF($A10="","",SUMPRODUCT(('Master Leads'!$D:$D=$A10) * (ISNUMBER(SEARCH("9", 'Master Leads'!$G:$G))) * ('Master Leads'!$E:$E>=IF(ISBLANK($B$5),0,$B$5)) * ('Master Leads'!$E:$E<=IF(ISBLANK($D$5),99999,$D$5)))) -> 0 | F10: =IF($A10="","",SUMPRODUCT(('Master Leads'!$D:$D=$A10) * (ISNUMBER(SEARCH("10", 'Master Leads'!$G:$G))) * ('Master Leads'!$E:$E>=IF(ISBLANK($B$5),0,$B$5)) * ('Master Leads'!$E:$E<=IF(ISBLANK($D$5),99999,$D$5)))) -> 0 | G10: =IF($A10="","",SUMPRODUCT(('Master Leads'!$D:$D=$A10) * (ISNUMBER(SEARCH("11", 'Master Leads'!$G:$G))) * ('Master Leads'!$E:$E>=IF(ISBLANK($B$5),0,$B$5)) * ('Master Leads'!$E:$E<=IF(ISBLANK($D$5),99999,$D$5)))) -> 0 | H10: =IF($A10="","",COUNTIFS('Master Leads'!$D:$D,$A10,'Master Leads'!$E:$E,">="&IF(ISBLANK($B$5),0,$B$5),'Master Leads'!$E:$E,"<="&IF(ISBLANK($D$5),99999,$D$5))) -> 0 | I10: =IF(OR($A10="",$H$29=0),"",H10/$H$29) -> 0
A11: {=IF(INDEX(Members!$A:$A,4)="","",INDEX(Members!$A:$A,4))} -> kavinda | B11: =IF($A11="","",SUMPRODUCT(('Master Leads'!$D:$D=$A11) * (ISNUMBER(SEARCH("6", 'Master Leads'!$G:$G))) * ('Master Leads'!$E:$E>=IF(ISBLANK($B$5),0,$B$5)) * ('Master Leads'!$E:$E<=IF(ISBLANK($D$5),99999,$D$5)))) -> 45 | C11: =IF($A11="","",SUMPRODUCT(('Master Leads'!$D:$D=$A11) * (ISNUMBER(SEARCH("7", 'Master Leads'!$G:$G))) * ('Master Leads'!$E:$E>=IF(ISBLANK($B$5),0,$B$5)) * ('Master Leads'!$E:$E<=IF(ISBLANK($D$5),99999,$D$5)))) -> 62 | D11: =IF($A11="","",SUMPRODUCT(('Master Leads'!$D:$D=$A11) * (ISNUMBER(SEARCH("8", 'Master Leads'!$G:$G))) * ('Master Leads'!$E:$E>=IF(ISBLANK($B$5),0,$B$5)) * ('Master Leads'!$E:$E<=IF(ISBLANK($D$5),99999,$D$5)))) -> 55 | E11: =IF($A11="","",SUMPRODUCT(('Master Leads'!$D:$D=$A11) * (ISNUMBER(SEARCH("9", 'Master Leads'!$G:$G))) * ('Master Leads'!$E:$E>=IF(ISBLANK($B$5),0,$B$5)) * ('Master Leads'!$E:$E<=IF(ISBLANK($D$5),99999,$D$5)))) -> 292 | F11: =IF($A11="","",SUMPRODUCT(('Master Leads'!$D:$D=$A11) * (ISNUMBER(SEARCH("10", 'Master Leads'!$G:$G))) * ('Master Leads'!$E:$E>=IF(ISBLANK($B$5),0,$B$5)) * ('Master Leads'!$E:$E<=IF(ISBLANK($D$5),99999,$D$5)))) -> 241 | G11: =IF($A11="","",SUMPRODUCT(('Master Leads'!$D:$D=$A11) * (ISNUMBER(SEARCH("11", 'Master Leads'!$G:$G))) * ('Master Leads'!$E:$E>=IF(ISBLANK($B$5),0,$B$5)) * ('Master Leads'!$E:$E<=IF(ISBLANK($D$5),99999,$D$5)))) -> 516 | H11: =IF($A11="","",COUNTIFS('Master Leads'!$D:$D,$A11,'Master Leads'!$E:$E,">="&IF(ISBLANK($B$5),0,$B$5),'Master Leads'!$E:$E,"<="&IF(ISBLANK($D$5),99999,$D$5))) -> 1722 | I11: =IF(OR($A11="",$H$29=0),"",H11/$H$29) -> 0.18640398
A12: {=IF(INDEX(Members!$A:$A,5)="","",INDEX(Members!$A:$A,5))} -> umesh | B12: =IF($A12="","",SUMPRODUCT(('Master Leads'!$D:$D=$A12) * (ISNUMBER(SEARCH("6", 'Master Leads'!$G:$G))) * ('Master Leads'!$E:$E>=IF(ISBLANK($B$5),0,$B$5)) * ('Master Leads'!$E:$E<=IF(ISBLANK($D$5),99999,$D$5)))) -> 51 | C12: =IF($A12="","",SUMPRODUCT(('Master Leads'!$D:$D=$A12) * (ISNUMBER(SEARCH("7", 'Master Leads'!$G:$G))) * ('Master Leads'!$E:$E>=IF(ISBLANK($B$5),0,$B$5)) * ('Master Leads'!$E:$E<=IF(ISBLANK($D$5),99999,$D$5)))) -> 21 | D12: =IF($A12="","",SUMPRODUCT(('Master Leads'!$D:$D=$A12) * (ISNUMBER(SEARCH("8", 'Master Leads'!$G:$G))) * ('Master Leads'!$E:$E>=IF(ISBLANK($B$5),0,$B$5)) * ('Master Leads'!$E:$E<=IF(ISBLANK($D$5),99999,$D$5)))) -> 17 | E12: =IF($A12="","",SUMPRODUCT(('Master Leads'!$D:$D=$A12) * (ISNUMBER(SEARCH("9", 'Master Leads'!$G:$G))) * ('Master Leads'!$E:$E>=IF(ISBLANK($B$5),0,$B$5)) * ('Master Leads'!$E:$E<=IF(ISBLANK($D$5),99999,$D$5)))) -> 22 | F12: =IF($A12="","",SUMPRODUCT(('Master Leads'!$D:$D=$A12) * (ISNUMBER(SEARCH("10", 'Master Leads'!$G:$G))) * ('Master Leads'!$E:$E>=IF(ISBLANK($B$5),0,$B$5)) * ('Master Leads'!$E:$E<=IF(ISBLANK($D$5),99999,$D$5)))) -> 47 | G12: =IF($A12="","",SUMPRODUCT(('Master Leads'!$D:$D=$A12) * (ISNUMBER(SEARCH("11", 'Master Leads'!$G:$G))) * ('Master Leads'!$E:$E>=IF(ISBLANK($B$5),0,$B$5)) * ('Master Leads'!$E:$E<=IF(ISBLANK($D$5),99999,$D$5)))) -> 280 | H12: =IF($A12="","",COUNTIFS('Master Leads'!$D:$D,$A12,'Master Leads'!$E:$E,">="&IF(ISBLANK($B$5),0,$B$5),'Master Leads'!$E:$E,"<="&IF(ISBLANK($D$5),99999,$D$5))) -> 657 | I12: =IF(OR($A12="",$H$29=0),"",H12/$H$29) -> 0.07111929
A13: {=IF(INDEX(Members!$A:$A,6)="","",INDEX(Members!$A:$A,6))} -> Avishka | B13: =IF($A13="","",SUMPRODUCT(('Master Leads'!$D:$D=$A13) * (ISNUMBER(SEARCH("6", 'Master Leads'!$G:$G))) * ('Master Leads'!$E:$E>=IF(ISBLANK($B$5),0,$B$5)) * ('Master Leads'!$E:$E<=IF(ISBLANK($D$5),99999,$D$5)))) -> 1 | C13: =IF($A13="","",SUMPRODUCT(('Master Leads'!$D:$D=$A13) * (ISNUMBER(SEARCH("7", 'Master Leads'!$G:$G))) * ('Master Leads'!$E:$E>=IF(ISBLANK($B$5),0,$B$5)) * ('Master Leads'!$E:$E<=IF(ISBLANK($D$5),99999,$D$5)))) -> 0 | D13: =IF($A13="","",SUMPRODUCT(('Master Leads'!$D:$D=$A13) * (ISNUMBER(SEARCH("8", 'Master Leads'!$G:$G))) * ('Master Leads'!$E:$E>=IF(ISBLANK($B$5),0,$B$5)) * ('Master Leads'!$E:$E<=IF(ISBLANK($D$5),99999,$D$5)))) -> 3 | E13: =IF($A13="","",SUMPRODUCT(('Master Leads'!$D:$D=$A13) * (ISNUMBER(SEARCH("9", 'Master Leads'!$G:$G))) * ('Master Leads'!$E:$E>=IF(ISBLANK($B$5),0,$B$5)) * ('Master Leads'!$E:$E<=IF(ISBLANK($D$5),99999,$D$5)))) -> 1 | F13: =IF($A13="","",SUMPRODUCT(('Master Leads'!$D:$D=$A13) * (ISNUMBER(SEARCH("10", 'Master Leads'!$G:$G))) * ('Master Leads'!$E:$E>=IF(ISBLANK($B$5),0,$B$5)) * ('Master Leads'!$E:$E<=IF(ISBLANK($D$5),99999,$D$5)))) -> 5 | G13: =IF($A13="","",SUMPRODUCT(('Master Leads'!$D:$D=$A13) * (ISNUMBER(SEARCH("11", 'Master Leads'!$G:$G))) * ('Master Leads'!$E:$E>=IF(ISBLANK($B$5),0,$B$5)) * ('Master Leads'!$E:$E<=IF(ISBLANK($D$5),99999,$D$5)))) -> 43 | H13: =IF($A13="","",COUNTIFS('Master Leads'!$D:$D,$A13,'Master Leads'!$E:$E,">="&IF(ISBLANK($B$5),0,$B$5),'Master Leads'!$E:$E,"<="&IF(ISBLANK($D$5),99999,$D$5))) -> 87 | I13: =IF(OR($A13="",$H$29=0),"",H13/$H$29) -> 0.0094176229
A14: {=IF(INDEX(Members!$A:$A,7)="","",INDEX(Members!$A:$A,7))} -> Wihanga | B14: =IF($A14="","",SUMPRODUCT(('Master Leads'!$D:$D=$A14) * (ISNUMBER(SEARCH("6", 'Master Leads'!$G:$G))) * ('Master Leads'!$E:$E>=IF(ISBLANK($B$5),0,$B$5)) * ('Master Leads'!$E:$E<=IF(ISBLANK($D$5),99999,$D$5)))) -> 0 | C14: =IF($A14="","",SUMPRODUCT(('Master Leads'!$D:$D=$A14) * (ISNUMBER(SEARCH("7", 'Master Leads'!$G:$G))) * ('Master Leads'!$E:$E>=IF(ISBLANK($B$5),0,$B$5)) * ('Master Leads'!$E:$E<=IF(ISBLANK($D$5),99999,$D$5)))) -> 0 | D14: =IF($A14="","",SUMPRODUCT(('Master Leads'!$D:$D=$A14) * (ISNUMBER(SEARCH("8", 'Master Leads'!$G:$G))) * ('Master Leads'!$E:$E>=IF(ISBLANK($B$5),0,$B$5)) * ('Master Leads'!$E:$E<=IF(ISBLANK($D$5),99999,$D$5)))) -> 0 | E14: =IF($A14="","",SUMPRODUCT(('Master Leads'!$D:$D=$A14) * (ISNUMBER(SEARCH("9", 'Master Leads'!$G:$G))) * ('Master Leads'!$E:$E>=IF(ISBLANK($B$5),0,$B$5)) * ('Master Leads'!$E:$E<=IF(ISBLANK($D$5),99999,$D$5)))) -> 0 | F14: =IF($A14="","",SUMPRODUCT(('Master Leads'!$D:$D=$A14) * (ISNUMBER(SEARCH("10", 'Master Leads'!$G:$G))) * ('Master Leads'!$E:$E>=IF(ISBLANK($B$5),0,$B$5)) * ('Master Leads'!$E:$E<=IF(ISBLANK($D$5),99999,$D$5)))) -> 0 | G14: =IF($A14="","",SUMPRODUCT(('Master Leads'!$D:$D=$A14) * (ISNUMBER(SEARCH("11", 'Master Leads'!$G:$G))) * ('Master Leads'!$E:$E>=IF(ISBLANK($B$5),0,$B$5)) * ('Master Leads'!$E:$E<=IF(ISBLANK($D$5),99999,$D$5)))) -> 0 | H14: =IF($A14="","",COUNTIFS('Master Leads'!$D:$D,$A14,'Master Leads'!$E:$E,">="&IF(ISBLANK($B$5),0,$B$5),'Master Leads'!$E:$E,"<="&IF(ISBLANK($D$5),99999,$D$5))) -> 0 | I14: =IF(OR($A14="",$H$29=0),"",H14/$H$29) -> 0
A15: {=IF(INDEX(Members!$A:$A,8)="","",INDEX(Members!$A:$A,8))} -> muthumali | B15: =IF($A15="","",SUMPRODUCT(('Master Leads'!$D:$D=$A15) * (ISNUMBER(SEARCH("6", 'Master Leads'!$G:$G))) * ('Master Leads'!$E:$E>=IF(ISBLANK($B$5),0,$B$5)) * ('Master Leads'!$E:$E<=IF(ISBLANK($D$5),99999,$D$5)))) -> 34 | C15: =IF($A15="","",SUMPRODUCT(('Master Leads'!$D:$D=$A15) * (ISNUMBER(SEARCH("7", 'Master Leads'!$G:$G))) * ('Master Leads'!$E:$E>=IF(ISBLANK($B$5),0,$B$5)) * ('Master Leads'!$E:$E<=IF(ISBLANK($D$5),99999,$D$5)))) -> 64 | D15: =IF($A15="","",SUMPRODUCT(('Master Leads'!$D:$D=$A15) * (ISNUMBER(SEARCH("8", 'Master Leads'!$G:$G))) * ('Master Leads'!$E:$E>=IF(ISBLANK($B$5),0,$B$5)) * ('Master Leads'!$E:$E<=IF(ISBLANK($D$5),99999,$D$5)))) -> 56 | E15: =IF($A15="","",SUMPRODUCT(('Master Leads'!$D:$D=$A15) * (ISNUMBER(SEARCH("9", 'Master Leads'!$G:$G))) * ('Master Leads'!$E:$E>=IF(ISBLANK($B$5),0,$B$5)) * ('Master Leads'!$E:$E<=IF(ISBLANK($D$5),99999,$D$5)))) -> 261 | F15: =IF($A15="","",SUMPRODUCT(('Master Leads'!$D:$D=$A15) * (ISNUMBER(SEARCH("10", 'Master Leads'!$G:$G))) * ('Master Leads'!$E:$E>=IF(ISBLANK($B$5),0,$B$5)) * ('Master Leads'!$E:$E<=IF(ISBLANK($D$5),99999,$D$5)))) -> 219 | G15: =IF($A15="","",SUMPRODUCT(('Master Leads'!$D:$D=$A15) * (ISNUMBER(SEARCH("11", 'Master Leads'!$G:$G))) * ('Master Leads'!$E:$E>=IF(ISBLANK($B$5),0,$B$5)) * ('Master Leads'!$E:$E<=IF(ISBLANK($D$5),99999,$D$5)))) -> 625 | H15: =IF($A15="","",COUNTIFS('Master Leads'!$D:$D,$A15,'Master Leads'!$E:$E,">="&IF(ISBLANK($B$5),0,$B$5),'Master Leads'!$E:$E,"<="&IF(ISBLANK($D$5),99999,$D$5))) -> 1539 | I15: =IF(OR($A15="",$H$29=0),"",H15/$H$29) -> 0.1665945
A16: {=IF(INDEX(Members!$A:$A,9)="","",INDEX(Members!$A:$A,9))} -> shamali | B16: =IF($A16="","",SUMPRODUCT(('Master Leads'!$D:$D=$A16) * (ISNUMBER(SEARCH("6", 'Master Leads'!$G:$G))) * ('Master Leads'!$E:$E>=IF(ISBLANK($B$5),0,$B$5)) * ('Master Leads'!$E:$E<=IF(ISBLANK($D$5),99999,$D$5)))) -> 44 | C16: =IF($A16="","",SUMPRODUCT(('Master Leads'!$D:$D=$A16) * (ISNUMBER(SEARCH("7", 'Master Leads'!$G:$G))) * ('Master Leads'!$E:$E>=IF(ISBLANK($B$5),0,$B$5)) * ('Master Leads'!$E:$E<=IF(ISBLANK($D$5),99999,$D$5)))) -> 103 | D16: =IF($A16="","",SUMPRODUCT(('Master Leads'!$D:$D=$A16) * (ISNUMBER(SEARCH("8", 'Master Leads'!$G:$G))) * ('Master Leads'!$E:$E>=IF(ISBLANK($B$5),0,$B$5)) * ('Master Leads'!$E:$E<=IF(ISBLANK($D$5),99999,$D$5)))) -> 84 | E16: =IF($A16="","",SUMPRODUCT(('Master Leads'!$D:$D=$A16) * (ISNUMBER(SEARCH("9", 'Master Leads'!$G:$G))) * ('Master Leads'!$E:$E>=IF(ISBLANK($B$5),0,$B$5)) * ('Master Leads'!$E:$E<=IF(ISBLANK($D$5),99999,$D$5)))) -> 335 | F16: =IF($A16="","",SUMPRODUCT(('Master Leads'!$D:$D=$A16) * (ISNUMBER(SEARCH("10", 'Master Leads'!$G:$G))) * ('Master Leads'!$E:$E>=IF(ISBLANK($B$5),0,$B$5)) * ('Master Leads'!$E:$E<=IF(ISBLANK($D$5),99999,$D$5)))) -> 294 | G16: =IF($A16="","",SUMPRODUCT(('Master Leads'!$D:$D=$A16) * (ISNUMBER(SEARCH("11", 'Master Leads'!$G:$G))) * ('Master Leads'!$E:$E>=IF(ISBLANK($B$5),0,$B$5)) * ('Master Leads'!$E:$E<=IF(ISBLANK($D$5),99999,$D$5)))) -> 530 | H16: =IF($A16="","",COUNTIFS('Master Leads'!$D:$D,$A16,'Master Leads'!$E:$E,">="&IF(ISBLANK($B$5),0,$B$5),'Master Leads'!$E:$E,"<="&IF(ISBLANK($D$5),99999,$D$5))) -> 1899 | I16: =IF(OR($A16="",$H$29=0),"",H16/$H$29) -> 0.20556397
A17: {=IF(INDEX(Members!$A:$A,10)="","",INDEX(Members!$A:$A,10))} -> Ama | B17: =IF($A17="","",SUMPRODUCT(('Master Leads'!$D:$D=$A17) * (ISNUMBER(SEARCH("6", 'Master Leads'!$G:$G))) * ('Master Leads'!$E:$E>=IF(ISBLANK($B$5),0,$B$5)) * ('Master Leads'!$E:$E<=IF(ISBLANK($D$5),99999,$D$5)))) -> 30 | C17: =IF($A17="","",SUMPRODUCT(('Master Leads'!$D:$D=$A17) * (ISNUMBER(SEARCH("7", 'Master Leads'!$G:$G))) * ('Master Leads'!$E:$E>=IF(ISBLANK($B$5),0,$B$5)) * ('Master Leads'!$E:$E<=IF(ISBLANK($D$5),99999,$D$5)))) -> 79 | D17: =IF($A17="","",SUMPRODUCT(('Master Leads'!$D:$D=$A17) * (ISNUMBER(SEARCH("8", 'Master Leads'!$G:$G))) * ('Master Leads'!$E:$E>=IF(ISBLANK($B$5),0,$B$5)) * ('Master Leads'!$E:$E<=IF(ISBLANK($D$5),99999,$D$5)))) -> 57 | E17: =IF($A17="","",SUMPRODUCT(('Master Leads'!$D:$D=$A17) * (ISNUMBER(SEARCH("9", 'Master Leads'!$G:$G))) * ('Master Leads'!$E:$E>=IF(ISBLANK($B$5),0,$B$5)) * ('Master Leads'!$E:$E<=IF(ISBLANK($D$5),99999,$D$5)))) -> 233 | F17: =IF($A17="","",SUMPRODUCT(('Master Leads'!$D:$D=$A17) * (ISNUMBER(SEARCH("10", 'Master Leads'!$G:$G))) * ('Master Leads'!$E:$E>=IF(ISBLANK($B$5),0,$B$5)) * ('Master Leads'!$E:$E<=IF(ISBLANK($D$5),99999,$D$5)))) -> 184 | G17: =IF($A17="","",SUMPRODUCT(('Master Leads'!$D:$D=$A17) * (ISNUMBER(SEARCH("11", 'Master Leads'!$G:$G))) * ('Master Leads'!$E:$E>=IF(ISBLANK($B$5),0,$B$5)) * ('Master Leads'!$E:$E<=IF(ISBLANK($D$5),99999,$D$5)))) -> 415 | H17: =IF($A17="","",COUNTIFS('Master Leads'!$D:$D,$A17,'Master Leads'!$E:$E,">="&IF(ISBLANK($B$5),0,$B$5),'Master Leads'!$E:$E,"<="&IF(ISBLANK($D$5),99999,$D$5))) -> 1568 | I17: =IF(OR($A17="",$H$29=0),"",H17/$H$29) -> 0.16973371
A18: {=IF(INDEX(Members!$A:$A,11)="","",INDEX(Members!$A:$A,11))} -> kushalya | B18: =IF($A18="","",SUMPRODUCT(('Master Leads'!$D:$D=$A18) * (ISNUMBER(SEARCH("6", 'Master Leads'!$G:$G))) * ('Master Leads'!$E:$E>=IF(ISBLANK($B$5),0,$B$5)) * ('Master Leads'!$E:$E<=IF(ISBLANK($D$5),99999,$D$5)))) -> 38 | C18: =IF($A18="","",SUMPRODUCT(('Master Leads'!$D:$D=$A18) * (ISNUMBER(SEARCH("7", 'Master Leads'!$G:$G))) * ('Master Leads'!$E:$E>=IF(ISBLANK($B$5),0,$B$5)) * ('Master Leads'!$E:$E<=IF(ISBLANK($D$5),99999,$D$5)))) -> 80 | D18: =IF($A18="","",SUMPRODUCT(('Master Leads'!$D:$D=$A18) * (ISNUMBER(SEARCH("8", 'Master Leads'!$G:$G))) * ('Master Leads'!$E:$E>=IF(ISBLANK($B$5),0,$B$5)) * ('Master Leads'!$E:$E<=IF(ISBLANK($D$5),99999,$D$5)))) -> 90 | E18: =IF($A18="","",SUMPRODUCT(('Master Leads'!$D:$D=$A18) * (ISNUMBER(SEARCH("9", 'Master Leads'!$G:$G))) * ('Master Leads'!$E:$E>=IF(ISBLANK($B$5),0,$B$5)) * ('Master Leads'!$E:$E<=IF(ISBLANK($D$5),99999,$D$5)))) -> 254 | F18: =IF($A18="","",SUMPRODUCT(('Master Leads'!$D:$D=$A18) * (ISNUMBER(SEARCH("10", 'Master Leads'!$G:$G))) * ('Master Leads'!$E:$E>=IF(ISBLANK($B$5),0,$B$5)) * ('Master Leads'!$E:$E<=IF(ISBLANK($D$5),99999,$D$5)))) -> 240 | G18: =IF($A18="","",SUMPRODUCT(('Master Leads'!$D:$D=$A18) * (ISNUMBER(SEARCH("11", 'Master Leads'!$G:$G))) * ('Master Leads'!$E:$E>=IF(ISBLANK($B$5),0,$B$5)) * ('Master Leads'!$E:$E<=IF(ISBLANK($D$5),99999,$D$5)))) -> 422 | H18: =IF($A18="","",COUNTIFS('Master Leads'!$D:$D,$A18,'Master Leads'!$E:$E,">="&IF(ISBLANK($B$5),0,$B$5),'Master Leads'!$E:$E,"<="&IF(ISBLANK($D$5),99999,$D$5))) -> 1736 | I18: =IF(OR($A18="",$H$29=0),"",H18/$H$29) -> 0.18791946
A19: {=IF(INDEX(Members!$A:$A,12)="","",INDEX(Members!$A:$A,12))} -> TOTAL | B19: =IF($A19="","",SUMPRODUCT(('Master Leads'!$D:$D=$A19) * (ISNUMBER(SEARCH("6", 'Master Leads'!$G:$G))) * ('Master Leads'!$E:$E>=IF(ISBLANK($B$5),0,$B$5)) * ('Master Leads'!$E:$E<=IF(ISBLANK($D$5),99999,$D$5)))) -> 0 | C19: =IF($A19="","",SUMPRODUCT(('Master Leads'!$D:$D=$A19) * (ISNUMBER(SEARCH("7", 'Master Leads'!$G:$G))) * ('Master Leads'!$E:$E>=IF(ISBLANK($B$5),0,$B$5)) * ('Master Leads'!$E:$E<=IF(ISBLANK($D$5),99999,$D$5)))) -> 0 | D19: =IF($A19="","",SUMPRODUCT(('Master Leads'!$D:$D=$A19) * (ISNUMBER(SEARCH("8", 'Master Leads'!$G:$G))) * ('Master Leads'!$E:$E>=IF(ISBLANK($B$5),0,$B$5)) * ('Master Leads'!$E:$E<=IF(ISBLANK($D$5),99999,$D$5)))) -> 0 | E19: =IF($A19="","",SUMPRODUCT(('Master Leads'!$D:$D=$A19) * (ISNUMBER(SEARCH("9", 'Master Leads'!$G:$G))) * ('Master Leads'!$E:$E>=IF(ISBLANK($B$5),0,$B$5)) * ('Master Leads'!$E:$E<=IF(ISBLANK($D$5),99999,$D$5)))) -> 0 | F19: =IF($A19="","",SUMPRODUCT(('Master Leads'!$D:$D=$A19) * (ISNUMBER(SEARCH("10", 'Master Leads'!$G:$G))) * ('Master Leads'!$E:$E>=IF(ISBLANK($B$5),0,$B$5)) * ('Master Leads'!$E:$E<=IF(ISBLANK($D$5),99999,$D$5)))) -> 0 | G19: =IF($A19="","",SUMPRODUCT(('Master Leads'!$D:$D=$A19) * (ISNUMBER(SEARCH("11", 'Master Leads'!$G:$G))) * ('Master Leads'!$E:$E>=IF(ISBLANK($B$5),0,$B$5)) * ('Master Leads'!$E:$E<=IF(ISBLANK($D$5),99999,$D$5)))) -> 0 | H19: =IF($A19="","",COUNTIFS('Master Leads'!$D:$D,$A19,'Master Leads'!$E:$E,">="&IF(ISBLANK($B$5),0,$B$5),'Master Leads'!$E:$E,"<="&IF(ISBLANK($D$5),99999,$D$5))) -> 0 | I19: =IF(OR($A19="",$H$29=0),"",H19/$H$29) -> 0
A20: {=IF(INDEX(Members!$A:$A,13)="","",INDEX(Members!$A:$A,13))} | B20: =IF($A20="","",SUMPRODUCT(('Master Leads'!$D:$D=$A20) * (ISNUMBER(SEARCH("6", 'Master Leads'!$G:$G))) * ('Master Leads'!$E:$E>=IF(ISBLANK($B$5),0,$B$5)) * ('Master Leads'!$E:$E<=IF(ISBLANK($D$5),99999,$D$5)))) | C20: =IF($A20="","",SUMPRODUCT(('Master Leads'!$D:$D=$A20) * (ISNUMBER(SEARCH("7", 'Master Leads'!$G:$G))) * ('Master Leads'!$E:$E>=IF(ISBLANK($B$5),0,$B$5)) * ('Master Leads'!$E:$E<=IF(ISBLANK($D$5),99999,$D$5)))) | D20: =IF($A20="","",SUMPRODUCT(('Master Leads'!$D:$D=$A20) * (ISNUMBER(SEARCH("8", 'Master Leads'!$G:$G))) * ('Master Leads'!$E:$E>=IF(ISBLANK($B$5),0,$B$5)) * ('Master Leads'!$E:$E<=IF(ISBLANK($D$5),99999,$D$5)))) | E20: =IF($A20="","",SUMPRODUCT(('Master Leads'!$D:$D=$A20) * (ISNUMBER(SEARCH("9", 'Master Leads'!$G:$G))) * ('Master Leads'!$E:$E>=IF(ISBLANK($B$5),0,$B$5)) * ('Master Leads'!$E:$E<=IF(ISBLANK($D$5),99999,$D$5)))) | F20: =IF($A20="","",SUMPRODUCT(('Master Leads'!$D:$D=$A20) * (ISNUMBER(SEARCH("10", 'Master Leads'!$G:$G))) * ('Master Leads'!$E:$E>=IF(ISBLANK($B$5),0,$B$5)) * ('Master Leads'!$E:$E<=IF(ISBLANK($D$5),99999,$D$5)))) | G20: =IF($A20="","",SUMPRODUCT(('Master Leads'!$D:$D=$A20) * (ISNUMBER(SEARCH("11", 'Master Leads'!$G:$G))) * ('Master Leads'!$E:$E>=IF(ISBLANK($B$5),0,$B$5)) * ('Master Leads'!$E:$E<=IF(ISBLANK($D$5),99999,$D$5)))) | H20: =IF($A20="","",COUNTIFS('Master Leads'!$D:$D,$A20,'Master Leads'!$E:$E,">="&IF(ISBLANK($B$5),0,$B$5),'Master Leads'!$E:$E,"<="&IF(ISBLANK($D$5),99999,$D$5))) | I20: =IF(OR($A20="",$H$29=0),"",H20/$H$29)
A21: {=IF(INDEX(Members!$A:$A,14)="","",INDEX(Members!$A:$A,14))} | B21: =IF($A21="","",SUMPRODUCT(('Master Leads'!$D:$D=$A21) * (ISNUMBER(SEARCH("6", 'Master Leads'!$G:$G))) * ('Master Leads'!$E:$E>=IF(ISBLANK($B$5),0,$B$5)) * ('Master Leads'!$E:$E<=IF(ISBLANK($D$5),99999,$D$5)))) | C21: =IF($A21="","",SUMPRODUCT(('Master Leads'!$D:$D=$A21) * (ISNUMBER(SEARCH("7", 'Master Leads'!$G:$G))) * ('Master Leads'!$E:$E>=IF(ISBLANK($B$5),0,$B$5)) * ('Master Leads'!$E:$E<=IF(ISBLANK($D$5),99999,$D$5)))) | D21: =IF($A21="","",SUMPRODUCT(('Master Leads'!$D:$D=$A21) * (ISNUMBER(SEARCH("8", 'Master Leads'!$G:$G))) * ('Master Leads'!$E:$E>=IF(ISBLANK($B$5),0,$B$5)) * ('Master Leads'!$E:$E<=IF(ISBLANK($D$5),99999,$D$5)))) | E21: =IF($A21="","",SUMPRODUCT(('Master Leads'!$D:$D=$A21) * (ISNUMBER(SEARCH("9", 'Master Leads'!$G:$G))) * ('Master Leads'!$E:$E>=IF(ISBLANK($B$5),0,$B$5)) * ('Master Leads'!$E:$E<=IF(ISBLANK($D$5),99999,$D$5)))) | F21: =IF($A21="","",SUMPRODUCT(('Master Leads'!$D:$D=$A21) * (ISNUMBER(SEARCH("10", 'Master Leads'!$G:$G))) * ('Master Leads'!$E:$E>=IF(ISBLANK($B$5),0,$B$5)) * ('Master Leads'!$E:$E<=IF(ISBLANK($D$5),99999,$D$5)))) | G21: =IF($A21="","",SUMPRODUCT(('Master Leads'!$D:$D=$A21) * (ISNUMBER(SEARCH("11", 'Master Leads'!$G:$G))) * ('Master Leads'!$E:$E>=IF(ISBLANK($B$5),0,$B$5)) * ('Master Leads'!$E:$E<=IF(ISBLANK($D$5),99999,$D$5)))) | H21: =IF($A21="","",COUNTIFS('Master Leads'!$D:$D,$A21,'Master Leads'!$E:$E,">="&IF(ISBLANK($B$5),0,$B$5),'Master Leads'!$E:$E,"<="&IF(ISBLANK($D$5),99999,$D$5))) | I21: =IF(OR($A21="",$H$29=0),"",H21/$H$29)
A22: {=IF(INDEX(Members!$A:$A,15)="","",INDEX(Members!$A:$A,15))} | B22: =IF($A22="","",SUMPRODUCT(('Master Leads'!$D:$D=$A22) * (ISNUMBER(SEARCH("6", 'Master Leads'!$G:$G))) * ('Master Leads'!$E:$E>=IF(ISBLANK($B$5),0,$B$5)) * ('Master Leads'!$E:$E<=IF(ISBLANK($D$5),99999,$D$5)))) | C22: =IF($A22="","",SUMPRODUCT(('Master Leads'!$D:$D=$A22) * (ISNUMBER(SEARCH("7", 'Master Leads'!$G:$G))) * ('Master Leads'!$E:$E>=IF(ISBLANK($B$5),0,$B$5)) * ('Master Leads'!$E:$E<=IF(ISBLANK($D$5),99999,$D$5)))) | D22: =IF($A22="","",SUMPRODUCT(('Master Leads'!$D:$D=$A22) * (ISNUMBER(SEARCH("8", 'Master Leads'!$G:$G))) * ('Master Leads'!$E:$E>=IF(ISBLANK($B$5),0,$B$5)) * ('Master Leads'!$E:$E<=IF(ISBLANK($D$5),99999,$D$5)))) | E22: =IF($A22="","",SUMPRODUCT(('Master Leads'!$D:$D=$A22) * (ISNUMBER(SEARCH("9", 'Master Leads'!$G:$G))) * ('Master Leads'!$E:$E>=IF(ISBLANK($B$5),0,$B$5)) * ('Master Leads'!$E:$E<=IF(ISBLANK($D$5),99999,$D$5)))) | F22: =IF($A22="","",SUMPRODUCT(('Master Leads'!$D:$D=$A22) * (ISNUMBER(SEARCH("10", 'Master Leads'!$G:$G))) * ('Master Leads'!$E:$E>=IF(ISBLANK($B$5),0,$B$5)) * ('Master Leads'!$E:$E<=IF(ISBLANK($D$5),99999,$D$5)))) | G22: =IF($A22="","",SUMPRODUCT(('Master Leads'!$D:$D=$A22) * (ISNUMBER(SEARCH("11", 'Master Leads'!$G:$G))) * ('Master Leads'!$E:$E>=IF(ISBLANK($B$5),0,$B$5)) * ('Master Leads'!$E:$E<=IF(ISBLANK($D$5),99999,$D$5)))) | H22: =IF($A22="","",COUNTIFS('Master Leads'!$D:$D,$A22,'Master Leads'!$E:$E,">="&IF(ISBLANK($B$5),0,$B$5),'Master Leads'!$E:$E,"<="&IF(ISBLANK($D$5),99999,$D$5))) | I22: =IF(OR($A22="",$H$29=0),"",H22/$H$29)
A23: {=IF(INDEX(Members!$A:$A,16)="","",INDEX(Members!$A:$A,16))} | B23: =IF($A23="","",SUMPRODUCT(('Master Leads'!$D:$D=$A23) * (ISNUMBER(SEARCH("6", 'Master Leads'!$G:$G))) * ('Master Leads'!$E:$E>=IF(ISBLANK($B$5),0,$B$5)) * ('Master Leads'!$E:$E<=IF(ISBLANK($D$5),99999,$D$5)))) | C23: =IF($A23="","",SUMPRODUCT(('Master Leads'!$D:$D=$A23) * (ISNUMBER(SEARCH("7", 'Master Leads'!$G:$G))) * ('Master Leads'!$E:$E>=IF(ISBLANK($B$5),0,$B$5)) * ('Master Leads'!$E:$E<=IF(ISBLANK($D$5),99999,$D$5)))) | D23: =IF($A23="","",SUMPRODUCT(('Master Leads'!$D:$D=$A23) * (ISNUMBER(SEARCH("8", 'Master Leads'!$G:$G))) * ('Master Leads'!$E:$E>=IF(ISBLANK($B$5),0,$B$5)) * ('Master Leads'!$E:$E<=IF(ISBLANK($D$5),99999,$D$5)))) | E23: =IF($A23="","",SUMPRODUCT(('Master Leads'!$D:$D=$A23) * (ISNUMBER(SEARCH("9", 'Master Leads'!$G:$G))) * ('Master Leads'!$E:$E>=IF(ISBLANK($B$5),0,$B$5)) * ('Master Leads'!$E:$E<=IF(ISBLANK($D$5),99999,$D$5)))) | F23: =IF($A23="","",SUMPRODUCT(('Master Leads'!$D:$D=$A23) * (ISNUMBER(SEARCH("10", 'Master Leads'!$G:$G))) * ('Master Leads'!$E:$E>=IF(ISBLANK($B$5),0,$B$5)) * ('Master Leads'!$E:$E<=IF(ISBLANK($D$5),99999,$D$5)))) | G23: =IF($A23="","",SUMPRODUCT(('Master Leads'!$D:$D=$A23) * (ISNUMBER(SEARCH("11", 'Master Leads'!$G:$G))) * ('Master Leads'!$E:$E>=IF(ISBLANK($B$5),0,$B$5)) * ('Master Leads'!$E:$E<=IF(ISBLANK($D$5),99999,$D$5)))) | H23: =IF($A23="","",COUNTIFS('Master Leads'!$D:$D,$A23,'Master Leads'!$E:$E,">="&IF(ISBLANK($B$5),0,$B$5),'Master Leads'!$E:$E,"<="&IF(ISBLANK($D$5),99999,$D$5))) | I23: =IF(OR($A23="",$H$29=0),"",H23/$H$29)
A24: {=IF(INDEX(Members!$A:$A,17)="","",INDEX(Members!$A:$A,17))} | B24: =IF($A24="","",SUMPRODUCT(('Master Leads'!$D:$D=$A24) * (ISNUMBER(SEARCH("6", 'Master Leads'!$G:$G))) * ('Master Leads'!$E:$E>=IF(ISBLANK($B$5),0,$B$5)) * ('Master Leads'!$E:$E<=IF(ISBLANK($D$5),99999,$D$5)))) | C24: =IF($A24="","",SUMPRODUCT(('Master Leads'!$D:$D=$A24) * (ISNUMBER(SEARCH("7", 'Master Leads'!$G:$G))) * ('Master Leads'!$E:$E>=IF(ISBLANK($B$5),0,$B$5)) * ('Master Leads'!$E:$E<=IF(ISBLANK($D$5),99999,$D$5)))) | D24: =IF($A24="","",SUMPRODUCT(('Master Leads'!$D:$D=$A24) * (ISNUMBER(SEARCH("8", 'Master Leads'!$G:$G))) * ('Master Leads'!$E:$E>=IF(ISBLANK($B$5),0,$B$5)) * ('Master Leads'!$E:$E<=IF(ISBLANK($D$5),99999,$D$5)))) | E24: =IF($A24="","",SUMPRODUCT(('Master Leads'!$D:$D=$A24) * (ISNUMBER(SEARCH("9", 'Master Leads'!$G:$G))) * ('Master Leads'!$E:$E>=IF(ISBLANK($B$5),0,$B$5)) * ('Master Leads'!$E:$E<=IF(ISBLANK($D$5),99999,$D$5)))) | F24: =IF($A24="","",SUMPRODUCT(('Master Leads'!$D:$D=$A24) * (ISNUMBER(SEARCH("10", 'Master Leads'!$G:$G))) * ('Master Leads'!$E:$E>=IF(ISBLANK($B$5),0,$B$5)) * ('Master Leads'!$E:$E<=IF(ISBLANK($D$5),99999,$D$5)))) | G24: =IF($A24="","",SUMPRODUCT(('Master Leads'!$D:$D=$A24) * (ISNUMBER(SEARCH("11", 'Master Leads'!$G:$G))) * ('Master Leads'!$E:$E>=IF(ISBLANK($B$5),0,$B$5)) * ('Master Leads'!$E:$E<=IF(ISBLANK($D$5),99999,$D$5)))) | H24: =IF($A24="","",COUNTIFS('Master Leads'!$D:$D,$A24,'Master Leads'!$E:$E,">="&IF(ISBLANK($B$5),0,$B$5),'Master Leads'!$E:$E,"<="&IF(ISBLANK($D$5),99999,$D$5))) | I24: =IF(OR($A24="",$H$29=0),"",H24/$H$29)
A25: {=IF(INDEX(Members!$A:$A,18)="","",INDEX(Members!$A:$A,18))} | B25: =IF($A25="","",SUMPRODUCT(('Master Leads'!$D:$D=$A25) * (ISNUMBER(SEARCH("6", 'Master Leads'!$G:$G))) * ('Master Leads'!$E:$E>=IF(ISBLANK($B$5),0,$B$5)) * ('Master Leads'!$E:$E<=IF(ISBLANK($D$5),99999,$D$5)))) | C25: =IF($A25="","",SUMPRODUCT(('Master Leads'!$D:$D=$A25) * (ISNUMBER(SEARCH("7", 'Master Leads'!$G:$G))) * ('Master Leads'!$E:$E>=IF(ISBLANK($B$5),0,$B$5)) * ('Master Leads'!$E:$E<=IF(ISBLANK($D$5),99999,$D$5)))) | D25: =IF($A25="","",SUMPRODUCT(('Master Leads'!$D:$D=$A25) * (ISNUMBER(SEARCH("8", 'Master Leads'!$G:$G))) * ('Master Leads'!$E:$E>=IF(ISBLANK($B$5),0,$B$5)) * ('Master Leads'!$E:$E<=IF(ISBLANK($D$5),99999,$D$5)))) | E25: =IF($A25="","",SUMPRODUCT(('Master Leads'!$D:$D=$A25) * (ISNUMBER(SEARCH("9", 'Master Leads'!$G:$G))) * ('Master Leads'!$E:$E>=IF(ISBLANK($B$5),0,$B$5)) * ('Master Leads'!$E:$E<=IF(ISBLANK($D$5),99999,$D$5)))) | F25: =IF($A25="","",SUMPRODUCT(('Master Leads'!$D:$D=$A25) * (ISNUMBER(SEARCH("10", 'Master Leads'!$G:$G))) * ('Master Leads'!$E:$E>=IF(ISBLANK($B$5),0,$B$5)) * ('Master Leads'!$E:$E<=IF(ISBLANK($D$5),99999,$D$5)))) | G25: =IF($A25="","",SUMPRODUCT(('Master Leads'!$D:$D=$A25) * (ISNUMBER(SEARCH("11", 'Master Leads'!$G:$G))) * ('Master Leads'!$E:$E>=IF(ISBLANK($B$5),0,$B$5)) * ('Master Leads'!$E:$E<=IF(ISBLANK($D$5),99999,$D$5)))) | H25: =IF($A25="","",COUNTIFS('Master Leads'!$D:$D,$A25,'Master Leads'!$E:$E,">="&IF(ISBLANK($B$5),0,$B$5),'Master Leads'!$E:$E,"<="&IF(ISBLANK($D$5),99999,$D$5))) | I25: =IF(OR($A25="",$H$29=0),"",H25/$H$29)
A26: {=IF(INDEX(Members!$A:$A,19)="","",INDEX(Members!$A:$A,19))} | B26: =IF($A26="","",SUMPRODUCT(('Master Leads'!$D:$D=$A26) * (ISNUMBER(SEARCH("6", 'Master Leads'!$G:$G))) * ('Master Leads'!$E:$E>=IF(ISBLANK($B$5),0,$B$5)) * ('Master Leads'!$E:$E<=IF(ISBLANK($D$5),99999,$D$5)))) | C26: =IF($A26="","",SUMPRODUCT(('Master Leads'!$D:$D=$A26) * (ISNUMBER(SEARCH("7", 'Master Leads'!$G:$G))) * ('Master Leads'!$E:$E>=IF(ISBLANK($B$5),0,$B$5)) * ('Master Leads'!$E:$E<=IF(ISBLANK($D$5),99999,$D$5)))) | D26: =IF($A26="","",SUMPRODUCT(('Master Leads'!$D:$D=$A26) * (ISNUMBER(SEARCH("8", 'Master Leads'!$G:$G))) * ('Master Leads'!$E:$E>=IF(ISBLANK($B$5),0,$B$5)) * ('Master Leads'!$E:$E<=IF(ISBLANK($D$5),99999,$D$5)))) | E26: =IF($A26="","",SUMPRODUCT(('Master Leads'!$D:$D=$A26) * (ISNUMBER(SEARCH("9", 'Master Leads'!$G:$G))) * ('Master Leads'!$E:$E>=IF(ISBLANK($B$5),0,$B$5)) * ('Master Leads'!$E:$E<=IF(ISBLANK($D$5),99999,$D$5)))) | F26: =IF($A26="","",SUMPRODUCT(('Master Leads'!$D:$D=$A26) * (ISNUMBER(SEARCH("10", 'Master Leads'!$G:$G))) * ('Master Leads'!$E:$E>=IF(ISBLANK($B$5),0,$B$5)) * ('Master Leads'!$E:$E<=IF(ISBLANK($D$5),99999,$D$5)))) | G26: =IF($A26="","",SUMPRODUCT(('Master Leads'!$D:$D=$A26) * (ISNUMBER(SEARCH("11", 'Master Leads'!$G:$G))) * ('Master Leads'!$E:$E>=IF(ISBLANK($B$5),0,$B$5)) * ('Master Leads'!$E:$E<=IF(ISBLANK($D$5),99999,$D$5)))) | H26: =IF($A26="","",COUNTIFS('Master Leads'!$D:$D,$A26,'Master Leads'!$E:$E,">="&IF(ISBLANK($B$5),0,$B$5),'Master Leads'!$E:$E,"<="&IF(ISBLANK($D$5),99999,$D$5))) | I26: =IF(OR($A26="",$H$29=0),"",H26/$H$29)
A27: {=IF(INDEX(Members!$A:$A,20)="","",INDEX(Members!$A:$A,20))} | B27: =IF($A27="","",SUMPRODUCT(('Master Leads'!$D:$D=$A27) * (ISNUMBER(SEARCH("6", 'Master Leads'!$G:$G))) * ('Master Leads'!$E:$E>=IF(ISBLANK($B$5),0,$B$5)) * ('Master Leads'!$E:$E<=IF(ISBLANK($D$5),99999,$D$5)))) | C27: =IF($A27="","",SUMPRODUCT(('Master Leads'!$D:$D=$A27) * (ISNUMBER(SEARCH("7", 'Master Leads'!$G:$G))) * ('Master Leads'!$E:$E>=IF(ISBLANK($B$5),0,$B$5)) * ('Master Leads'!$E:$E<=IF(ISBLANK($D$5),99999,$D$5)))) | D27: =IF($A27="","",SUMPRODUCT(('Master Leads'!$D:$D=$A27) * (ISNUMBER(SEARCH("8", 'Master Leads'!$G:$G))) * ('Master Leads'!$E:$E>=IF(ISBLANK($B$5),0,$B$5)) * ('Master Leads'!$E:$E<=IF(ISBLANK($D$5),99999,$D$5)))) | E27: =IF($A27="","",SUMPRODUCT(('Master Leads'!$D:$D=$A27) * (ISNUMBER(SEARCH("9", 'Master Leads'!$G:$G))) * ('Master Leads'!$E:$E>=IF(ISBLANK($B$5),0,$B$5)) * ('Master Leads'!$E:$E<=IF(ISBLANK($D$5),99999,$D$5)))) | F27: =IF($A27="","",SUMPRODUCT(('Master Leads'!$D:$D=$A27) * (ISNUMBER(SEARCH("10", 'Master Leads'!$G:$G))) * ('Master Leads'!$E:$E>=IF(ISBLANK($B$5),0,$B$5)) * ('Master Leads'!$E:$E<=IF(ISBLANK($D$5),99999,$D$5)))) | G27: =IF($A27="","",SUMPRODUCT(('Master Leads'!$D:$D=$A27) * (ISNUMBER(SEARCH("11", 'Master Leads'!$G:$G))) * ('Master Leads'!$E:$E>=IF(ISBLANK($B$5),0,$B$5)) * ('Master Leads'!$E:$E<=IF(ISBLANK($D$5),99999,$D$5)))) | H27: =IF($A27="","",COUNTIFS('Master Leads'!$D:$D,$A27,'Master Leads'!$E:$E,">="&IF(ISBLANK($B$5),0,$B$5),'Master Leads'!$E:$E,"<="&IF(ISBLANK($D$5),99999,$D$5))) | I27: =IF(OR($A27="",$H$29=0),"",H27/$H$29)
A28: {=IF(INDEX(Members!$A:$A,21)="","",INDEX(Members!$A:$A,21))} | B28: =IF($A28="","",SUMPRODUCT(('Master Leads'!$D:$D=$A28) * (ISNUMBER(SEARCH("6", 'Master Leads'!$G:$G))) * ('Master Leads'!$E:$E>=IF(ISBLANK($B$5),0,$B$5)) * ('Master Leads'!$E:$E<=IF(ISBLANK($D$5),99999,$D$5)))) | C28: =IF($A28="","",SUMPRODUCT(('Master Leads'!$D:$D=$A28) * (ISNUMBER(SEARCH("7", 'Master Leads'!$G:$G))) * ('Master Leads'!$E:$E>=IF(ISBLANK($B$5),0,$B$5)) * ('Master Leads'!$E:$E<=IF(ISBLANK($D$5),99999,$D$5)))) | D28: =IF($A28="","",SUMPRODUCT(('Master Leads'!$D:$D=$A28) * (ISNUMBER(SEARCH("8", 'Master Leads'!$G:$G))) * ('Master Leads'!$E:$E>=IF(ISBLANK($B$5),0,$B$5)) * ('Master Leads'!$E:$E<=IF(ISBLANK($D$5),99999,$D$5)))) | E28: =IF($A28="","",SUMPRODUCT(('Master Leads'!$D:$D=$A28) * (ISNUMBER(SEARCH("9", 'Master Leads'!$G:$G))) * ('Master Leads'!$E:$E>=IF(ISBLANK($B$5),0,$B$5)) * ('Master Leads'!$E:$E<=IF(ISBLANK($D$5),99999,$D$5)))) | F28: =IF($A28="","",SUMPRODUCT(('Master Leads'!$D:$D=$A28) * (ISNUMBER(SEARCH("10", 'Master Leads'!$G:$G))) * ('Master Leads'!$E:$E>=IF(ISBLANK($B$5),0,$B$5)) * ('Master Leads'!$E:$E<=IF(ISBLANK($D$5),99999,$D$5)))) | G28: =IF($A28="","",SUMPRODUCT(('Master Leads'!$D:$D=$A28) * (ISNUMBER(SEARCH("11", 'Master Leads'!$G:$G))) * ('Master Leads'!$E:$E>=IF(ISBLANK($B$5),0,$B$5)) * ('Master Leads'!$E:$E<=IF(ISBLANK($D$5),99999,$D$5)))) | H28: =IF($A28="","",COUNTIFS('Master Leads'!$D:$D,$A28,'Master Leads'!$E:$E,">="&IF(ISBLANK($B$5),0,$B$5),'Master Leads'!$E:$E,"<="&IF(ISBLANK($D$5),99999,$D$5))) | I28: =IF(OR($A28="",$H$29=0),"",H28/$H$29)
A29: TOTAL | B29: =SUMPRODUCT((ISNUMBER(SEARCH("6", 'Master Leads'!$G:$G))) * ('Master Leads'!$E:$E>=IF(ISBLANK($B$5),0,$B$5)) * ('Master Leads'!$E:$E<=IF(ISBLANK($D$5),99999,$D$5))) -> 244 | C29: =SUMPRODUCT((ISNUMBER(SEARCH("7", 'Master Leads'!$G:$G))) * ('Master Leads'!$E:$E>=IF(ISBLANK($B$5),0,$B$5)) * ('Master Leads'!$E:$E<=IF(ISBLANK($D$5),99999,$D$5))) -> 409 | D29: =SUMPRODUCT((ISNUMBER(SEARCH("8", 'Master Leads'!$G:$G))) * ('Master Leads'!$E:$E>=IF(ISBLANK($B$5),0,$B$5)) * ('Master Leads'!$E:$E<=IF(ISBLANK($D$5),99999,$D$5))) -> 363 | E29: =SUMPRODUCT((ISNUMBER(SEARCH("9", 'Master Leads'!$G:$G))) * ('Master Leads'!$E:$E>=IF(ISBLANK($B$5),0,$B$5)) * ('Master Leads'!$E:$E<=IF(ISBLANK($D$5),99999,$D$5))) -> 1399 | F29: =SUMPRODUCT((ISNUMBER(SEARCH("10", 'Master Leads'!$G:$G))) * ('Master Leads'!$E:$E>=IF(ISBLANK($B$5),0,$B$5)) * ('Master Leads'!$E:$E<=IF(ISBLANK($D$5),99999,$D$5))) -> 1231 | G29: =SUMPRODUCT((ISNUMBER(SEARCH("11", 'Master Leads'!$G:$G))) * ('Master Leads'!$E:$E>=IF(ISBLANK($B$5),0,$B$5)) * ('Master Leads'!$E:$E<=IF(ISBLANK($D$5),99999,$D$5))) -> 2853 | H29: =COUNTIFS('Master Leads'!$D:$D,"<>",'Master Leads'!$E:$E,">="&IF(ISBLANK($B$5),0,$B$5),'Master Leads'!$E:$E,"<="&IF(ISBLANK($D$5),99999,$D$5)) -> 9238 | I29: 1
A32: TABLE 2: PAID LEADS BY MEMBER & GRADE
A33: Assigned Member | B33: Grade 6 | C33: Grade 7 | D33: Grade 8 | E33: Grade 9 | F33: Grade 10 | G33: Grade 11 | H33: Total Paid | I33: Paid Share % | J33: Conversion %
A34: {=IF(INDEX(Members!$A:$A,2)="","",INDEX(Members!$A:$A,2))} -> maheesha | B34: =IF($A34="","",SUMPRODUCT(('Master Leads'!$D:$D=$A34) * (ISNUMBER(SEARCH("6", 'Master Leads'!$P:$P))) * ('Master Leads'!$O:$O="Yes") * ('Master Leads'!$E:$E>=IF(ISBLANK($B$5),0,$B$5)) * ('Master Leads'!$E:$E<=IF(ISBLANK($D$5),99999,$D$5)))) -> 0 | C34: =IF($A34="","",SUMPRODUCT(('Master Leads'!$D:$D=$A34) * (ISNUMBER(SEARCH("7", 'Master Leads'!$P:$P))) * ('Master Leads'!$O:$O="Yes") * ('Master Leads'!$E:$E>=IF(ISBLANK($B$5),0,$B$5)) * ('Master Leads'!$E:$E<=IF(ISBLANK($D$5),99999,$D$5)))) -> 0 | D34: =IF($A34="","",SUMPRODUCT(('Master Leads'!$D:$D=$A34) * (ISNUMBER(SEARCH("8", 'Master Leads'!$P:$P))) * ('Master Leads'!$O:$O="Yes") * ('Master Leads'!$E:$E>=IF(ISBLANK($B$5),0,$B$5)) * ('Master Leads'!$E:$E<=IF(ISBLANK($D$5),99999,$D$5)))) -> 0 | E34: =IF($A34="","",SUMPRODUCT(('Master Leads'!$D:$D=$A34) * (ISNUMBER(SEARCH("9", 'Master Leads'!$P:$P))) * ('Master Leads'!$O:$O="Yes") * ('Master Leads'!$E:$E>=IF(ISBLANK($B$5),0,$B$5)) * ('Master Leads'!$E:$E<=IF(ISBLANK($D$5),99999,$D$5)))) -> 0 | F34: =IF($A34="","",SUMPRODUCT(('Master Leads'!$D:$D=$A34) * (ISNUMBER(SEARCH("10", 'Master Leads'!$P:$P))) * ('Master Leads'!$O:$O="Yes") * ('Master Leads'!$E:$E>=IF(ISBLANK($B$5),0,$B$5)) * ('Master Leads'!$E:$E<=IF(ISBLANK($D$5),99999,$D$5)))) -> 0 | G34: =IF($A34="","",SUMPRODUCT(('Master Leads'!$D:$D=$A34) * (ISNUMBER(SEARCH("11", 'Master Leads'!$P:$P))) * ('Master Leads'!$O:$O="Yes") * ('Master Leads'!$E:$E>=IF(ISBLANK($B$5),0,$B$5)) * ('Master Leads'!$E:$E<=IF(ISBLANK($D$5),99999,$D$5)))) -> 0 | H34: =IF($A34="","",SUM(B34:G34)) -> 0 | I34: =IF(OR($A34="",$H$54=0),"",H34/$H$54) -> 0 | J34: =IF(OR($A34="",H9=0),"",H34/H9) -> 0
A35: {=IF(INDEX(Members!$A:$A,3)="","",INDEX(Members!$A:$A,3))} -> menik | B35: =IF($A35="","",SUMPRODUCT(('Master Leads'!$D:$D=$A35) * (ISNUMBER(SEARCH("6", 'Master Leads'!$P:$P))) * ('Master Leads'!$O:$O="Yes") * ('Master Leads'!$E:$E>=IF(ISBLANK($B$5),0,$B$5)) * ('Master Leads'!$E:$E<=IF(ISBLANK($D$5),99999,$D$5)))) -> 0 | C35: =IF($A35="","",SUMPRODUCT(('Master Leads'!$D:$D=$A35) * (ISNUMBER(SEARCH("7", 'Master Leads'!$P:$P))) * ('Master Leads'!$O:$O="Yes") * ('Master Leads'!$E:$E>=IF(ISBLANK($B$5),0,$B$5)) * ('Master Leads'!$E:$E<=IF(ISBLANK($D$5),99999,$D$5)))) -> 0 | D35: =IF($A35="","",SUMPRODUCT(('Master Leads'!$D:$D=$A35) * (ISNUMBER(SEARCH("8", 'Master Leads'!$P:$P))) * ('Master Leads'!$O:$O="Yes") * ('Master Leads'!$E:$E>=IF(ISBLANK($B$5),0,$B$5)) * ('Master Leads'!$E:$E<=IF(ISBLANK($D$5),99999,$D$5)))) -> 0 | E35: =IF($A35="","",SUMPRODUCT(('Master Leads'!$D:$D=$A35) * (ISNUMBER(SEARCH("9", 'Master Leads'!$P:$P))) * ('Master Leads'!$O:$O="Yes") * ('Master Leads'!$E:$E>=IF(ISBLANK($B$5),0,$B$5)) * ('Master Leads'!$E:$E<=IF(ISBLANK($D$5),99999,$D$5)))) -> 0 | F35: =IF($A35="","",SUMPRODUCT(('Master Leads'!$D:$D=$A35) * (ISNUMBER(SEARCH("10", 'Master Leads'!$P:$P))) * ('Master Leads'!$O:$O="Yes") * ('Master Leads'!$E:$E>=IF(ISBLANK($B$5),0,$B$5)) * ('Master Leads'!$E:$E<=IF(ISBLANK($D$5),99999,$D$5)))) -> 0 | G35: =IF($A35="","",SUMPRODUCT(('Master Leads'!$D:$D=$A35) * (ISNUMBER(SEARCH("11", 'Master Leads'!$P:$P))) * ('Master Leads'!$O:$O="Yes") * ('Master Leads'!$E:$E>=IF(ISBLANK($B$5),0,$B$5)) * ('Master Leads'!$E:$E<=IF(ISBLANK($D$5),99999,$D$5)))) -> 0 | H35: =IF($A35="","",SUM(B35:G35)) -> 0 | I35: =IF(OR($A35="",$H$54=0),"",H35/$H$54) -> 0 | J35: =IF(OR($A35="",H10=0),"",H35/H10)
