Workbook

Sheet Master Leads
A1: Phone (Normalized) | B1: Raw Phone (as entered) | C1: F-Code | D1: Assigned Member | E1: Date Added | F1: Status | G1: Grade | H1: Comments | I1: Campaign / Boost Name | J1: Repeat Student? | K1: Duplicate Check | L1: Previous F-Code (if repeat) | M1: Second Call Done | N1: Second Call Notes | O1: Paid | P1: Grade (Final / Interested)

Sheet Leads Summary
A2: CRM LEADS & PERFORMANCE ANALYTICS
A3: Real-time team analytics, grade distribution, conversion metrics, unresolved pipelines, and campaign effectiveness.
A5: Filter Start Date: | C5: End Date: | E5: Leave dates blank to view All-Time data. Format: YYYY-MM-DD (e.g. 2026-07-01)
A7: TABLE 1: ALL LEADS BY MEMBER & GRADE
A8: Assigned Member | B8: Grade 6 | C8: Grade 7 | D8: Grade 8 | E8: Grade 9 | F8: Grade 10 | G8: Grade 11 | H8: Total Leads | I8: Share %
A9: =IF(INDEX(Members!$A:$A,2)="","",INDEX(Members!$A:$A,2)) | B9: =IF($A9="","",SUMPRODUCT(('Master Leads'!$D:$D=$A9) * (ISNUMBER(SEARCH("6", 'Master Leads'!$G:$G))) * ('Master Leads'!$E:$E>=IF(ISBLANK($B$5),0,$B$5)) * ('Master Leads'!$E:$E<=IF(ISBLANK($D$5),99999,$D$5)))) | C9: =IF($A9="","",SUMPRODUCT(('Master Leads'!$D:$D=$A9) * (ISNUMBER(SEARCH("7", 'Master Leads'!$G:$G))) * ('Master Leads'!$E:$E>=IF(ISBLANK($B$5),0,$B$5)) * ('Master Leads'!$E:$E<=IF(ISBLANK($D$5),99999,$D$5)))) | D9: =IF($A9="","",SUMPRODUCT(('Master Leads'!$D:$D=$A9) * (ISNUMBER(SEARCH("8", 'Master Leads'!$G:$G))) * ('Master Leads'!$E:$E>=IF(ISBLANK($B$5),0,$B$5)) * ('Master Leads'!$E:$E<=IF(ISBLANK($D$5),99999,$D$5)))) | E9: =IF($A9="","",SUMPRODUCT(('Master Leads'!$D:$D=$A9) * (ISNUMBER(SEARCH("9", 'Master Leads'!$G:$G))) * ('Master Leads'!$E:$E>=IF(ISBLANK($B$5),0,$B$5)) * ('Master Leads'!$E:$E<=IF(ISBLANK($D$5),99999,$D$5)))) | F9: =IF($A9="","",SUMPRODUCT(('Master Leads'!$D:$D=$A9) * (ISNUMBER(SEARCH("10", 'Master Leads'!$G:$G))) * ('Master Leads'!$E:$E>=IF(ISBLANK($B$5),0,$B$5)) * ('Master Leads'!$E:$E<=IF(ISBLANK($D$5),99999,$D$5)))) | G9: =IF($A9="","",SUMPRODUCT(('Master Leads'!$D:$D=$A9) * (ISNUMBER(SEARCH("11", 'Master Leads'!$G:$G))) * ('Master Leads'!$E:$E>=IF(ISBLANK($B$5),0,$B$5)) * ('Master Leads'!$E:$E<=IF(ISBLANK($D$5),99999,$D$5)))) | H9: =IF($A9="","",COUNTIFS('Master Leads'!$D:$D,$A9,'Master Leads'!$E:$E,">="&IF(ISBLANK($B$5),0,$B$5),'Master Leads'!$E:$E,"<="&IF(ISBLANK($D$5),99999,$D$5))) | I9: =IF(OR($A9="",$H$29=0),"",H9/$H$29)
A10: =IF(INDEX(Members!$A:$A,3)="","",INDEX(Members!$A:$A,3)) | B10: =IF($A10="","",SUMPRODUCT(('Master Leads'!$D:$D=$A10) * (ISNUMBER(SEARCH("6", 'Master Leads'!$G:$G))) * ('Master Leads'!$E:$E>=IF(ISBLANK($B$5),0,$B$5)) * ('Master Leads'!$E:$E<=IF(ISBLANK($D$5),99999,$D$5)))) | C10: =IF($A10="","",SUMPRODUCT(('Master Leads'!$D:$D=$A10) * (ISNUMBER(SEARCH("7", 'Master Leads'!$G:$G))) * ('Master Leads'!$E:$E>=IF(ISBLANK($B$5),0,$B$5)) * ('Master Leads'!$E:$E<=IF(ISBLANK($D$5),99999,$D$5)))) | D10: =IF($A10="","",SUMPRODUCT(('Master Leads'!$D:$D=$A10) * (ISNUMBER(SEARCH("8", 'Master Leads'!$G:$G))) * ('Master Leads'!$E:$E>=IF(ISBLANK($B$5),0,$B$5)) * ('Master Leads'!$E:$E<=IF(ISBLANK($D$5),99999,$D$5)))) | E10: =IF($A10="","",SUMPRODUCT(('Master Leads'!$D:$D=$A10) * (ISNUMBER(SEARCH("9", 'Master Leads'!$G:$G))) * ('Master Leads'!$E:$E>=IF(ISBLANK($B$5),0,$B$5)) * ('Master Leads'!$E:$E<=IF(ISBLANK($D$5),99999,$D$5)))) | F10: =IF($A10="","",SUMPRODUCT(('Master Leads'!$D:$D=$A10) * (ISNUMBER(SEARCH("10", 'Master Leads'!$G:$G))) * ('Master Leads'!$E:$E>=IF(ISBLANK($B$5),0,$B$5)) * ('Master Leads'!$E:$E<=IF(ISBLANK($D$5),99999,$D$5)))) | G10: =IF($A10="","",SUMPRODUCT(('Master Leads'!$D:$D=$A10) * (ISNUMBER(SEARCH("11", 'Master Leads'!$G:$G))) * ('Master Leads'!$E:$E>=IF(ISBLANK($B$5),0,$B$5)) * ('Master Leads'!$E:$E<=IF(ISBLANK($D$5),99999,$D$5)))) | H10: =IF($A10="","",COUNTIFS('Master Leads'!$D:$D,$A10,'Master Leads'!$E:$E,">="&IF(ISBLANK($B$5),0,$B$5),'Master Leads'!$E:$E,"<="&IF(ISBLANK($D$5),99999,$D$5))) | I10: =IF(OR($A10="",$H$29=0),"",H10/$H$29)
A11: =IF(INDEX(Members!$A:$A,4)="","",INDEX(Members!$A:$A,4)) | B11: =IF($A11="","",SUMPRODUCT(('Master Leads'!$D:$D=$A11) * (ISNUMBER(SEARCH("6", 'Master Leads'!$G:$G))) * ('Master Leads'!$E:$E>=IF(ISBLANK($B$5),0,$B$5)) * ('Master Leads'!$E:$E<=IF(ISBLANK($D$5),99999,$D$5)))) | C11: =IF($A11="","",SUMPRODUCT(('Master Leads'!$D:$D=$A11) * (ISNUMBER(SEARCH("7", 'Master Leads'!$G:$G))) * ('Master Leads'!$E:$E>=IF(ISBLANK($B$5),0,$B$5)) * ('Master Leads'!$E:$E<=IF(ISBLANK($D$5),99999,$D$5)))) | D11: =IF($A11="","",SUMPRODUCT(('Master Leads'!$D:$D=$A11) * (ISNUMBER(SEARCH("8", 'Master Leads'!$G:$G))) * ('Master Leads'!$E:$E>=IF(ISBLANK($B$5),0,$B$5)) * ('Master Leads'!$E:$E<=IF(ISBLANK($D$5),99999,$D$5)))) | E11: =IF($A11="","",SUMPRODUCT(('Master Leads'!$D:$D=$A11) * (ISNUMBER(SEARCH("9", 'Master Leads'!$G:$G))) * ('Master Leads'!$E:$E>=IF(ISBLANK($B$5),0,$B$5)) * ('Master Leads'!$E:$E<=IF(ISBLANK($D$5),99999,$D$5)))) | F11: =IF($A11="","",SUMPRODUCT(('Master Leads'!$D:$D=$A11) * (ISNUMBER(SEARCH("10", 'Master Leads'!$G:$G))) * ('Master Leads'!$E:$E>=IF(ISBLANK($B$5),0,$B$5)) * ('Master Leads'!$E:$E<=IF(ISBLANK($D$5),99999,$D$5)))) | G11: =IF($A11="","",SUMPRODUCT(('Master Leads'!$D:$D=$A11) * (ISNUMBER(SEARCH("11", 'Master Leads'!$G:$G))) * ('Master Leads'!$E:$E>=IF(ISBLANK($B$5),0,$B$5)) * ('Master Leads'!$E:$E<=IF(ISBLANK($D$5),99999,$D$5)))) | H11: =IF($A11="","",COUNTIFS('Master Leads'!$D:$D,$A11,'Master Leads'!$E:$E,">="&IF(ISBLANK($B$5),0,$B$5),'Master Leads'!$E:$E,"<="&IF(ISBLANK($D$5),99999,$D$5))) | I11: =IF(OR($A11="",$H$29=0),"",H11/$H$29)
A12: =IF(INDEX(Members!$A:$A,5)="","",INDEX(Members!$A:$A,5)) | B12: =IF($A12="","",SUMPRODUCT(('Master Leads'!$D:$D=$A12) * (ISNUMBER(SEARCH("6", 'Master Leads'!$G:$G))) * ('Master Leads'!$E:$E>=IF(ISBLANK($B$5),0,$B$5)) * ('Master Leads'!$E:$E<=IF(ISBLANK($D$5),99999,$D$5)))) | C12: =IF($A12="","",SUMPRODUCT(('Master Leads'!$D:$D=$A12) * (ISNUMBER(SEARCH("7", 'Master Leads'!$G:$G))) * ('Master Leads'!$E:$E>=IF(ISBLANK($B$5),0,$B$5)) * ('Master Leads'!$E:$E<=IF(ISBLANK($D$5),99999,$D$5)))) | D12: =IF($A12="","",SUMPRODUCT(('Master Leads'!$D:$D=$A12) * (ISNUMBER(SEARCH("8", 'Master Leads'!$G:$G))) * ('Master Leads'!$E:$E>=IF(ISBLANK($B$5),0,$B$5)) * ('Master Leads'!$E:$E<=IF(ISBLANK($D$5),99999,$D$5)))) | E12: =IF($A12="","",SUMPRODUCT(('Master Leads'!$D:$D=$A12) * (ISNUMBER(SEARCH("9", 'Master Leads'!$G:$G))) * ('Master Leads'!$E:$E>=IF(ISBLANK($B$5),0,$B$5)) * ('Master Leads'!$E:$E<=IF(ISBLANK($D$5),99999,$D$5)))) | F12: =IF($A12="","",SUMPRODUCT(('Master Leads'!$D:$D=$A12) * (ISNUMBER(SEARCH("10", 'Master Leads'!$G:$G))) * ('Master Leads'!$E:$E>=IF(ISBLANK($B$5),0,$B$5)) * ('Master Leads'!$E:$E<=IF(ISBLANK($D$5),99999,$D$5)))) | G12: =IF($A12="","",SUMPRODUCT(('Master Leads'!$D:$D=$A12) * (ISNUMBER(SEARCH("11", 'Master Leads'!$G:$G))) * ('Master Leads'!$E:$E>=IF(ISBLANK($B$5),0,$B$5)) * ('Master Leads'!$E:$E<=IF(ISBLANK($D$5),99999,$D$5)))) | H12: =IF($A12="","",COUNTIFS('Master Leads'!$D:$D,$A12,'Master Leads'!$E:$E,">="&IF(ISBLANK($B$5),0,$B$5),'Master Leads'!$E:$E,"<="&IF(ISBLANK($D$5),99999,$D$5))) | I12: =IF(OR($A12="",$H$29=0),"",H12/$H$29)
A13: =IF(INDEX(Members!$A:$A,6)="","",INDEX(Members!$A:$A,6)) | B13: =IF($A13="","",SUMPRODUCT(('Master Leads'!$D:$D=$A13) * (ISNUMBER(SEARCH("6", 'Master Leads'!$G:$G))) * ('Master Leads'!$E:$E>=IF(ISBLANK($B$5),0,$B$5)) * ('Master Leads'!$E:$E<=IF(ISBLANK($D$5),99999,$D$5)))) | C13: =IF($A13="","",SUMPRODUCT(('Master Leads'!$D:$D=$A13) * (ISNUMBER(SEARCH("7", 'Master Leads'!$G:$G))) * ('Master Leads'!$E:$E>=IF(ISBLANK($B$5),0,$B$5)) * ('Master Leads'!$E:$E<=IF(ISBLANK($D$5),99999,$D$5)))) | D13: =IF($A13="","",SUMPRODUCT(('Master Leads'!$D:$D=$A13) * (ISNUMBER(SEARCH("8", 'Master Leads'!$G:$G))) * ('Master Leads'!$E:$E>=IF(ISBLANK($B$5),0,$B$5)) * ('Master Leads'!$E:$E<=IF(ISBLANK($D$5),99999,$D$5)))) | E13: =IF($A13="","",SUMPRODUCT(('Master Leads'!$D:$D=$A13) * (ISNUMBER(SEARCH("9", 'Master Leads'!$G:$G))) * ('Master Leads'!$E:$E>=IF(ISBLANK($B$5),0,$B$5)) * ('Master Leads'!$E:$E<=IF(ISBLANK($D$5),99999,$D$5)))) | F13: =IF($A13="","",SUMPRODUCT(('Master Leads'!$D:$D=$A13) * (ISNUMBER(SEARCH("10", 'Master Leads'!$G:$G))) * ('Master Leads'!$E:$E>=IF(ISBLANK($B$5),0,$B$5)) * ('Master Leads'!$E:$E<=IF(ISBLANK($D$5),99999,$D$5)))) | G13: =IF($A13="","",SUMPRODUCT(('Master Leads'!$D:$D=$A13) * (ISNUMBER(SEARCH("11", 'Master Leads'!$G:$G))) * ('Master Leads'!$E:$E>=IF(ISBLANK($B$5),0,$B$5)) * ('Master Leads'!$E:$E<=IF(ISBLANK($D$5),99999,$D$5)))) | H13: =IF($A13="","",COUNTIFS('Master Leads'!$D:$D,$A13,'Master Leads'!$E:$E,">="&IF(ISBLANK($B$5),0,$B$5),'Master Leads'!$E:$E,"<="&IF(ISBLANK($D$5),99999,$D$5))) | I13: =IF(OR($A13="",$H$29=0),"",H13/$H$29)
A14: =IF(INDEX(Members!$A:$A,7)="","",INDEX(Members!$A:$A,7)) | B14: =IF($A14="","",SUMPRODUCT(('Master Leads'!$D:$D=$A14) * (ISNUMBER(SEARCH("6", 'Master Leads'!$G:$G))) * ('Master Leads'!$E:$E>=IF(ISBLANK($B$5),0,$B$5)) * ('Master Leads'!$E:$E<=IF(ISBLANK($D$5),99999,$D$5)))) | C14: =IF($A14="","",SUMPRODUCT(('Master Leads'!$D:$D=$A14) * (ISNUMBER(SEARCH("7", 'Master Leads'!$G:$G))) * ('Master Leads'!$E:$E>=IF(ISBLANK($B$5),0,$B$5)) * ('Master Leads'!$E:$E<=IF(ISBLANK($D$5),99999,$D$5)))) | D14: =IF($A14="","",SUMPRODUCT(('Master Leads'!$D:$D=$A14) * (ISNUMBER(SEARCH("8", 'Master Leads'!$G:$G))) * ('Master Leads'!$E:$E>=IF(ISBLANK($B$5),0,$B$5)) * ('Master Leads'!$E:$E<=IF(ISBLANK($D$5),99999,$D$5)))) | E14: =IF($A14="","",SUMPRODUCT(('Master Leads'!$D:$D=$A14) * (ISNUMBER(SEARCH("9", 'Master Leads'!$G:$G))) * ('Master Leads'!$E:$E>=IF(ISBLANK($B$5),0,$B$5)) * ('Master Leads'!$E:$E<=IF(ISBLANK($D$5),99999,$D$5)))) | F14: =IF($A14="","",SUMPRODUCT(('Master Leads'!$D:$D=$A14) * (ISNUMBER(SEARCH("10", 'Master Leads'!$G:$G))) * ('Master Leads'!$E:$E>=IF(ISBLANK($B$5),0,$B$5)) * ('Master Leads'!$E:$E<=IF(ISBLANK($D$5),99999,$D$5)))) | G14: =IF($A14="","",SUMPRODUCT(('Master Leads'!$D:$D=$A14) * (ISNUMBER(SEARCH("11", 'Master Leads'!$G:$G))) * ('Master Leads'!$E:$E>=IF(ISBLANK($B$5),0,$B$5)) * ('Master Leads'!$E:$E<=IF(ISBLANK($D$5),99999,$D$5)))) | H14: =IF($A14="","",COUNTIFS('Master Leads'!$D:$D,$A14,'Master Leads'!$E:$E,">="&IF(ISBLANK($B$5),0,$B$5),'Master Leads'!$E:$E,"<="&IF(ISBLANK($D$5),99999,$D$5))) | I14: =IF(OR($A14="",$H$29=0),"",H14/$H$29)
A15: =IF(INDEX(Members!$A:$A,8)="","",INDEX(Members!$A:$A,8)) | B15: =IF($A15="","",SUMPRODUCT(('Master Leads'!$D:$D=$A15) * (ISNUMBER(SEARCH("6", 'Master Leads'!$G:$G))) * ('Master Leads'!$E:$E>=IF(ISBLANK($B$5),0,$B$5)) * ('Master Leads'!$E:$E<=IF(ISBLANK($D$5),99999,$D$5)))) | C15: =IF($A15="","",SUMPRODUCT(('Master Leads'!$D:$D=$A15) * (ISNUMBER(SEARCH("7", 'Master Leads'!$G:$G))) * ('Master Leads'!$E:$E>=IF(ISBLANK($B$5),0,$B$5)) * ('Master Leads'!$E:$E<=IF(ISBLANK($D$5),99999,$D$5)))) | D15: =IF($A15="","",SUMPRODUCT(('Master Leads'!$D:$D=$A15) * (ISNUMBER(SEARCH("8", 'Master Leads'!$G:$G))) * ('Master Leads'!$E:$E>=IF(ISBLANK($B$5),0,$B$5)) * ('Master Leads'!$E:$E<=IF(ISBLANK($D$5),99999,$D$5)))) | E15: =IF($A15="","",SUMPRODUCT(('Master Leads'!$D:$D=$A15) * (ISNUMBER(SEARCH("9", 'Master Leads'!$G:$G))) * ('Master Leads'!$E:$E>=IF(ISBLANK($B$5),0,$B$5)) * ('Master Leads'!$E:$E<=IF(ISBLANK($D$5),99999,$D$5)))) | F15: =IF($A15="","",SUMPRODUCT(('Master Leads'!$D:$D=$A15) * (ISNUMBER(SEARCH("10", 'Master Leads'!$G:$G))) * ('Master Leads'!$E:$E>=IF(ISBLANK($B$5),0,$B$5)) * ('Master Leads'!$E:$E<=IF(ISBLANK($D$5),99999,$D$5)))) | G15: =IF($A15="","",SUMPRODUCT(('Master Leads'!$D:$D=$A15) * (ISNUMBER(SEARCH("11", 'Master Leads'!$G:$G))) * ('Master Leads'!$E:$E>=IF(ISBLANK($B$5),0,$B$5)) * ('Master Leads'!$E:$E<=IF(ISBLANK($D$5),99999,$D$5)))) | H15: =IF($A15="","",COUNTIFS('Master Leads'!$D:$D,$A15,'Master Leads'!$E:$E,">="&IF(ISBLANK($B$5),0,$B$5),'Master Leads'!$E:$E,"<="&IF(ISBLANK($D$5),99999,$D$5))) | I15: =IF(OR($A15="",$H$29=0),"",H15/$H$29)
A16: =IF(INDEX(Members!$A:$A,9)="","",INDEX(Members!$A:$A,9)) | B16: =IF($A16="","",SUMPRODUCT(('Master Leads'!$D:$D=$A16) * (ISNUMBER(SEARCH("6", 'Master Leads'!$G:$G))) * ('Master Leads'!$E:$E>=IF(ISBLANK($B$5),0,$B$5)) * ('Master Leads'!$E:$E<=IF(ISBLANK($D$5),99999,$D$5)))) | C16: =IF($A16="","",SUMPRODUCT(('Master Leads'!$D:$D=$A16) * (ISNUMBER(SEARCH("7", 'Master Leads'!$G:$G))) * ('Master Leads'!$E:$E>=IF(ISBLANK($B$5),0,$B$5)) * ('Master Leads'!$E:$E<=IF(ISBLANK($D$5),99999,$D$5)))) | D16: =IF($A16="","",SUMPRODUCT(('Master Leads'!$D:$D=$A16) * (ISNUMBER(SEARCH("8", 'Master Leads'!$G:$G))) * ('Master Leads'!$E:$E>=IF(ISBLANK($B$5),0,$B$5)) * ('Master Leads'!$E:$E<=IF(ISBLANK($D$5),99999,$D$5)))) | E16: =IF($A16="","",SUMPRODUCT(('Master Leads'!$D:$D=$A16) * (ISNUMBER(SEARCH("9", 'Master Leads'!$G:$G))) * ('Master Leads'!$E:$E>=IF(ISBLANK($B$5),0,$B$5)) * ('Master Leads'!$E:$E<=IF(ISBLANK($D$5),99999,$D$5)))) | F16: =IF($A16="","",SUMPRODUCT(('Master Leads'!$D:$D=$A16) * (ISNUMBER(SEARCH("10", 'Master Leads'!$G:$G))) * ('Master Leads'!$E:$E>=IF(ISBLANK($B$5),0,$B$5)) * ('Master Leads'!$E:$E<=IF(ISBLANK($D$5),99999,$D$5)))) | G16: =IF($A16="","",SUMPRODUCT(('Master Leads'!$D:$D=$A16) * (ISNUMBER(SEARCH("11", 'Master Leads'!$G:$G))) * ('Master Leads'!$E:$E>=IF(ISBLANK($B$5),0,$B$5)) * ('Master Leads'!$E:$E<=IF(ISBLANK($D$5),99999,$D$5)))) | H16: =IF($A16="","",COUNTIFS('Master Leads'!$D:$D,$A16,'Master Leads'!$E:$E,">="&IF(ISBLANK($B$5),0,$B$5),'Master Leads'!$E:$E,"<="&IF(ISBLANK($D$5),99999,$D$5))) | I16: =IF(OR($A16="",$H$29=0),"",H16/$H$29)
A17: =IF(INDEX(Members!$A:$A,10)="","",INDEX(Members!$A:$A,10)) | B17: =IF($A17="","",SUMPRODUCT(('Master Leads'!$D:$D=$A17) * (ISNUMBER(SEARCH("6", 'Master Leads'!$G:$G))) * ('Master Leads'!$E:$E>=IF(ISBLANK($B$5),0,$B$5)) * ('Master Leads'!$E:$E<=IF(ISBLANK($D$5),99999,$D$5)))) | C17: =IF($A17="","",SUMPRODUCT(('Master Leads'!$D:$D=$A17) * (ISNUMBER(SEARCH("7", 'Master Leads'!$G:$G))) * ('Master Leads'!$E:$E>=IF(ISBLANK($B$5),0,$B$5)) * ('Master Leads'!$E:$E<=IF(ISBLANK($D$5),99999,$D$5)))) | D17: =IF($A17="","",SUMPRODUCT(('Master Leads'!$D:$D=$A17) * (ISNUMBER(SEARCH("8", 'Master Leads'!$G:$G))) * ('Master Leads'!$E:$E>=IF(ISBLANK($B$5),0,$B$5)) * ('Master Leads'!$E:$E<=IF(ISBLANK($D$5),99999,$D$5)))) | E17: =IF($A17="","",SUMPRODUCT(('Master Leads'!$D:$D=$A17) * (ISNUMBER(SEARCH("9", 'Master Leads'!$G:$G))) * ('Master Leads'!$E:$E>=IF(ISBLANK($B$5),0,$B$5)) * ('Master Leads'!$E:$E<=IF(ISBLANK($D$5),99999,$D$5)))) | F17: =IF($A17="","",SUMPRODUCT(('Master Leads'!$D:$D=$A17) * (ISNUMBER(SEARCH("10", 'Master Leads'!$G:$G))) * ('Master Leads'!$E:$E>=IF(ISBLANK($B$5),0,$B$5)) * ('Master Leads'!$E:$E<=IF(ISBLANK($D$5),99999,$D$5)))) | G17: =IF($A17="","",SUMPRODUCT(('Master Leads'!$D:$D=$A17) * (ISNUMBER(SEARCH("11", 'Master Leads'!$G:$G))) * ('Master Leads'!$E:$E>=IF(ISBLANK($B$5),0,$B$5)) * ('Master Leads'!$E:$E<=IF(ISBLANK($D$5),99999,$D$5)))) | H17: =IF($A17="","",COUNTIFS('Master Leads'!$D:$D,$A17,'Master Leads'!$E:$E,">="&IF(ISBLANK($B$5),0,$B$5),'Master Leads'!$E:$E,"<="&IF(ISBLANK($D$5),99999,$D$5))) | I17: =IF(OR($A17="",$H$29=0),"",H17/$H$29)
A18: =IF(INDEX(Members!$A:$A,11)="","",INDEX(Members!$A:$A,11)) | B18: =IF($A18="","",SUMPRODUCT(('Master Leads'!$D:$D=$A18) * (ISNUMBER(SEARCH("6", 'Master Leads'!$G:$G))) * ('Master Leads'!$E:$E>=IF(ISBLANK($B$5),0,$B$5)) * ('Master Leads'!$E:$E<=IF(ISBLANK($D$5),99999,$D$5)))) | C18: =IF($A18="","",SUMPRODUCT(('Master Leads'!$D:$D=$A18) * (ISNUMBER(SEARCH("7", 'Master Leads'!$G:$G))) * ('Master Leads'!$E:$E>=IF(ISBLANK($B$5),0,$B$5)) * ('Master Leads'!$E:$E<=IF(ISBLANK($D$5),99999,$D$5)))) | D18: =IF($A18="","",SUMPRODUCT(('Master Leads'!$D:$D=$A18) * (ISNUMBER(SEARCH("8", 'Master Leads'!$G:$G))) * ('Master Leads'!$E:$E>=IF(ISBLANK($B$5),0,$B$5)) * ('Master Leads'!$E:$E<=IF(ISBLANK($D$5),99999,$D$5)))) | E18: =IF($A18="","",SUMPRODUCT(('Master Leads'!$D:$D=$A18) * (ISNUMBER(SEARCH("9", 'Master Leads'!$G:$G))) * ('Master Leads'!$E:$E>=IF(ISBLANK($B$5),0,$B$5)) * ('Master Leads'!$E:$E<=IF(ISBLANK($D$5),99999,$D$5)))) | F18: =IF($A18="","",SUMPRODUCT(('Master Leads'!$D:$D=$A18) * (ISNUMBER(SEARCH("10", 'Master Leads'!$G:$G))) * ('Master Leads'!$E:$E>=IF(ISBLANK($B$5),0,$B$5)) * ('Master Leads'!$E:$E<=IF(ISBLANK($D$5),99999,$D$5)))) | G18: =IF($A18="","",SUMPRODUCT(('Master Leads'!$D:$D=$A18) * (ISNUMBER(SEARCH("11", 'Master Leads'!$G:$G))) * ('Master Leads'!$E:$E>=IF(ISBLANK($B$5),0,$B$5)) * ('Master Leads'!$E:$E<=IF(ISBLANK($D$5),99999,$D$5)))) | H18: =IF($A18="","",COUNTIFS('Master Leads'!$D:$D,$A18,'Master Leads'!$E:$E,">="&IF(ISBLANK($B$5),0,$B$5),'Master Leads'!$E:$E,"<="&IF(ISBLANK($D$5),99999,$D$5))) | I18: =IF(OR($A18="",$H$29=0),"",H18/$H$29)
A19: =IF(INDEX(Members!$A:$A,12)="","",INDEX(Members!$A:$A,12)) | B19: =IF($A19="","",SUMPRODUCT(('Master Leads'!$D:$D=$A19) * (ISNUMBER(SEARCH("6", 'Master Leads'!$G:$G))) * ('Master Leads'!$E:$E>=IF(ISBLANK($B$5),0,$B$5)) * ('Master Leads'!$E:$E<=IF(ISBLANK($D$5),99999,$D$5)))) | C19: =IF($A19="","",SUMPRODUCT(('Master Leads'!$D:$D=$A19) * (ISNUMBER(SEARCH("7", 'Master Leads'!$G:$G))) * ('Master Leads'!$E:$E>=IF(ISBLANK($B$5),0,$B$5)) * ('Master Leads'!$E:$E<=IF(ISBLANK($D$5),99999,$D$5)))) | D19: =IF($A19="","",SUMPRODUCT(('Master Leads'!$D:$D=$A19) * (ISNUMBER(SEARCH("8", 'Master Leads'!$G:$G))) * ('Master Leads'!$E:$E>=IF(ISBLANK($B$5),0,$B$5)) * ('Master Leads'!$E:$E<=IF(ISBLANK($D$5),99999,$D$5)))) | E19: =IF($A19="","",SUMPRODUCT(('Master Leads'!$D:$D=$A19) * (ISNUMBER(SEARCH("9", 'Master Leads'!$G:$G))) * ('Master Leads'!$E:$E>=IF(ISBLANK($B$5),0,$B$5)) * ('Master Leads'!$E:$E<=IF(ISBLANK($D$5),99999,$D$5)))) | F19: =IF($A19="","",SUMPRODUCT(('Master Leads'!$D:$D=$A19) * (ISNUMBER(SEARCH("10", 'Master Leads'!$G:$G))) * ('Master Leads'!$E:$E>=IF(ISBLANK($B$5),0,$B$5)) * ('Master Leads'!$E:$E<=IF(ISBLANK($D$5),99999,$D$5)))) | G19: =IF($A19="","",SUMPRODUCT(('Master Leads'!$D:$D=$A19) * (ISNUMBER(SEARCH("11", 'Master Leads'!$G:$G))) * ('Master Leads'!$E:$E>=IF(ISBLANK($B$5),0,$B$5)) * ('Master Leads'!$E:$E<=IF(ISBLANK($D$5),99999,$D$5)))) | H19: =IF($A19="","",COUNTIFS('Master Leads'!$D:$D,$A19,'Master Leads'!$E:$E,">="&IF(ISBLANK($B$5),0,$B$5),'Master Leads'!$E:$E,"<="&IF(ISBLANK($D$5),99999,$D$5))) | I19: =IF(OR($A19="",$H$29=0),"",H19/$H$29)
A20: =IF(INDEX(Members!$A:$A,13)="","",INDEX(Members!$A:$A,13)) | B20: =IF($A20="","",SUMPRODUCT(('Master Leads'!$D:$D=$A20) * (ISNUMBER(SEARCH("6", 'Master Leads'!$G:$G))) * ('Master Leads'!$E:$E>=IF(ISBLANK($B$5),0,$B$5)) * ('Master Leads'!$E:$E<=IF(ISBLANK($D$5),99999,$D$5)))) | C20: =IF($A20="","",SUMPRODUCT(('Master Leads'!$D:$D=$A20) * (ISNUMBER(SEARCH("7", 'Master Leads'!$G:$G))) * ('Master Leads'!$E:$E>=IF(ISBLANK($B$5),0,$B$5)) * ('Master Leads'!$E:$E<=IF(ISBLANK($D$5),99999,$D$5)))) | D20: =IF($A20="","",SUMPRODUCT(('Master Leads'!$D:$D=$A20) * (ISNUMBER(SEARCH("8", 'Master Leads'!$G:$G))) * ('Master Leads'!$E:$E>=IF(ISBLANK($B$5),0,$B$5)) * ('Master Leads'!$E:$E<=IF(ISBLANK($D$5),99999,$D$5)))) | E20: =IF($A20="","",SUMPRODUCT(('Master Leads'!$D:$D=$A20) * (ISNUMBER(SEARCH("9", 'Master Leads'!$G:$G))) * ('Master Leads'!$E:$E>=IF(ISBLANK($B$5),0,$B$5)) * ('Master Leads'!$E:$E<=IF(ISBLANK($D$5),99999,$D$5)))) | F20: =IF($A20="","",SUMPRODUCT(('Master Leads'!$D:$D=$A20) * (ISNUMBER(SEARCH("10", 'Master Leads'!$G:$G))) * ('Master Leads'!$E:$E>=IF(ISBLANK($B$5),0,$B$5)) * ('Master Leads'!$E:$E<=IF(ISBLANK($D$5),99999,$D$5)))) | G20: =IF($A20="","",SUMPRODUCT(('Master Leads'!$D:$D=$A20) * (ISNUMBER(SEARCH("11", 'Master Leads'!$G:$G))) * ('Master Leads'!$E:$E>=IF(ISBLANK($B$5),0,$B$5)) * ('Master Leads'!$E:$E<=IF(ISBLANK($D$5),99999,$D$5)))) | H20: =IF($A20="","",COUNTIFS('Master Leads'!$D:$D,$A20,'Master Leads'!$E:$E,">="&IF(ISBLANK($B$5),0,$B$5),'Master Leads'!$E:$E,"<="&IF(ISBLANK($D$5),99999,$D$5))) | I20: =IF(OR($A20="",$H$29=0),"",H20/$H$29)
A21: =IF(INDEX(Members!$A:$A,14)="","",INDEX(Members!$A:$A,14)) | B21: =IF($A21="","",SUMPRODUCT(('Master Leads'!$D:$D=$A21) * (ISNUMBER(SEARCH("6", 'Master Leads'!$G:$G))) * ('Master Leads'!$E:$E>=IF(ISBLANK($B$5),0,$B$5)) * ('Master Leads'!$E:$E<=IF(ISBLANK($D$5),99999,$D$5)))) | C21: =IF($A21="","",SUMPRODUCT(('Master Leads'!$D:$D=$A21) * (ISNUMBER(SEARCH("7", 'Master Leads'!$G:$G))) * ('Master Leads'!$E:$E>=IF(ISBLANK($B$5),0,$B$5)) * ('Master Leads'!$E:$E<=IF(ISBLANK($D$5),99999,$D$5)))) | D21: =IF($A21="","",SUMPRODUCT(('Master Leads'!$D:$D=$A21) * (ISNUMBER(SEARCH("8", 'Master Leads'!$G:$G))) * ('Master Leads'!$E:$E>=IF(ISBLANK($B$5),0,$B$5)) * ('Master Leads'!$E:$E<=IF(ISBLANK($D$5),99999,$D$5)))) | E21: =IF($A21="","",SUMPRODUCT(('Master Leads'!$D:$D=$A21) * (ISNUMBER(SEARCH("9", 'Master Leads'!$G:$G))) * ('Master Leads'!$E:$E>=IF(ISBLANK($B$5),0,$B$5)) * ('Master Leads'!$E:$E<=IF(ISBLANK($D$5),99999,$D$5)))) | F21: =IF($A21="","",SUMPRODUCT(('Master Leads'!$D:$D=$A21) * (ISNUMBER(SEARCH("10", 'Master Leads'!$G:$G))) * ('Master Leads'!$E:$E>=IF(ISBLANK($B$5),0,$B$5)) * ('Master Leads'!$E:$E<=IF(ISBLANK($D$5),99999,$D$5)))) | G21: =IF($A21="","",SUMPRODUCT(('Master Leads'!$D:$D=$A21) * (ISNUMBER(SEARCH("11", 'Master Leads'!$G:$G))) * ('Master Leads'!$E:$E>=IF(ISBLANK($B$5),0,$B$5)) * ('Master Leads'!$E:$E<=IF(ISBLANK($D$5),99999,$D$5)))) | H21: =IF($A21="","",COUNTIFS('Master Leads'!$D:$D,$A21,'Master Leads'!$E:$E,">="&IF(ISBLANK($B$5),0,$B$5),'Master Leads'!$E:$E,"<="&IF(ISBLANK($D$5),99999,$D$5))) | I21: =IF(OR($A21="",$H$29=0),"",H21/$H$29)
A22: =IF(INDEX(Members!$A:$A,15)="","",INDEX(Members!$A:$A,15)) | B22: =IF($A22="","",SUMPRODUCT(('Master Leads'!$D:$D=$A22) * (ISNUMBER(SEARCH("6", 'Master Leads'!$G:$G))) * ('Master Leads'!$E:$E>=IF(ISBLANK($B$5),0,$B$5)) * ('Master Leads'!$E:$E<=IF(ISBLANK($D$5),99999,$D$5)))) | C22: =IF($A22="","",SUMPRODUCT(('Master Leads'!$D:$D=$A22) * (ISNUMBER(SEARCH("7", 'Master Leads'!$G:$G))) * ('Master Leads'!$E:$E>=IF(ISBLANK($B$5),0,$B$5)) * ('Master Leads'!$E:$E<=IF(ISBLANK($D$5),99999,$D$5)))) | D22: =IF($A22="","",SUMPRODUCT(('Master Leads'!$D:$D=$A22) * (ISNUMBER(SEARCH("8", 'Master Leads'!$G:$G))) * ('Master Leads'!$E:$E>=IF(ISBLANK($B$5),0,$B$5)) * ('Master Leads'!$E:$E<=IF(ISBLANK($D$5),99999,$D$5)))) | E22: =IF($A22="","",SUMPRODUCT(('Master Leads'!$D:$D=$A22) * (ISNUMBER(SEARCH("9", 'Master Leads'!$G:$G))) * ('Master Leads'!$E:$E>=IF(ISBLANK($B$5),0,$B$5)) * ('Master Leads'!$E:$E<=IF(ISBLANK($D$5),99999,$D$5)))) | F22: =IF($A22="","",SUMPRODUCT(('Master Leads'!$D:$D=$A22) * (ISNUMBER(SEARCH("10", 'Master Leads'!$G:$G))) * ('Master Leads'!$E:$E>=IF(ISBLANK($B$5),0,$B$5)) * ('Master Leads'!$E:$E<=IF(ISBLANK($D$5),99999,$D$5)))) | G22: =IF($A22="","",SUMPRODUCT(('Master Leads'!$D:$D=$A22) * (ISNUMBER(SEARCH("11", 'Master Leads'!$G:$G))) * ('Master Leads'!$E:$E>=IF(ISBLANK($B$5),0,$B$5)) * ('Master Leads'!$E:$E<=IF(ISBLANK($D$5),99999,$D$5)))) | H22: =IF($A22="","",COUNTIFS('Master Leads'!$D:$D,$A22,'Master Leads'!$E:$E,">="&IF(ISBLANK($B$5),0,$B$5),'Master Leads'!$E:$E,"<="&IF(ISBLANK($D$5),99999,$D$5))) | I22: =IF(OR($A22="",$H$29=0),"",H22/$H$29)
A23: =IF(INDEX(Members!$A:$A,16)="","",INDEX(Members!$A:$A,16)) | B23: =IF($A23="","",SUMPRODUCT(('Master Leads'!$D:$D=$A23) * (ISNUMBER(SEARCH("6", 'Master Leads'!$G:$G))) * ('Master Leads'!$E:$E>=IF(ISBLANK($B$5),0,$B$5)) * ('Master Leads'!$E:$E<=IF(ISBLANK($D$5),99999,$D$5)))) | C23: =IF($A23="","",SUMPRODUCT(('Master Leads'!$D:$D=$A23) * (ISNUMBER(SEARCH("7", 'Master Leads'!$G:$G))) * ('Master Leads'!$E:$E>=IF(ISBLANK($B$5),0,$B$5)) * ('Master Leads'!$E:$E<=IF(ISBLANK($D$5),99999,$D$5)))) | D23: =IF($A23="","",SUMPRODUCT(('Master Leads'!$D:$D=$A23) * (ISNUMBER(SEARCH("8", 'Master Leads'!$G:$G))) * ('Master Leads'!$E:$E>=IF(ISBLANK($B$5),0,$B$5)) * ('Master Leads'!$E:$E<=IF(ISBLANK($D$5),99999,$D$5)))) | E23: =IF($A23="","",SUMPRODUCT(('Master Leads'!$D:$D=$A23) * (ISNUMBER(SEARCH("9", 'Master Leads'!$G:$G))) * ('Master Leads'!$E:$E>=IF(ISBLANK($B$5),0,$B$5)) * ('Master Leads'!$E:$E<=IF(ISBLANK($D$5),99999,$D$5)))) | F23: =IF($A23="","",SUMPRODUCT(('Master Leads'!$D:$D=$A23) * (ISNUMBER(SEARCH("10", 'Master Leads'!$G:$G))) * ('Master Leads'!$E:$E>=IF(ISBLANK($B$5),0,$B$5)) * ('Master Leads'!$E:$E<=IF(ISBLANK($D$5),99999,$D$5)))) | G23: =IF($A23="","",SUMPRODUCT(('Master Leads'!$D:$D=$A23) * (ISNUMBER(SEARCH("11", 'Master Leads'!$G:$G))) * ('Master Leads'!$E:$E>=IF(ISBLANK($B$5),0,$B$5)) * ('Master Leads'!$E:$E<=IF(ISBLANK($D$5),99999,$D$5)))) | H23: =IF($A23="","",COUNTIFS('Master Leads'!$D:$D,$A23,'Master Leads'!$E:$E,">="&IF(ISBLANK($B$5),0,$B$5),'Master Leads'!$E:$E,"<="&IF(ISBLANK($D$5),99999,$D$5))) | I23: =IF(OR($A23="",$H$29=0),"",H23/$H$29)
A24: =IF(INDEX(Members!$A:$A,17)="","",INDEX(Members!$A:$A,17)) | B24: =IF($A24="","",SUMPRODUCT(('Master Leads'!$D:$D=$A24) * (ISNUMBER(SEARCH("6", 'Master Leads'!$G:$G))) * ('Master Leads'!$E:$E>=IF(ISBLANK($B$5),0,$B$5)) * ('Master Leads'!$E:$E<=IF(ISBLANK($D$5),99999,$D$5)))) | C24: =IF($A24="","",SUMPRODUCT(('Master Leads'!$D:$D=$A24) * (ISNUMBER(SEARCH("7", 'Master Leads'!$G:$G))) * ('Master Leads'!$E:$E>=IF(ISBLANK($B$5),0,$B$5)) * ('Master Leads'!$E:$E<=IF(ISBLANK($D$5),99999,$D$5)))) | D24: =IF($A24="","",SUMPRODUCT(('Master Leads'!$D:$D=$A24) * (ISNUMBER(SEARCH("8", 'Master Leads'!$G:$G))) * ('Master Leads'!$E:$E>=IF(ISBLANK($B$5),0,$B$5)) * ('Master Leads'!$E:$E<=IF(ISBLANK($D$5),99999,$D$5)))) | E24: =IF($A24="","",SUMPRODUCT(('Master Leads'!$D:$D=$A24) * (ISNUMBER(SEARCH("9", 'Master Leads'!$G:$G))) * ('Master Leads'!$E:$E>=IF(ISBLANK($B$5),0,$B$5)) * ('Master Leads'!$E:$E<=IF(ISBLANK($D$5),99999,$D$5)))) | F24: =IF($A24="","",SUMPRODUCT(('Master Leads'!$D:$D=$A24) * (ISNUMBER(SEARCH("10", 'Master Leads'!$G:$G))) * ('Master Leads'!$E:$E>=IF(ISBLANK($B$5),0,$B$5)) * ('Master Leads'!$E:$E<=IF(ISBLANK($D$5),99999,$D$5)))) | G24: =IF($A24="","",SUMPRODUCT(('Master Leads'!$D:$D=$A24) * (ISNUMBER(SEARCH("11", 'Master Leads'!$G:$G))) * ('Master Leads'!$E:$E>=IF(ISBLANK($B$5),0,$B$5)) * ('Master Leads'!$E:$E<=IF(ISBLANK($D$5),99999,$D$5)))) | H24: =IF($A24="","",COUNTIFS('Master Leads'!$D:$D,$A24,'Master Leads'!$E:$E,">="&IF(ISBLANK($B$5),0,$B$5),'Master Leads'!$E:$E,"<="&IF(ISBLANK($D$5),99999,$D$5))) | I24: =IF(OR($A24="",$H$29=0),"",H24/$H$29)
A25: =IF(INDEX(Members!$A:$A,18)="","",INDEX(Members!$A:$A,18)) | B25: =IF($A25="","",SUMPRODUCT(('Master Leads'!$D:$D=$A25) * (ISNUMBER(SEARCH("6", 'Master Leads'!$G:$G))) * ('Master Leads'!$E:$E>=IF(ISBLANK($B$5),0,$B$5)) * ('Master Leads'!$E:$E<=IF(ISBLANK($D$5),99999,$D$5)))) | C25: =IF($A25="","",SUMPRODUCT(('Master Leads'!$D:$D=$A25) * (ISNUMBER(SEARCH("7", 'Master Leads'!$G:$G))) * ('Master Leads'!$E:$E>=IF(ISBLANK($B$5),0,$B$5)) * ('Master Leads'!$E:$E<=IF(ISBLANK($D$5),99999,$D$5)))) | D25: =IF($A25="","",SUMPRODUCT(('Master Leads'!$D:$D=$A25) * (ISNUMBER(SEARCH("8", 'Master Leads'!$G:$G))) * ('Master Leads'!$E:$E>=IF(ISBLANK($B$5),0,$B$5)) * ('Master Leads'!$E:$E<=IF(ISBLANK($D$5),99999,$D$5)))) | E25: =IF($A25="","",SUMPRODUCT(('Master Leads'!$D:$D=$A25) * (ISNUMBER(SEARCH("9", 'Master Leads'!$G:$G))) * ('Master Leads'!$E:$E>=IF(ISBLANK($B$5),0,$B$5)) * ('Master Leads'!$E:$E<=IF(ISBLANK($D$5),99999,$D$5)))) | F25: =IF($A25="","",SUMPRODUCT(('Master Leads'!$D:$D=$A25) * (ISNUMBER(SEARCH("10", 'Master Leads'!$G:$G))) * ('Master Leads'!$E:$E>=IF(ISBLANK($B$5),0,$B$5)) * ('Master Leads'!$E:$E<=IF(ISBLANK($D$5),99999,$D$5)))) | G25: =IF($A25="","",SUMPRODUCT(('Master Leads'!$D:$D=$A25) * (ISNUMBER(SEARCH("11", 'Master Leads'!$G:$G))) * ('Master Leads'!$E:$E>=IF(ISBLANK($B$5),0,$B$5)) * ('Master Leads'!$E:$E<=IF(ISBLANK($D$5),99999,$D$5)))) | H25: =IF($A25="","",COUNTIFS('Master Leads'!$D:$D,$A25,'Master Leads'!$E:$E,">="&IF(ISBLANK($B$5),0,$B$5),'Master Leads'!$E:$E,"<="&IF(ISBLANK($D$5),99999,$D$5))) | I25: =IF(OR($A25="",$H$29=0),"",H25/$H$29)
A26: =IF(INDEX(Members!$A:$A,19)="","",INDEX(Members!$A:$A,19)) | B26: =IF($A26="","",SUMPRODUCT(('Master Leads'!$D:$D=$A26) * (ISNUMBER(SEARCH("6", 'Master Leads'!$G:$G))) * ('Master Leads'!$E:$E>=IF(ISBLANK($B$5),0,$B$5)) * ('Master Leads'!$E:$E<=IF(ISBLANK($D$5),99999,$D$5)))) | C26: =IF($A26="","",SUMPRODUCT(('Master Leads'!$D:$D=$A26) * (ISNUMBER(SEARCH("7", 'Master Leads'!$G:$G))) * ('Master Leads'!$E:$E>=IF(ISBLANK($B$5),0,$B$5)) * ('Master Leads'!$E:$E<=IF(ISBLANK($D$5),99999,$D$5)))) | D26: =IF($A26="","",SUMPRODUCT(('Master Leads'!$D:$D=$A26) * (ISNUMBER(SEARCH("8", 'Master Leads'!$G:$G))) * ('Master Leads'!$E:$E>=IF(ISBLANK($B$5),0,$B$5)) * ('Master Leads'!$E:$E<=IF(ISBLANK($D$5),99999,$D$5)))) | E26: =IF($A26="","",SUMPRODUCT(('Master Leads'!$D:$D=$A26) * (ISNUMBER(SEARCH("9", 'Master Leads'!$G:$G))) * ('Master Leads'!$E:$E>=IF(ISBLANK($B$5),0,$B$5)) * ('Master Leads'!$E:$E<=IF(ISBLANK($D$5),99999,$D$5)))) | F26: =IF($A26="","",SUMPRODUCT(('Master Leads'!$D:$D=$A26) * (ISNUMBER(SEARCH("10", 'Master Leads'!$G:$G))) * ('Master Leads'!$E:$E>=IF(ISBLANK($B$5),0,$B$5)) * ('Master Leads'!$E:$E<=IF(ISBLANK($D$5),99999,$D$5)))) | G26: =IF($A26="","",SUMPRODUCT(('Master Leads'!$D:$D=$A26) * (ISNUMBER(SEARCH("11", 'Master Leads'!$G:$G))) * ('Master Leads'!$E:$E>=IF(ISBLANK($B$5),0,$B$5)) * ('Master Leads'!$E:$E<=IF(ISBLANK($D$5),99999,$D$5)))) | H26: =IF($A26="","",COUNTIFS('Master Leads'!$D:$D,$A26,'Master Leads'!$E:$E,">="&IF(ISBLANK($B$5),0,$B$5),'Master Leads'!$E:$E,"<="&IF(ISBLANK($D$5),99999,$D$5))) | I26: =IF(OR($A26="",$H$29=0),"",H26/$H$29)
A27: =IF(INDEX(Members!$A:$A,20)="","",INDEX(Members!$A:$A,20)) | B27: =IF($A27="","",SUMPRODUCT(('Master Leads'!$D:$D=$A27) * (ISNUMBER(SEARCH("6", 'Master Leads'!$G:$G))) * ('Master Leads'!$E:$E>=IF(ISBLANK($B$5),0,$B$5)) * ('Master Leads'!$E:$E<=IF(ISBLANK($D$5),99999,$D$5)))) | C27: =IF($A27="","",SUMPRODUCT(('Master Leads'!$D:$D=$A27) * (ISNUMBER(SEARCH("7", 'Master Leads'!$G:$G))) * ('Master Leads'!$E:$E>=IF(ISBLANK($B$5),0,$B$5)) * ('Master Leads'!$E:$E<=IF(ISBLANK($D$5),99999,$D$5)))) | D27: =IF($A27="","",SUMPRODUCT(('Master Leads'!$D:$D=$A27) * (ISNUMBER(SEARCH("8", 'Master Leads'!$G:$G))) * ('Master Leads'!$E:$E>=IF(ISBLANK($B$5),0,$B$5)) * ('Master Leads'!$E:$E<=IF(ISBLANK($D$5),99999,$D$5)))) | E27: =IF($A27="","",SUMPRODUCT(('Master Leads'!$D:$D=$A27) * (ISNUMBER(SEARCH("9", 'Master Leads'!$G:$G))) * ('Master Leads'!$E:$E>=IF(ISBLANK($B$5),0,$B$5)) * ('Master Leads'!$E:$E<=IF(ISBLANK($D$5),99999,$D$5)))) | F27: =IF($A27="","",SUMPRODUCT(('Master Leads'!$D:$D=$A27) * (ISNUMBER(SEARCH("10", 'Master Leads'!$G:$G))) * ('Master Leads'!$E:$E>=IF(ISBLANK($B$5),0,$B$5)) * ('Master Leads'!$E:$E<=IF(ISBLANK($D$5),99999,$D$5)))) | G27: =IF($A27="","",SUMPRODUCT(('Master Leads'!$D:$D=$A27) * (ISNUMBER(SEARCH("11", 'Master Leads'!$G:$G))) * ('Master Leads'!$E:$E>=IF(ISBLANK($B$5),0,$B$5)) * ('Master Leads'!$E:$E<=IF(ISBLANK($D$5),99999,$D$5)))) | H27: =IF($A27="","",COUNTIFS('Master Leads'!$D:$D,$A27,'Master Leads'!$E:$E,">="&IF(ISBLANK($B$5),0,$B$5),'Master Leads'!$E:$E,"<="&IF(ISBLANK($D$5),99999,$D$5))) | I27: =IF(OR($A27="",$H$29=0),"",H27/$H$29)
A28: =IF(INDEX(Members!$A:$A,21)="","",INDEX(Members!$A:$A,21)) | B28: =IF($A28="","",SUMPRODUCT(('Master Leads'!$D:$D=$A28) * (ISNUMBER(SEARCH("6", 'Master Leads'!$G:$G))) * ('Master Leads'!$E:$E>=IF(ISBLANK($B$5),0,$B$5)) * ('Master Leads'!$E:$E<=IF(ISBLANK($D$5),99999,$D$5)))) | C28: =IF($A28="","",SUMPRODUCT(('Master Leads'!$D:$D=$A28) * (ISNUMBER(SEARCH("7", 'Master Leads'!$G:$G))) * ('Master Leads'!$E:$E>=IF(ISBLANK($B$5),0,$B$5)) * ('Master Leads'!$E:$E<=IF(ISBLANK($D$5),99999,$D$5)))) | D28: =IF($A28="","",SUMPRODUCT(('Master Leads'!$D:$D=$A28) * (ISNUMBER(SEARCH("8", 'Master Leads'!$G:$G))) * ('Master Leads'!$E:$E>=IF(ISBLANK($B$5),0,$B$5)) * ('Master Leads'!$E:$E<=IF(ISBLANK($D$5),99999,$D$5)))) | E28: =IF($A28="","",SUMPRODUCT(('Master Leads'!$D:$D=$A28) * (ISNUMBER(SEARCH("9", 'Master Leads'!$G:$G))) * ('Master Leads'!$E:$E>=IF(ISBLANK($B$5),0,$B$5)) * ('Master Leads'!$E:$E<=IF(ISBLANK($D$5),99999,$D$5)))) | F28: =IF($A28="","",SUMPRODUCT(('Master Leads'!$D:$D=$A28) * (ISNUMBER(SEARCH("10", 'Master Leads'!$G:$G))) * ('Master Leads'!$E:$E>=IF(ISBLANK($B$5),0,$B$5)) * ('Master Leads'!$E:$E<=IF(ISBLANK($D$5),99999,$D$5)))) | G28: =IF($A28="","",SUMPRODUCT(('Master Leads'!$D:$D=$A28) * (ISNUMBER(SEARCH("11", 'Master Leads'!$G:$G))) * ('Master Leads'!$E:$E>=IF(ISBLANK($B$5),0,$B$5)) * ('Master Leads'!$E:$E<=IF(ISBLANK($D$5),99999,$D$5)))) | H28: =IF($A28="","",COUNTIFS('Master Leads'!$D:$D,$A28,'Master Leads'!$E:$E,">="&IF(ISBLANK($B$5),0,$B$5),'Master Leads'!$E:$E,"<="&IF(ISBLANK($D$5),99999,$D$5))) | I28: =IF(OR($A28="",$H$29=0),"",H28/$H$29)
A29: TOTAL | B29: =SUMPRODUCT((ISNUMBER(SEARCH("6", 'Master Leads'!$G:$G))) * ('Master Leads'!$E:$E>=IF(ISBLANK($B$5),0,$B$5)) * ('Master Leads'!$E:$E<=IF(ISBLANK($D$5),99999,$D$5))) | C29: =SUMPRODUCT((ISNUMBER(SEARCH("7", 'Master Leads'!$G:$G))) * ('Master Leads'!$E:$E>=IF(ISBLANK($B$5),0,$B$5)) * ('Master Leads'!$E:$E<=IF(ISBLANK($D$5),99999,$D$5))) | D29: =SUMPRODUCT((ISNUMBER(SEARCH("8", 'Master Leads'!$G:$G))) * ('Master Leads'!$E:$E>=IF(ISBLANK($B$5),0,$B$5)) * ('Master Leads'!$E:$E<=IF(ISBLANK($D$5),99999,$D$5))) | E29: =SUMPRODUCT((ISNUMBER(SEARCH("9", 'Master Leads'!$G:$G))) * ('Master Leads'!$E:$E>=IF(ISBLANK($B$5),0,$B$5)) * ('Master Leads'!$E:$E<=IF(ISBLANK($D$5),99999,$D$5))) | F29: =SUMPRODUCT((ISNUMBER(SEARCH("10", 'Master Leads'!$G:$G))) * ('Master Leads'!$E:$E>=IF(ISBLANK($B$5),0,$B$5)) * ('Master Leads'!$E:$E<=IF(ISBLANK($D$5),99999,$D$5))) | G29: =SUMPRODUCT((ISNUMBER(SEARCH("11", 'Master Leads'!$G:$G))) * ('Master Leads'!$E:$E>=IF(ISBLANK($B$5),0,$B$5)) * ('Master Leads'!$E:$E<=IF(ISBLANK($D$5),99999,$D$5))) | H29: =COUNTIFS('Master Leads'!$D:$D,"<>",'Master Leads'!$E:$E,">="&IF(ISBLANK($B$5),0,$B$5),'Master Leads'!$E:$E,"<="&IF(ISBLANK($D$5),99999,$D$5)) | I29: 1
A32: TABLE 2: PAID LEADS BY MEMBER & GRADE
A33: Assigned Member | B33: Grade 6 | C33: Grade 7 | D33: Grade 8 | E33: Grade 9 | F33: Grade 10 | G33: Grade 11 | H33: Total Paid | I33: Paid Share % | J33: Conversion %
A34: =IF(INDEX(Members!$A:$A,2)="","",INDEX(Members!$A:$A,2)) | B34: =IF($A34="","",SUMPRODUCT(('Master Leads'!$D:$D=$A34) * (ISNUMBER(SEARCH("6", 'Master Leads'!$P:$P))) * ('Master Leads'!$O:$O="Yes") * ('Master Leads'!$E:$E>=IF(ISBLANK($B$5),0,$B$5)) * ('Master Leads'!$E:$E<=IF(ISBLANK($D$5),99999,$D$5)))) | C34: =IF($A34="","",SUMPRODUCT(('Master Leads'!$D:$D=$A34) * (ISNUMBER(SEARCH("7", 'Master Leads'!$P:$P))) * ('Master Leads'!$O:$O="Yes") * ('Master Leads'!$E:$E>=IF(ISBLANK($B$5),0,$B$5)) * ('Master Leads'!$E:$E<=IF(ISBLANK($D$5),99999,$D$5)))) | D34: =IF($A34="","",SUMPRODUCT(('Master Leads'!$D:$D=$A34) * (ISNUMBER(SEARCH("8", 'Master Leads'!$P:$P))) * ('Master Leads'!$O:$O="Yes") * ('Master Leads'!$E:$E>=IF(ISBLANK($B$5),0,$B$5)) * ('Master Leads'!$E:$E<=IF(ISBLANK($D$5),99999,$D$5)))) | E34: =IF($A34="","",SUMPRODUCT(('Master Leads'!$D:$D=$A34) * (ISNUMBER(SEARCH("9", 'Master Leads'!$P:$P))) * ('Master Leads'!$O:$O="Yes") * ('Master Leads'!$E:$E>=IF(ISBLANK($B$5),0,$B$5)) * ('Master Leads'!$E:$E<=IF(ISBLANK($D$5),99999,$D$5)))) | F34: =IF($A34="","",SUMPRODUCT(('Master Leads'!$D:$D=$A34) * (ISNUMBER(SEARCH("10", 'Master Leads'!$P:$P))) * ('Master Leads'!$O:$O="Yes") * ('Master Leads'!$E:$E>=IF(ISBLANK($B$5),0,$B$5)) * ('Master Leads'!$E:$E<=IF(ISBLANK($D$5),99999,$D$5)))) | G34: =IF($A34="","",SUMPRODUCT(('Master Leads'!$D:$D=$A34) * (ISNUMBER(SEARCH("11", 'Master Leads'!$P:$P))) * ('Master Leads'!$O:$O="Yes") * ('Master Leads'!$E:$E>=IF(ISBLANK($B$5),0,$B$5)) * ('Master Leads'!$E:$E<=IF(ISBLANK($D$5),99999,$D$5)))) | H34: =IF($A34="","",SUM(B34:G34)) | I34: =IF(OR($A34="",$H$54=0),"",H34/$H$54) | J34: =IF(OR($A34="",H9=0),"",H34/H9)
A35: =IF(INDEX(Members!$A:$A,3)="","",INDEX(Members!$A:$A,3)) | B35: =IF($A35="","",SUMPRODUCT(('Master Leads'!$D:$D=$A35) * (ISNUMBER(SEARCH("6", 'Master Leads'!$P:$P))) * ('Master Leads'!$O:$O="Yes") * ('Master Leads'!$E:$E>=IF(ISBLANK($B$5),0,$B$5)) * ('Master Leads'!$E:$E<=IF(ISBLANK($D$5),99999,$D$5)))) | C35: =IF($A35="","",SUMPRODUCT(('Master Leads'!$D:$D=$A35) * (ISNUMBER(SEARCH("7", 'Master Leads'!$P:$P))) * ('Master Leads'!$O:$O="Yes") * ('Master Leads'!$E:$E>=IF(ISBLANK($B$5),0,$B$5)) * ('Master Leads'!$E:$E<=IF(ISBLANK($D$5),99999,$D$5)))) | D35: =IF($A35="","",SUMPRODUCT(('Master Leads'!$D:$D=$A35) * (ISNUMBER(SEARCH("8", 'Master Leads'!$P:$P))) * ('Master Leads'!$O:$O="Yes") * ('Master Leads'!$E:$E>=IF(ISBLANK($B$5),0,$B$5)) * ('Master Leads'!$E:$E<=IF(ISBLANK($D$5),99999,$D$5)))) | E35: =IF($A35="","",SUMPRODUCT(('Master Leads'!$D:$D=$A35) * (ISNUMBER(SEARCH("9", 'Master Leads'!$P:$P))) * ('Master Leads'!$O:$O="Yes") * ('Master Leads'!$E:$E>=IF(ISBLANK($B$5),0,$B$5)) * ('Master Leads'!$E:$E<=IF(ISBLANK($D$5),99999,$D$5)))) | F35: =IF($A35="","",SUMPRODUCT(('Master Leads'!$D:$D=$A35) * (ISNUMBER(SEARCH("10", 'Master Leads'!$P:$P))) * ('Master Leads'!$O:$O="Yes") * ('Master Leads'!$E:$E>=IF(ISBLANK($B$5),0,$B$5)) * ('Master Leads'!$E:$E<=IF(ISBLANK($D$5),99999,$D$5)))) | G35: =IF($A35="","",SUMPRODUCT(('Master Leads'!$D:$D=$A35) * (ISNUMBER(SEARCH("11", 'Master Leads'!$P:$P))) * ('Master Leads'!$O:$O="Yes") * ('Master Leads'!$E:$E>=IF(ISBLANK($B$5),0,$B$5)) * ('Master Leads'!$E:$E<=IF(ISBLANK($D$5),99999,$D$5)))) | H35: =IF($A35="","",SUM(B35:G35)) | I35: =IF(OR($A35="",$H$54=0),"",H35/$H$54) | J35: =IF(OR($A35="",H10=0),"",H35/H10)
A36: =IF(INDEX(Members!$A:$A,4)="","",INDEX(Members!$A:$A,4)) | B36: =IF($A36="","",SUMPRODUCT(('Master Leads'!$D:$D=$A36) * (ISNUMBER(SEARCH("6", 'Master Leads'!$P:$P))) * ('Master Leads'!$O:$O="Yes") * ('Master Leads'!$E:$E>=IF(ISBLANK($B$5),0,$B$5)) * ('Master Leads'!$E:$E<=IF(ISBLANK($D$5),99999,$D$5)))) | C36: =IF($A36="","",SUMPRODUCT(('Master Leads'!$D:$D=$A36) * (ISNUMBER(SEARCH("7", 'Master Leads'!$P:$P))) * ('Master Leads'!$O:$O="Yes") * ('Master Leads'!$E:$E>=IF(ISBLANK($B$5),0,$B$5)) * ('Master Leads'!$E:$E<=IF(ISBLANK($D$5),99999,$D$5)))) | D36: =IF($A36="","",SUMPRODUCT(('Master Leads'!$D:$D=$A36) * (ISNUMBER(SEARCH("8", 'Master Leads'!$P:$P))) * ('Master Leads'!$O:$O="Yes") * ('Master Leads'!$E:$E>=IF(ISBLANK($B$5),0,$B$5)) * ('Master Leads'!$E:$E<=IF(ISBLANK($D$5),99999,$D$5)))) | E36: =IF($A36="","",SUMPRODUCT(('Master Leads'!$D:$D=$A36) * (ISNUMBER(SEARCH("9", 'Master Leads'!$P:$P))) * ('Master Leads'!$O:$O="Yes") * ('Master Leads'!$E:$E>=IF(ISBLANK($B$5),0,$B$5)) * ('Master Leads'!$E:$E<=IF(ISBLANK($D$5),99999,$D$5)))) | F36: =IF($A36="","",SUMPRODUCT(('Master Leads'!$D:$D=$A36) * (ISNUMBER(SEARCH("10", 'Master Leads'!$P:$P))) * ('Master Leads'!$O:$O="Yes") * ('Master Leads'!$E:$E>=IF(ISBLANK($B$5),0,$B$5)) * ('Master Leads'!$E:$E<=IF(ISBLANK($D$5),99999,$D$5)))) | G36: =IF($A36="","",SUMPRODUCT(('Master Leads'!$D:$D=$A36) * (ISNUMBER(SEARCH("11", 'Master Leads'!$P:$P))) * ('Master Leads'!$O:$O="Yes") * ('Master Leads'!$E:$E>=IF(ISBLANK($B$5),0,$B$5)) * ('Master Leads'!$E:$E<=IF(ISBLANK($D$5),99999,$D$5)))) | H36: =IF($A36="","",SUM(B36:G36)) | I36: =IF(OR($A36="",$H$54=0),"",H36/$H$54) | J36: =IF(OR($A36="",H11=0),"",H36/H11)
A37: =IF(INDEX(Members!$A:$A,5)="","",INDEX(Members!$A:$A,5)) | B37: =IF($A37="","",SUMPRODUCT(('Master Leads'!$D:$D=$A37) * (ISNUMBER(SEARCH("6", 'Master Leads'!$P:$P))) * ('Master Leads'!$O:$O="Yes") * ('Master Leads'!$E:$E>=IF(ISBLANK($B$5),0,$B$5)) * ('Master Leads'!$E:$E<=IF(ISBLANK($D$5),99999,$D$5)))) | C37: =IF($A37="","",SUMPRODUCT(('Master Leads'!$D:$D=$A37) * (ISNUMBER(SEARCH("7", 'Master Leads'!$P:$P))) * ('Master Leads'!$O:$O="Yes") * ('Master Leads'!$E:$E>=IF(ISBLANK($B$5),0,$B$5)) * ('Master Leads'!$E:$E<=IF(ISBLANK($D$5),99999,$D$5)))) | D37: =IF($A37="","",SUMPRODUCT(('Master Leads'!$D:$D=$A37) * (ISNUMBER(SEARCH("8", 'Master Leads'!$P:$P))) * ('Master Leads'!$O:$O="Yes") * ('Master Leads'!$E:$E>=IF(ISBLANK($B$5),0,$B$5)) * ('Master Leads'!$E:$E<=IF(ISBLANK($D$5),99999,$D$5)))) | E37: =IF($A37="","",SUMPRODUCT(('Master Leads'!$D:$D=$A37) * (ISNUMBER(SEARCH("9", 'Master Leads'!$P:$P))) * ('Master Leads'!$O:$O="Yes") * ('Master Leads'!$E:$E>=IF(ISBLANK($B$5),0,$B$5)) * ('Master Leads'!$E:$E<=IF(ISBLANK($D$5),99999,$D$5)))) | F37: =IF($A37="","",SUMPRODUCT(('Master Leads'!$D:$D=$A37) * (ISNUMBER(SEARCH("10", 'Master Leads'!$P:$P))) * ('Master Leads'!$O:$O="Yes") * ('Master Leads'!$E:$E>=IF(ISBLANK($B$5),0,$B$5)) * ('Master Leads'!$E:$E<=IF(ISBLANK($D$5),99999,$D$5)))) | G37: =IF($A37="","",SUMPRODUCT(('Master Leads'!$D:$D=$A37) * (ISNUMBER(SEARCH("11", 'Master Leads'!$P:$P))) * ('Master Leads'!$O:$O="Yes") * ('Master Leads'!$E:$E>=IF(ISBLANK($B$5),0,$B$5)) * ('Master Leads'!$E:$E<=IF(ISBLANK($D$5),99999,$D$5)))) | H37: =IF($A37="","",SUM(B37:G37)) | I37: =IF(OR($A37="",$H$54=0),"",H37/$H$54) | J37: =IF(OR($A37="",H12=0),"",H37/H12)
A38: =IF(INDEX(Members!$A:$A,6)="","",INDEX(Members!$A:$A,6)) | B38: =IF($A38="","",SUMPRODUCT(('Master Leads'!$D:$D=$A38) * (ISNUMBER(SEARCH("6", 'Master Leads'!$P:$P))) * ('Master Leads'!$O:$O="Yes") * ('Master Leads'!$E:$E>=IF(ISBLANK($B$5),0,$B$5)) * ('Master Leads'!$E:$E<=IF(ISBLANK($D$5),99999,$D$5)))) | C38: =IF($A38="","",SUMPRODUCT(('Master Leads'!$D:$D=$A38) * (ISNUMBER(SEARCH("7", 'Master Leads'!$P:$P))) * ('Master Leads'!$O:$O="Yes") * ('Master Leads'!$E:$E>=IF(ISBLANK($B$5),0,$B$5)) * ('Master Leads'!$E:$E<=IF(ISBLANK($D$5),99999,$D$5)))) | D38: =IF($A38="","",SUMPRODUCT(('Master Leads'!$D:$D=$A38) * (ISNUMBER(SEARCH("8", 'Master Leads'!$P:$P))) * ('Master Leads'!$O:$O="Yes") * ('Master Leads'!$E:$E>=IF(ISBLANK($B$5),0,$B$5)) * ('Master Leads'!$E:$E<=IF(ISBLANK($D$5),99999,$D$5)))) | E38: =IF($A38="","",SUMPRODUCT(('Master Leads'!$D:$D=$A38) * (ISNUMBER(SEARCH("9", 'Master Leads'!$P:$P))) * ('Master Leads'!$O:$O="Yes") * ('Master Leads'!$E:$E>=IF(ISBLANK($B$5),0,$B$5)) * ('Master Leads'!$E:$E<=IF(ISBLANK($D$5),99999,$D$5)))) | F38: =IF($A38="","",SUMPRODUCT(('Master Leads'!$D:$D=$A38) * (ISNUMBER(SEARCH("10", 'Master Leads'!$P:$P))) * ('Master Leads'!$O:$O="Yes") * ('Master Leads'!$E:$E>=IF(ISBLANK($B$5),0,$B$5)) * ('Master Leads'!$E:$E<=IF(ISBLANK($D$5),99999,$D$5)))) | G38: =IF($A38="","",SUMPRODUCT(('Master Leads'!$D:$D=$A38) * (ISNUMBER(SEARCH("11", 'Master Leads'!$P:$P))) * ('Master Leads'!$O:$O="Yes") * ('Master Leads'!$E:$E>=IF(ISBLANK($B$5),0,$B$5)) * ('Master Leads'!$E:$E<=IF(ISBLANK($D$5),99999,$D$5)))) | H38: =IF($A38="","",SUM(B38:G38)) | I38: =IF(OR($A38="",$H$54=0),"",H38/$H$54) | J38: =IF(OR($A38="",H13=0),"",H38/H13)
A39: =IF(INDEX(Members!$A:$A,7)="","",INDEX(Members!$A:$A,7)) | B39: =IF($A39="","",SUMPRODUCT(('Master Leads'!$D:$D=$A39) * (ISNUMBER(SEARCH("6", 'Master Leads'!$P:$P))) * ('Master Leads'!$O:$O="Yes") * ('Master Leads'!$E:$E>=IF(ISBLANK($B$5),0,$B$5)) * ('Master Leads'!$E:$E<=IF(ISBLANK($D$5),99999,$D$5)))) | C39: =IF($A39="","",SUMPRODUCT(('Master Leads'!$D:$D=$A39) * (ISNUMBER(SEARCH("7", 'Master Leads'!$P:$P))) * ('Master Leads'!$O:$O="Yes") * ('Master Leads'!$E:$E>=IF(ISBLANK($B$5),0,$B$5)) * ('Master Leads'!$E:$E<=IF(ISBLANK($D$5),99999,$D$5)))) | D39: =IF($A39="","",SUMPRODUCT(('Master Leads'!$D:$D=$A39) * (ISNUMBER(SEARCH("8", 'Master Leads'!$P:$P))) * ('Master Leads'!$O:$O="Yes") * ('Master Leads'!$E:$E>=IF(ISBLANK($B$5),0,$B$5)) * ('Master Leads'!$E:$E<=IF(ISBLANK($D$5),99999,$D$5)))) | E39: =IF($A39="","",SUMPRODUCT(('Master Leads'!$D:$D=$A39) * (ISNUMBER(SEARCH("9", 'Master Leads'!$P:$P))) * ('Master Leads'!$O:$O="Yes") * ('Master Leads'!$E:$E>=IF(ISBLANK($B$5),0,$B$5)) * ('Master Leads'!$E:$E<=IF(ISBLANK($D$5),99999,$D$5)))) | F39: =IF($A39="","",SUMPRODUCT(('Master Leads'!$D:$D=$A39) * (ISNUMBER(SEARCH("10", 'Master Leads'!$P:$P))) * ('Master Leads'!$O:$O="Yes") * ('Master Leads'!$E:$E>=IF(ISBLANK($B$5),0,$B$5)) * ('Master Leads'!$E:$E<=IF(ISBLANK($D$5),99999,$D$5)))) | G39: =IF($A39="","",SUMPRODUCT(('Master Leads'!$D:$D=$A39) * (ISNUMBER(SEARCH("11", 'Master Leads'!$P:$P))) * ('Master Leads'!$O:$O="Yes") * ('Master Leads'!$E:$E>=IF(ISBLANK($B$5),0,$B$5)) * ('Master Leads'!$E:$E<=IF(ISBLANK($D$5),99999,$D$5)))) | H39: =IF($A39="","",SUM(B39:G39)) | I39: =IF(OR($A39="",$H$54=0),"",H39/$H$54) | J39: =IF(OR($A39="",H14=0),"",H39/H14)
A40: =IF(INDEX(Members!$A:$A,8)="","",INDEX(Members!$A:$A,8)) | B40: =IF($A40="","",SUMPRODUCT(('Master Leads'!$D:$D=$A40) * (ISNUMBER(SEARCH("6", 'Master Leads'!$P:$P))) * ('Master Leads'!$O:$O="Yes") * ('Master Leads'!$E:$E>=IF(ISBLANK($B$5),0,$B$5)) * ('Master Leads'!$E:$E<=IF(ISBLANK($D$5),99999,$D$5)))) | C40: =IF($A40="","",SUMPRODUCT(('Master Leads'!$D:$D=$A40) * (ISNUMBER(SEARCH("7", 'Master Leads'!$P:$P))) * ('Master Leads'!$O:$O="Yes") * ('Master Leads'!$E:$E>=IF(ISBLANK($B$5),0,$B$5)) * ('Master Leads'!$E:$E<=IF(ISBLANK($D$5),99999,$D$5)))) | D40: =IF($A40="","",SUMPRODUCT(('Master Leads'!$D:$D=$A40) * (ISNUMBER(SEARCH("8", 'Master Leads'!$P:$P))) * ('Master Leads'!$O:$O="Yes") * ('Master Leads'!$E:$E>=IF(ISBLANK($B$5),0,$B$5)) * ('Master Leads'!$E:$E<=IF(ISBLANK($D$5),99999,$D$5)))) | E40: =IF($A40="","",SUMPRODUCT(('Master Leads'!$D:$D=$A40) * (ISNUMBER(SEARCH("9", 'Master Leads'!$P:$P))) * ('Master Leads'!$O:$O="Yes") * ('Master Leads'!$E:$E>=IF(ISBLANK($B$5),0,$B$5)) * ('Master Leads'!$E:$E<=IF(ISBLANK($D$5),99999,$D$5)))) | F40: =IF($A40="","",SUMPRODUCT(('Master Leads'!$D:$D=$A40) * (ISNUMBER(SEARCH("10", 'Master Leads'!$P:$P))) * ('Master Leads'!$O:$O="Yes") * ('Master Leads'!$E:$E>=IF(ISBLANK($B$5),0,$B$5)) * ('Master Leads'!$E:$E<=IF(ISBLANK($D$5),99999,$D$5)))) | G40: =IF($A40="","",SUMPRODUCT(('Master Leads'!$D:$D=$A40) * (ISNUMBER(SEARCH("11", 'Master Leads'!$P:$P))) * ('Master Leads'!$O:$O="Yes") * ('Master Leads'!$E:$E>=IF(ISBLANK($B$5),0,$B$5)) * ('Master Leads'!$E:$E<=IF(ISBLANK($D$5),99999,$D$5)))) | H40: =IF($A40="","",SUM(B40:G40)) | I40: =IF(OR($A40="",$H$54=0),"",H40/$H$54) | J40: =IF(OR($A40="",H15=0),"",H40/H15)
A41: =IF(INDEX(Members!$A:$A,9)="","",INDEX(Members!$A:$A,9)) | B41: =IF($A41="","",SUMPRODUCT(('Master Leads'!$D:$D=$A41) * (ISNUMBER(SEARCH("6", 'Master Leads'!$P:$P))) * ('Master Leads'!$O:$O="Yes") * ('Master Leads'!$E:$E>=IF(ISBLANK($B$5),0,$B$5)) * ('Master Leads'!$E:$E<=IF(ISBLANK($D$5),99999,$D$5)))) | C41: =IF($A41="","",SUMPRODUCT(('Master Leads'!$D:$D=$A41) * (ISNUMBER(SEARCH("7", 'Master Leads'!$P:$P))) * ('Master Leads'!$O:$O="Yes") * ('Master Leads'!$E:$E>=IF(ISBLANK($B$5),0,$B$5)) * ('Master Leads'!$E:$E<=IF(ISBLANK($D$5),99999,$D$5)))) | D41: =IF($A41="","",SUMPRODUCT(('Master Leads'!$D:$D=$A41) * (ISNUMBER(SEARCH("8", 'Master Leads'!$P:$P))) * ('Master Leads'!$O:$O="Yes") * ('Master Leads'!$E:$E>=IF(ISBLANK($B$5),0,$B$5)) * ('Master Leads'!$E:$E<=IF(ISBLANK($D$5),99999,$D$5)))) | E41: =IF($A41="","",SUMPRODUCT(('Master Leads'!$D:$D=$A41) * (ISNUMBER(SEARCH("9", 'Master Leads'!$P:$P))) * ('Master Leads'!$O:$O="Yes") * ('Master Leads'!$E:$E>=IF(ISBLANK($B$5),0,$B$5)) * ('Master Leads'!$E:$E<=IF(ISBLANK($D$5),99999,$D$5)))) | F41: =IF($A41="","",SUMPRODUCT(('Master Leads'!$D:$D=$A41) * (ISNUMBER(SEARCH("10", 'Master Leads'!$P:$P))) * ('Master Leads'!$O:$O="Yes") * ('Master Leads'!$E:$E>=IF(ISBLANK($B$5),0,$B$5)) * ('Master Leads'!$E:$E<=IF(ISBLANK($D$5),99999,$D$5)))) | G41: =IF($A41="","",SUMPRODUCT(('Master Leads'!$D:$D=$A41) * (ISNUMBER(SEARCH("11", 'Master Leads'!$P:$P))) * ('Master Leads'!$O:$O="Yes") * ('Master Leads'!$E:$E>=IF(ISBLANK($B$5),0,$B$5)) * ('Master Leads'!$E:$E<=IF(ISBLANK($D$5),99999,$D$5)))) | H41: =IF($A41="","",SUM(B41:G41)) | I41: =IF(OR($A41="",$H$54=0),"",H41/$H$54) | J41: =IF(OR($A41="",H16=0),"",H41/H16)
A42: =IF(INDEX(Members!$A:$A,10)="","",INDEX(Members!$A:$A,10)) | B42: =IF($A42="","",SUMPRODUCT(('Master Leads'!$D:$D=$A42) * (ISNUMBER(SEARCH("6", 'Master Leads'!$P:$P))) * ('Master Leads'!$O:$O="Yes") * ('Master Leads'!$E:$E>=IF(ISBLANK($B$5),0,$B$5)) * ('Master Leads'!$E:$E<=IF(ISBLANK($D$5),99999,$D$5)))) | C42: =IF($A42="","",SUMPRODUCT(('Master Leads'!$D:$D=$A42) * (ISNUMBER(SEARCH("7", 'Master Leads'!$P:$P))) * ('Master Leads'!$O:$O="Yes") * ('Master Leads'!$E:$E>=IF(ISBLANK($B$5),0,$B$5)) * ('Master Leads'!$E:$E<=IF(ISBLANK($D$5),99999,$D$5)))) | D42: =IF($A42="","",SUMPRODUCT(('Master Leads'!$D:$D=$A42) * (ISNUMBER(SEARCH("8", 'Master Leads'!$P:$P))) * ('Master Leads'!$O:$O="Yes") * ('Master Leads'!$E:$E>=IF(ISBLANK($B$5),0,$B$5)) * ('Master Leads'!$E:$E<=IF(ISBLANK($D$5),99999,$D$5)))) | E42: =IF($A42="","",SUMPRODUCT(('Master Leads'!$D:$D=$A42) * (ISNUMBER(SEARCH("9", 'Master Leads'!$P:$P))) * ('Master Leads'!$O:$O="Yes") * ('Master Leads'!$E:$E>=IF(ISBLANK($B$5),0,$B$5)) * ('Master Leads'!$E:$E<=IF(ISBLANK($D$5),99999,$D$5)))) | F42: =IF($A42="","",SUMPRODUCT(('Master Leads'!$D:$D=$A42) * (ISNUMBER(SEARCH("10", 'Master Leads'!$P:$P))) * ('Master Leads'!$O:$O="Yes") * ('Master Leads'!$E:$E>=IF(ISBLANK($B$5),0,$B$5)) * ('Master Leads'!$E:$E<=IF(ISBLANK($D$5),99999,$D$5)))) | G42: =IF($A42="","",SUMPRODUCT(('Master Leads'!$D:$D=$A42) * (ISNUMBER(SEARCH("11", 'Master Leads'!$P:$P))) * ('Master Leads'!$O:$O="Yes") * ('Master Leads'!$E:$E>=IF(ISBLANK($B$5),0,$B$5)) * ('Master Leads'!$E:$E<=IF(ISBLANK($D$5),99999,$D$5)))) | H42: =IF($A42="","",SUM(B42:G42)) | I42: =IF(OR($A42="",$H$54=0),"",H42/$H$54) | J42: =IF(OR($A42="",H17=0),"",H42/H17)
A43: =IF(INDEX(Members!$A:$A,11)="","",INDEX(Members!$A:$A,11)) | B43: =IF($A43="","",SUMPRODUCT(('Master Leads'!$D:$D=$A43) * (ISNUMBER(SEARCH("6", 'Master Leads'!$P:$P))) * ('Master Leads'!$O:$O="Yes") * ('Master Leads'!$E:$E>=IF(ISBLANK($B$5),0,$B$5)) * ('Master Leads'!$E:$E<=IF(ISBLANK($D$5),99999,$D$5)))) | C43: =IF($A43="","",SUMPRODUCT(('Master Leads'!$D:$D=$A43) * (ISNUMBER(SEARCH("7", 'Master Leads'!$P:$P))) * ('Master Leads'!$O:$O="Yes") * ('Master Leads'!$E:$E>=IF(ISBLANK($B$5),0,$B$5)) * ('Master Leads'!$E:$E<=IF(ISBLANK($D$5),99999,$D$5)))) | D43: =IF($A43="","",SUMPRODUCT(('Master Leads'!$D:$D=$A43) * (ISNUMBER(SEARCH("8", 'Master Leads'!$P:$P))) * ('Master Leads'!$O:$O="Yes") * ('Master Leads'!$E:$E>=IF(ISBLANK($B$5),0,$B$5)) * ('Master Leads'!$E:$E<=IF(ISBLANK($D$5),99999,$D$5)))) | E43: =IF($A43="","",SUMPRODUCT(('Master Leads'!$D:$D=$A43) * (ISNUMBER(SEARCH("9", 'Master Leads'!$P:$P))) * ('Master Leads'!$O:$O="Yes") * ('Master Leads'!$E:$E>=IF(ISBLANK($B$5),0,$B$5)) * ('Master Leads'!$E:$E<=IF(ISBLANK($D$5),99999,$D$5)))) | F43: =IF($A43="","",SUMPRODUCT(('Master Leads'!$D:$D=$A43) * (ISNUMBER(SEARCH("10", 'Master Leads'!$P:$P))) * ('Master Leads'!$O:$O="Yes") * ('Master Leads'!$E:$E>=IF(ISBLANK($B$5),0,$B$5)) * ('Master Leads'!$E:$E<=IF(ISBLANK($D$5),99999,$D$5)))) | G43: =IF($A43="","",SUMPRODUCT(('Master Leads'!$D:$D=$A43) * (ISNUMBER(SEARCH("11", 'Master Leads'!$P:$P))) * ('Master Leads'!$O:$O="Yes") * ('Master Leads'!$E:$E>=IF(ISBLANK($B$5),0,$B$5)) * ('Master Leads'!$E:$E<=IF(ISBLANK($D$5),99999,$D$5)))) | H43: =IF($A43="","",SUM(B43:G43)) | I43: =IF(OR($A43="",$H$54=0),"",H43/$H$54) | J43: =IF(OR($A43="",H18=0),"",H43/H18)
A44: =IF(INDEX(Members!$A:$A,12)="","",INDEX(Members!$A:$A,12)) | B44: =IF($A44="","",SUMPRODUCT(('Master Leads'!$D:$D=$A44) * (ISNUMBER(SEARCH("6", 'Master Leads'!$P:$P))) * ('Master Leads'!$O:$O="Yes") * ('Master Leads'!$E:$E>=IF(ISBLANK($B$5),0,$B$5)) * ('Master Leads'!$E:$E<=IF(ISBLANK($D$5),99999,$D$5)))) | C44: =IF($A44="","",SUMPRODUCT(('Master Leads'!$D:$D=$A44) * (ISNUMBER(SEARCH("7", 'Master Leads'!$P:$P))) * ('Master Leads'!$O:$O="Yes") * ('Master Leads'!$E:$E>=IF(ISBLANK($B$5),0,$B$5)) * ('Master Leads'!$E:$E<=IF(ISBLANK($D$5),99999,$D$5)))) | D44: =IF($A44="","",SUMPRODUCT(('Master Leads'!$D:$D=$A44) * (ISNUMBER(SEARCH("8", 'Master Leads'!$P:$P))) * ('Master Leads'!$O:$O="Yes") * ('Master Leads'!$E:$E>=IF(ISBLANK($B$5),0,$B$5)) * ('Master Leads'!$E:$E<=IF(ISBLANK($D$5),99999,$D$5)))) | E44: =IF($A44="","",SUMPRODUCT(('Master Leads'!$D:$D=$A44) * (ISNUMBER(SEARCH("9", 'Master Leads'!$P:$P))) * ('Master Leads'!$O:$O="Yes") * ('Master Leads'!$E:$E>=IF(ISBLANK($B$5),0,$B$5)) * ('Master Leads'!$E:$E<=IF(ISBLANK($D$5),99999,$D$5)))) | F44: =IF($A44="","",SUMPRODUCT(('Master Leads'!$D:$D=$A44) * (ISNUMBER(SEARCH("10", 'Master Leads'!$P:$P))) * ('Master Leads'!$O:$O="Yes") * ('Master Leads'!$E:$E>=IF(ISBLANK($B$5),0,$B$5)) * ('Master Leads'!$E:$E<=IF(ISBLANK($D$5),99999,$D$5)))) | G44: =IF($A44="","",SUMPRODUCT(('Master Leads'!$D:$D=$A44) * (ISNUMBER(SEARCH("11", 'Master Leads'!$P:$P))) * ('Master Leads'!$O:$O="Yes") * ('Master Leads'!$E:$E>=IF(ISBLANK($B$5),0,$B$5)) * ('Master Leads'!$E:$E<=IF(ISBLANK($D$5),99999,$D$5)))) | H44: =IF($A44="","",SUM(B44:G44)) | I44: =IF(OR($A44="",$H$54=0),"",H44/$H$54) | J44: =IF(OR($A44="",H19=0),"",H44/H19)
A45: =IF(INDEX(Members!$A:$A,13)="","",INDEX(Members!$A:$A,13)) | B45: =IF($A45="","",SUMPRODUCT(('Master Leads'!$D:$D=$A45) * (ISNUMBER(SEARCH("6", 'Master Leads'!$P:$P))) * ('Master Leads'!$O:$O="Yes") * ('Master Leads'!$E:$E>=IF(ISBLANK($B$5),0,$B$5)) * ('Master Leads'!$E:$E<=IF(ISBLANK($D$5),99999,$D$5)))) | C45: =IF($A45="","",SUMPRODUCT(('Master Leads'!$D:$D=$A45) * (ISNUMBER(SEARCH("7", 'Master Leads'!$P:$P))) * ('Master Leads'!$O:$O="Yes") * ('Master Leads'!$E:$E>=IF(ISBLANK($B$5),0,$B$5)) * ('Master Leads'!$E:$E<=IF(ISBLANK($D$5),99999,$D$5)))) | D45: =IF($A45="","",SUMPRODUCT(('Master Leads'!$D:$D=$A45) * (ISNUMBER(SEARCH("8", 'Master Leads'!$P:$P))) * ('Master Leads'!$O:$O="Yes") * ('Master Leads'!$E:$E>=IF(ISBLANK($B$5),0,$B$5)) * ('Master Leads'!$E:$E<=IF(ISBLANK($D$5),99999,$D$5)))) | E45: =IF($A45="","",SUMPRODUCT(('Master Leads'!$D:$D=$A45) * (ISNUMBER(SEARCH("9", 'Master Leads'!$P:$P))) * ('Master Leads'!$O:$O="Yes") * ('Master Leads'!$E:$E>=IF(ISBLANK($B$5),0,$B$5)) * ('Master Leads'!$E:$E<=IF(ISBLANK($D$5),99999,$D$5)))) | F45: =IF($A45="","",SUMPRODUCT(('Master Leads'!$D:$D=$A45) * (ISNUMBER(SEARCH("10", 'Master Leads'!$P:$P))) * ('Master Leads'!$O:$O="Yes") * ('Master Leads'!$E:$E>=IF(ISBLANK($B$5),0,$B$5)) * ('Master Leads'!$E:$E<=IF(ISBLANK($D$5),99999,$D$5)))) | G45: =IF($A45="","",SUMPRODUCT(('Master Leads'!$D:$D=$A45) * (ISNUMBER(SEARCH("11", 'Master Leads'!$P:$P))) * ('Master Leads'!$O:$O="Yes") * ('Master Leads'!$E:$E>=IF(ISBLANK($B$5),0,$B$5)) * ('Master Leads'!$E:$E<=IF(ISBLANK($D$5),99999,$D$5)))) | H45: =IF($A45="","",SUM(B45:G45)) | I45: =IF(OR($A45="",$H$54=0),"",H45/$H$54) | J45: =IF(OR($A45="",H20=0),"",H45/H20)
...

Sheet Members
A1: Member Name | B1: Total Leads (auto) | C1: Converted Leads (auto) | D1: Paid (auto) | E1: No Answer (auto) | F1: Conversion Rate (auto) | G1: Paid Rate (auto) | H1: Date Joined | I1: Notes / Role
A2: maheesha | B2: =COUNTIF('Master Leads'!D:D,A2) | C2: =COUNTIFS('Master Leads'!D:D,A2,'Master Leads'!F:F,"Converted") | D2: =COUNTIFS('Master Leads'!D:D,A2,'Master Leads'!O:O,"Yes") | E2: =COUNTIFS('Master Leads'!D:D,A2,'Master Leads'!F:F,"No Answer") | F2: =IFERROR(C2/B2,"-") | G2: =IFERROR(D2/B2,"-")
A3: menik | B3: =COUNTIF('Master Leads'!D:D,A3) | C3: =COUNTIFS('Master Leads'!D:D,A3,'Master Leads'!F:F,"Converted") | D3: =COUNTIFS('Master Leads'!D:D,A3,'Master Leads'!O:O,"Yes") | E3: =COUNTIFS('Master Leads'!D:D,A3,'Master Leads'!F:F,"No Answer") | F3: =IFERROR(C3/B3,"-") | G3: =IFERROR(D3/B3,"-")
A4: kavinda | B4: =COUNTIF('Master Leads'!D:D,A4) | C4: =COUNTIFS('Master Leads'!D:D,A4,'Master Leads'!F:F,"Converted") | D4: =COUNTIFS('Master Leads'!D:D,A4,'Master Leads'!O:O,"Yes") | E4: =COUNTIFS('Master Leads'!D:D,A4,'Master Leads'!F:F,"No Answer") | F4: =IFERROR(C4/B4,"-") | G4: =IFERROR(D4/B4,"-")
A5: umesh | B5: =COUNTIF('Master Leads'!D:D,A5) | C5: =COUNTIFS('Master Leads'!D:D,A5,'Master Leads'!F:F,"Converted") | D5: =COUNTIFS('Master Leads'!D:D,A5,'Master Leads'!O:O,"Yes") | E5: =COUNTIFS('Master Leads'!D:D,A5,'Master Leads'!F:F,"No Answer") | F5: =IFERROR(C5/B5,"-") | G5: =IFERROR(D5/B5,"-")
A6: Avishka | B6: =COUNTIF('Master Leads'!D:D,A6) | C6: =COUNTIFS('Master Leads'!D:D,A6,'Master Leads'!F:F,"Converted") | D6: =COUNTIFS('Master Leads'!D:D,A6,'Master Leads'!O:O,"Yes") | E6: =COUNTIFS('Master Leads'!D:D,A6,'Master Leads'!F:F,"No Answer") | F6: =IFERROR(C6/B6,"-") | G6: =IFERROR(D6/B6,"-")
A7: Wihanga | B7: =COUNTIF('Master Leads'!D:D,A7) | C7: =COUNTIFS('Master Leads'!D:D,A7,'Master Leads'!F:F,"Converted") | D7: =COUNTIFS('Master Leads'!D:D,A7,'Master Leads'!O:O,"Yes") | E7: =COUNTIFS('Master Leads'!D:D,A7,'Master Leads'!F:F,"No Answer") | F7: =IFERROR(C7/B7,"-") | G7: =IFERROR(D7/B7,"-")
A8: muthumali | B8: =COUNTIF('Master Leads'!D:D,A8) | C8: =COUNTIFS('Master Leads'!D:D,A8,'Master Leads'!F:F,"Converted") | D8: =COUNTIFS('Master Leads'!D:D,A8,'Master Leads'!O:O,"Yes") | E8: =COUNTIFS('Master Leads'!D:D,A8,'Master Leads'!F:F,"No Answer") | F8: =IFERROR(C8/B8,"-") | G8: =IFERROR(D8/B8,"-")
A9: shamali | B9: =COUNTIF('Master Leads'!D:D,A9) | C9: =COUNTIFS('Master Leads'!D:D,A9,'Master Leads'!F:F,"Converted") | D9: =COUNTIFS('Master Leads'!D:D,A9,'Master Leads'!O:O,"Yes") | E9: =COUNTIFS('Master Leads'!D:D,A9,'Master Leads'!F:F,"No Answer") | F9: =IFERROR(C9/B9,"-") | G9: =IFERROR(D9/B9,"-")
A10: TOTAL | B10: =COUNTA('Master Leads'!B:B)-1 | C10: =COUNTIF('Master Leads'!F:F,"Converted") | D10: =COUNTIF('Master Leads'!O:O,"Yes") | E10: =COUNTIF('Master Leads'!F:F,"No Answer")

Sheet Instructions
A1: LEAD MANAGEMENT SYSTEM v9 — Google Sheets Edition
A3: HOW TO USE THIS SYSTEM
A5: 1. Upload this file to Google Sheets (File > Import, or drag and drop onto drive.google.com)
A6: 2. Go to Extensions > Apps Script and paste the new v9 Apps Script code
A7: 3. Save the script (Ctrl+S), then reload the sheet
A8: 4. A 'Lead Tools' menu will appear at the top
A10: LEAD TOOLS MENU OPTIONS
A12: Add New Lead — Enter phone + campaign + member. Auto: F-Code, Date, Duplicate check, Repeat tag
A13: Look Up a Number — See full history of any phone number across all campaigns
A14: Add New Member — Add a new team member to the Members sheet (auto-updates all dropdowns)
A15: Remove Member — Soft-remove: blanks the name but keeps all their lead history
A17: COLUMNS IN MASTER LEADS
... A49: LIGHT BLUE — Repeat Student row
